<robot name = "robot">
    <link name="rootLink">
        <inertial>
            <origin xyz="0 0 0.5" rpy="0 0 0"/>
            <mass value="1" />
            <inertia ixx="100" ixy="0" ixz="0" iyy="100" iyz="0" izz="100" />
        </inertial>
        <visual>
            <origin xyz="0 0 0.5" rpy="0 0 0"/>
            <geometry>
                <box size="1 1 1" />
            </geometry>
            <material name="Blue">
                <color rgba="0 0 1.0 1.0"/>
            </material>
        </visual>
        <collision>
            <origin xyz="0 0 0.5" rpy="0 0 0"/>
            <geometry>
                <box size="1 1 1" />
            </geometry>
        </collision>
    </link>
    <joint name="rootLink_rootLink2" type="revolute">
       <parent link="rootLink"/>
       <child  link="rootLink2"/>
       <origin rpy="0 0 0" xyz="0 0 1.0" />
     <axis xyz="0 0 1"/>
       <limit effort="0.0" lower="-3.14159" upper="3.14159" velocity="0.0"/>
    </joint>
    <link name="rootLink2">
        <inertial>
            <origin xyz="0 0 0.9576430482159263" rpy="0 0 0"/>
            <mass value="1" />
            <inertia ixx="100" ixy="0" ixz="0" iyy="100" iyz="0" izz="100" />
        </inertial>
        <visual>
            <origin xyz="0 0 0.9576430482159263" rpy="0 0 0"/>
            <geometry>
                <box size="1 1 1.9152860964318525" />
            </geometry>
            <material name="Green">
                <color rgba="0 1.0 0 1.0"/>
            </material>
        </visual>
        <collision>
            <origin xyz="0 0 0.9576430482159263" rpy="0 0 0"/>
            <geometry>
                <box size="1 1 1.9152860964318525" />
            </geometry>
        </collision>
    </link>
    <joint name="rootLink2_rootLink20" type="revolute">
       <parent link="rootLink2"/>
       <child  link="rootLink20"/>
       <origin rpy="0 0 0" xyz="0 0.5 0.9576430482159263" />
     <axis xyz="0 0 1"/>
       <limit effort="0.0" lower="-3.14159" upper="3.14159" velocity="0.0"/>
    </joint>
    <link name="rootLink20">
        <inertial>
            <origin xyz="0 0.5163592430621458 0" rpy="0 0 0"/>
            <mass value="1" />
            <inertia ixx="100" ixy="0" ixz="0" iyy="100" iyz="0" izz="100" />
        </inertial>
        <visual>
            <origin xyz="0 0.5163592430621458 0" rpy="0 0 0"/>
            <geometry>
                <box size="1 1.0327184861242915 1" />
            </geometry>
            <material name="Blue">
                <color rgba="0 0 1.0 1.0"/>
            </material>
        </visual>
        <collision>
            <origin xyz="0 0.5163592430621458 0" rpy="0 0 0"/>
            <geometry>
                <box size="1 1.0327184861242915 1" />
            </geometry>
        </collision>
    </link>
    <joint name="rootLink20_rootLink200" type="revolute">
       <parent link="rootLink20"/>
       <child  link="rootLink200"/>
       <origin rpy="0 0 0" xyz="0 0.5163592430621458 -0.5" />
     <axis xyz="0 1 0"/>
       <limit effort="0.0" lower="-3.14159" upper="3.14159" velocity="0.0"/>
    </joint>
    <link name="rootLink200">
        <inertial>
            <origin xyz="0 0 -0.627649586208006" rpy="0 0 0"/>
            <mass value="1" />
            <inertia ixx="100" ixy="0" ixz="0" iyy="100" iyz="0" izz="100" />
        </inertial>
        <visual>
            <origin xyz="0 0 -0.627649586208006" rpy="0 0 0"/>
            <geometry>
                <box size="1 1 1.255299172416012" />
            </geometry>
            <material name="Green">
                <color rgba="0 1.0 0 1.0"/>
            </material>
        </visual>
        <collision>
            <origin xyz="0 0 -0.627649586208006" rpy="0 0 0"/>
            <geometry>
                <box size="1 1 1.255299172416012" />
            </geometry>
        </collision>
    </link>
    <joint name="rootLink200_rootLink2000" type="revolute">
       <parent link="rootLink200"/>
       <child  link="rootLink2000"/>
       <origin rpy="0 0 0" xyz="0.5 0 -0.627649586208006" />
     <axis xyz="0 1 0"/>
       <limit effort="0.0" lower="-3.14159" upper="3.14159" velocity="0.0"/>
    </joint>
    <link name="rootLink2000">
        <inertial>
            <origin xyz="0.786177167419713 0 0" rpy="0 0 0"/>
            <mass value="1" />
            <inertia ixx="100" ixy="0" ixz="0" iyy="100" iyz="0" izz="100" />
        </inertial>
        <visual>
            <origin xyz="0.786177167419713 0 0" rpy="0 0 0"/>
            <geometry>
                <box size="1.572354334839426 1 1" />
            </geometry>
            <material name="Blue">
                <color rgba="0 0 1.0 1.0"/>
            </material>
        </visual>
        <collision>
            <origin xyz="0.786177167419713 0 0" rpy="0 0 0"/>
            <geometry>
                <box size="1.572354334839426 1 1" />
            </geometry>
        </collision>
    </link>
    <joint name="rootLink20_rootLink201" type="revolute">
       <parent link="rootLink20"/>
       <child  link="rootLink201"/>
       <origin rpy="0 0 0" xyz="0 1.0327184861242915 0" />
     <axis xyz="1 0 0"/>
       <limit effort="0.0" lower="-3.14159" upper="3.14159" velocity="0.0"/>
    </joint>
    <link name="rootLink201">
        <inertial>
            <origin xyz="0 0.7512136660507986 0" rpy="0 0 0"/>
            <mass value="1" />
            <inertia ixx="100" ixy="0" ixz="0" iyy="100" iyz="0" izz="100" />
        </inertial>
        <visual>
            <origin xyz="0 0.7512136660507986 0" rpy="0 0 0"/>
            <geometry>
                <box size="1 1.5024273321015973 1" />
            </geometry>
            <material name="Blue">
                <color rgba="0 0 1.0 1.0"/>
            </material>
        </visual>
        <collision>
            <origin xyz="0 0.7512136660507986 0" rpy="0 0 0"/>
            <geometry>
                <box size="1 1.5024273321015973 1" />
            </geometry>
        </collision>
    </link>
</robot>