<robot name = "robot">
    <link name="rootLink">
        <inertial>
            <origin xyz="0 0 0.5" rpy="0 0 0"/>
            <mass value="1" />
            <inertia ixx="100" ixy="0" ixz="0" iyy="100" iyz="0" izz="100" />
        </inertial>
        <visual>
            <origin xyz="0 0 0.5" rpy="0 0 0"/>
            <geometry>
                <box size="1 1 1" />
            </geometry>
            <material name="Blue">
                <color rgba="0 0 1.0 1.0"/>
            </material>
        </visual>
        <collision>
            <origin xyz="0 0 0.5" rpy="0 0 0"/>
            <geometry>
                <box size="1 1 1" />
            </geometry>
        </collision>
    </link>
    <joint name="rootLink_rootLink0" type="revolute">
       <parent link="rootLink"/>
       <child  link="rootLink0"/>
       <origin rpy="0 0 0" xyz="0 0.5 0.5" />
     <axis xyz="0 0 1"/>
       <limit effort="0.0" lower="-3.14159" upper="3.14159" velocity="0.0"/>
    </joint>
    <link name="rootLink0">
        <inertial>
            <origin xyz="0 0.8702006159803533 0" rpy="0 0 0"/>
            <mass value="1" />
            <inertia ixx="100" ixy="0" ixz="0" iyy="100" iyz="0" izz="100" />
        </inertial>
        <visual>
            <origin xyz="0 0.8702006159803533 0" rpy="0 0 0"/>
            <geometry>
                <box size="1 1.7404012319607065 1" />
            </geometry>
            <material name="Blue">
                <color rgba="0 0 1.0 1.0"/>
            </material>
        </visual>
        <collision>
            <origin xyz="0 0.8702006159803533 0" rpy="0 0 0"/>
            <geometry>
                <box size="1 1.7404012319607065 1" />
            </geometry>
        </collision>
    </link>
    <joint name="rootLink0_rootLink00" type="revolute">
       <parent link="rootLink0"/>
       <child  link="rootLink00"/>
       <origin rpy="0 0 0" xyz="0.5 0.8702006159803533 0" />
     <axis xyz="1 0 0"/>
       <limit effort="0.0" lower="-3.14159" upper="3.14159" velocity="0.0"/>
    </joint>
    <link name="rootLink00">
        <inertial>
            <origin xyz="0.7474333276561125 0 0" rpy="0 0 0"/>
            <mass value="1" />
            <inertia ixx="100" ixy="0" ixz="0" iyy="100" iyz="0" izz="100" />
        </inertial>
        <visual>
            <origin xyz="0.7474333276561125 0 0" rpy="0 0 0"/>
            <geometry>
                <box size="1.494866655312225 1 1" />
            </geometry>
            <material name="Green">
                <color rgba="0 1.0 0 1.0"/>
            </material>
        </visual>
        <collision>
            <origin xyz="0.7474333276561125 0 0" rpy="0 0 0"/>
            <geometry>
                <box size="1.494866655312225 1 1" />
            </geometry>
        </collision>
    </link>
    <joint name="rootLink00_rootLink000" type="revolute">
       <parent link="rootLink00"/>
       <child  link="rootLink000"/>
       <origin rpy="0 0 0" xyz="0.7474333276561125 0 0.5" />
     <axis xyz="0 0 1"/>
       <limit effort="0.0" lower="-3.14159" upper="3.14159" velocity="0.0"/>
    </joint>
    <link name="rootLink000">
        <inertial>
            <origin xyz="0 0 0.7837274771534295" rpy="0 0 0"/>
            <mass value="1" />
            <inertia ixx="100" ixy="0" ixz="0" iyy="100" iyz="0" izz="100" />
        </inertial>
        <visual>
            <origin xyz="0 0 0.7837274771534295" rpy="0 0 0"/>
            <geometry>
                <box size="1 1 1.567454954306859" />
            </geometry>
            <material name="Blue">
                <color rgba="0 0 1.0 1.0"/>
            </material>
        </visual>
        <collision>
            <origin xyz="0 0 0.7837274771534295" rpy="0 0 0"/>
            <geometry>
                <box size="1 1 1.567454954306859" />
            </geometry>
        </collision>
    </link>
    <joint name="rootLink000_rootLink0000" type="revolute">
       <parent link="rootLink000"/>
       <child  link="rootLink0000"/>
       <origin rpy="0 0 0" xyz="0 0.5 0.7837274771534295" />
     <axis xyz="0 1 0"/>
       <limit effort="0.0" lower="-3.14159" upper="3.14159" velocity="0.0"/>
    </joint>
    <link name="rootLink0000">
        <inertial>
            <origin xyz="0 0.522994810362493 0" rpy="0 0 0"/>
            <mass value="1" />
            <inertia ixx="100" ixy="0" ixz="0" iyy="100" iyz="0" izz="100" />
        </inertial>
        <visual>
            <origin xyz="0 0.522994810362493 0" rpy="0 0 0"/>
            <geometry>
                <box size="1 1.045989620724986 1" />
            </geometry>
            <material name="Blue">
                <color rgba="0 0 1.0 1.0"/>
            </material>
        </visual>
        <collision>
            <origin xyz="0 0.522994810362493 0" rpy="0 0 0"/>
            <geometry>
                <box size="1 1.045989620724986 1" />
            </geometry>
        </collision>
    </link>
    <joint name="rootLink00_rootLink001" type="revolute">
       <parent link="rootLink00"/>
       <child  link="rootLink001"/>
       <origin rpy="0 0 0" xyz="1.494866655312225 0 0" />
     <axis xyz="0 1 0"/>
       <limit effort="0.0" lower="-3.14159" upper="3.14159" velocity="0.0"/>
    </joint>
    <link name="rootLink001">
        <inertial>
            <origin xyz="0.651620380083695 0 0" rpy="0 0 0"/>
            <mass value="1" />
            <inertia ixx="100" ixy="0" ixz="0" iyy="100" iyz="0" izz="100" />
        </inertial>
        <visual>
            <origin xyz="0.651620380083695 0 0" rpy="0 0 0"/>
            <geometry>
                <box size="1.30324076016739 1 1" />
            </geometry>
            <material name="Blue">
                <color rgba="0 0 1.0 1.0"/>
            </material>
        </visual>
        <collision>
            <origin xyz="0.651620380083695 0 0" rpy="0 0 0"/>
            <geometry>
                <box size="1.30324076016739 1 1" />
            </geometry>
        </collision>
    </link>
    <joint name="rootLink001_rootLink0010" type="revolute">
       <parent link="rootLink001"/>
       <child  link="rootLink0010"/>
       <origin rpy="0 0 0" xyz="0.651620380083695 0 0.5" />
     <axis xyz="1 0 0"/>
       <limit effort="0.0" lower="-3.14159" upper="3.14159" velocity="0.0"/>
    </joint>
    <link name="rootLink0010">
        <inertial>
            <origin xyz="0 0 0.9013507306213945" rpy="0 0 0"/>
            <mass value="1" />
            <inertia ixx="100" ixy="0" ixz="0" iyy="100" iyz="0" izz="100" />
        </inertial>
        <visual>
            <origin xyz="0 0 0.9013507306213945" rpy="0 0 0"/>
            <geometry>
                <box size="1 1 1.802701461242789" />
            </geometry>
            <material name="Blue">
                <color rgba="0 0 1.0 1.0"/>
            </material>
        </visual>
        <collision>
            <origin xyz="0 0 0.9013507306213945" rpy="0 0 0"/>
            <geometry>
                <box size="1 1 1.802701461242789" />
            </geometry>
        </collision>
    </link>
    <joint name="rootLink0010_rootLink00100" type="revolute">
       <parent link="rootLink0010"/>
       <child  link="rootLink00100"/>
       <origin rpy="0 0 0" xyz="0 0 1.802701461242789" />
     <axis xyz="0 0 1"/>
       <limit effort="0.0" lower="-3.14159" upper="3.14159" velocity="0.0"/>
    </joint>
    <link name="rootLink00100">
        <inertial>
            <origin xyz="0 0 0.9198974865901858" rpy="0 0 0"/>
            <mass value="1" />
            <inertia ixx="100" ixy="0" ixz="0" iyy="100" iyz="0" izz="100" />
        </inertial>
        <visual>
            <origin xyz="0 0 0.9198974865901858" rpy="0 0 0"/>
            <geometry>
                <box size="1 1 1.8397949731803716" />
            </geometry>
            <material name="Blue">
                <color rgba="0 0 1.0 1.0"/>
            </material>
        </visual>
        <collision>
            <origin xyz="0 0 0.9198974865901858" rpy="0 0 0"/>
            <geometry>
                <box size="1 1 1.8397949731803716" />
            </geometry>
        </collision>
    </link>
    <joint name="rootLink0010_rootLink00101" type="revolute">
       <parent link="rootLink0010"/>
       <child  link="rootLink00101"/>
       <origin rpy="0 0 0" xyz="0 0.5 0.9013507306213945" />
     <axis xyz="1 0 0"/>
       <limit effort="0.0" lower="-3.14159" upper="3.14159" velocity="0.0"/>
    </joint>
    <link name="rootLink00101">
        <inertial>
            <origin xyz="0 0.5386493569678603 0" rpy="0 0 0"/>
            <mass value="1" />
            <inertia ixx="100" ixy="0" ixz="0" iyy="100" iyz="0" izz="100" />
        </inertial>
        <visual>
            <origin xyz="0 0.5386493569678603 0" rpy="0 0 0"/>
            <geometry>
                <box size="1 1.0772987139357206 1" />
            </geometry>
            <material name="Green">
                <color rgba="0 1.0 0 1.0"/>
            </material>
        </visual>
        <collision>
            <origin xyz="0 0.5386493569678603 0" rpy="0 0 0"/>
            <geometry>
                <box size="1 1.0772987139357206 1" />
            </geometry>
        </collision>
    </link>
    <joint name="rootLink0_rootLink01" type="revolute">
       <parent link="rootLink0"/>
       <child  link="rootLink01"/>
       <origin rpy="0 0 0" xyz="0 0.8702006159803533 0.5" />
     <axis xyz="0 0 1"/>
       <limit effort="0.0" lower="-3.14159" upper="3.14159" velocity="0.0"/>
    </joint>
    <link name="rootLink01">
        <inertial>
            <origin xyz="0 0 0.6998823941131411" rpy="0 0 0"/>
            <mass value="1" />
            <inertia ixx="100" ixy="0" ixz="0" iyy="100" iyz="0" izz="100" />
        </inertial>
        <visual>
            <origin xyz="0 0 0.6998823941131411" rpy="0 0 0"/>
            <geometry>
                <box size="1 1 1.3997647882262823" />
            </geometry>
            <material name="Blue">
                <color rgba="0 0 1.0 1.0"/>
            </material>
        </visual>
        <collision>
            <origin xyz="0 0 0.6998823941131411" rpy="0 0 0"/>
            <geometry>
                <box size="1 1 1.3997647882262823" />
            </geometry>
        </collision>
    </link>
    <joint name="rootLink0_rootLink03" type="revolute">
       <parent link="rootLink0"/>
       <child  link="rootLink03"/>
       <origin rpy="0 0 0" xyz="0 1.7404012319607065 0" />
     <axis xyz="0 1 0"/>
       <limit effort="0.0" lower="-3.14159" upper="3.14159" velocity="0.0"/>
    </joint>
    <link name="rootLink03">
        <inertial>
            <origin xyz="0 0.7746664502205904 0" rpy="0 0 0"/>
            <mass value="1" />
            <inertia ixx="100" ixy="0" ixz="0" iyy="100" iyz="0" izz="100" />
        </inertial>
        <visual>
            <origin xyz="0 0.7746664502205904 0" rpy="0 0 0"/>
            <geometry>
                <box size="1 1.5493329004411809 1" />
            </geometry>
            <material name="Green">
                <color rgba="0 1.0 0 1.0"/>
            </material>
        </visual>
        <collision>
            <origin xyz="0 0.7746664502205904 0" rpy="0 0 0"/>
            <geometry>
                <box size="1 1.5493329004411809 1" />
            </geometry>
        </collision>
    </link>
    <joint name="rootLink03_rootLink030" type="revolute">
       <parent link="rootLink03"/>
       <child  link="rootLink030"/>
       <origin rpy="0 0 0" xyz="0.5 0.7746664502205904 0" />
     <axis xyz="1 0 0"/>
       <limit effort="0.0" lower="-3.14159" upper="3.14159" velocity="0.0"/>
    </joint>
    <link name="rootLink030">
        <inertial>
            <origin xyz="0.5163606079119004 0 0" rpy="0 0 0"/>
            <mass value="1" />
            <inertia ixx="100" ixy="0" ixz="0" iyy="100" iyz="0" izz="100" />
        </inertial>
        <visual>
            <origin xyz="0.5163606079119004 0 0" rpy="0 0 0"/>
            <geometry>
                <box size="1.0327212158238008 1 1" />
            </geometry>
            <material name="Green">
                <color rgba="0 1.0 0 1.0"/>
            </material>
        </visual>
        <collision>
            <origin xyz="0.5163606079119004 0 0" rpy="0 0 0"/>
            <geometry>
                <box size="1.0327212158238008 1 1" />
            </geometry>
        </collision>
    </link>
    <joint name="rootLink_rootLink1" type="revolute">
       <parent link="rootLink"/>
       <child  link="rootLink1"/>
       <origin rpy="0 0 0" xyz="0 0 1.0" />
     <axis xyz="0 0 1"/>
       <limit effort="0.0" lower="-3.14159" upper="3.14159" velocity="0.0"/>
    </joint>
    <link name="rootLink1">
        <inertial>
            <origin xyz="0 0 0.991029644343693" rpy="0 0 0"/>
            <mass value="1" />
            <inertia ixx="100" ixy="0" ixz="0" iyy="100" iyz="0" izz="100" />
        </inertial>
        <visual>
            <origin xyz="0 0 0.991029644343693" rpy="0 0 0"/>
            <geometry>
                <box size="1 1 1.982059288687386" />
            </geometry>
            <material name="Blue">
                <color rgba="0 0 1.0 1.0"/>
            </material>
        </visual>
        <collision>
            <origin xyz="0 0 0.991029644343693" rpy="0 0 0"/>
            <geometry>
                <box size="1 1 1.982059288687386" />
            </geometry>
        </collision>
    </link>
    <joint name="rootLink1_rootLink10" type="revolute">
       <parent link="rootLink1"/>
       <child  link="rootLink10"/>
       <origin rpy="0 0 0" xyz="0.5 0 0.991029644343693" />
     <axis xyz="0 0 1"/>
       <limit effort="0.0" lower="-3.14159" upper="3.14159" velocity="0.0"/>
    </joint>
    <link name="rootLink10">
        <inertial>
            <origin xyz="0.9441290297538336 0 0" rpy="0 0 0"/>
            <mass value="1" />
            <inertia ixx="100" ixy="0" ixz="0" iyy="100" iyz="0" izz="100" />
        </inertial>
        <visual>
            <origin xyz="0.9441290297538336 0 0" rpy="0 0 0"/>
            <geometry>
                <box size="1.8882580595076672 1 1" />
            </geometry>
            <material name="Green">
                <color rgba="0 1.0 0 1.0"/>
            </material>
        </visual>
        <collision>
            <origin xyz="0.9441290297538336 0 0" rpy="0 0 0"/>
            <geometry>
                <box size="1.8882580595076672 1 1" />
            </geometry>
        </collision>
    </link>
    <joint name="rootLink10_rootLink100" type="revolute">
       <parent link="rootLink10"/>
       <child  link="rootLink100"/>
       <origin rpy="0 0 0" xyz="0.9441290297538336 0.5 0" />
     <axis xyz="0 1 0"/>
       <limit effort="0.0" lower="-3.14159" upper="3.14159" velocity="0.0"/>
    </joint>
    <link name="rootLink100">
        <inertial>
            <origin xyz="0 0.5406693591577756 0" rpy="0 0 0"/>
            <mass value="1" />
            <inertia ixx="100" ixy="0" ixz="0" iyy="100" iyz="0" izz="100" />
        </inertial>
        <visual>
            <origin xyz="0 0.5406693591577756 0" rpy="0 0 0"/>
            <geometry>
                <box size="1 1.0813387183155512 1" />
            </geometry>
            <material name="Blue">
                <color rgba="0 0 1.0 1.0"/>
            </material>
        </visual>
        <collision>
            <origin xyz="0 0.5406693591577756 0" rpy="0 0 0"/>
            <geometry>
                <box size="1 1.0813387183155512 1" />
            </geometry>
        </collision>
    </link>
    <joint name="rootLink100_rootLink1000" type="revolute">
       <parent link="rootLink100"/>
       <child  link="rootLink1000"/>
       <origin rpy="0 0 0" xyz="0 1.0813387183155512 0" />
     <axis xyz="0 1 0"/>
       <limit effort="0.0" lower="-3.14159" upper="3.14159" velocity="0.0"/>
    </joint>
    <link name="rootLink1000">
        <inertial>
            <origin xyz="0 0.7743485672277552 0" rpy="0 0 0"/>
            <mass value="1" />
            <inertia ixx="100" ixy="0" ixz="0" iyy="100" iyz="0" izz="100" />
        </inertial>
        <visual>
            <origin xyz="0 0.7743485672277552 0" rpy="0 0 0"/>
            <geometry>
                <box size="1 1.5486971344555105 1" />
            </geometry>
            <material name="Blue">
                <color rgba="0 0 1.0 1.0"/>
            </material>
        </visual>
        <collision>
            <origin xyz="0 0.7743485672277552 0" rpy="0 0 0"/>
            <geometry>
                <box size="1 1.5486971344555105 1" />
            </geometry>
        </collision>
    </link>
    <joint name="rootLink100_rootLink1002" type="revolute">
       <parent link="rootLink100"/>
       <child  link="rootLink1002"/>
       <origin rpy="0 0 0" xyz="0.5 0.5406693591577756 0" />
     <axis xyz="0 1 0"/>
       <limit effort="0.0" lower="-3.14159" upper="3.14159" velocity="0.0"/>
    </joint>
    <link name="rootLink1002">
        <inertial>
            <origin xyz="0.5455062597123368 0 0" rpy="0 0 0"/>
            <mass value="1" />
            <inertia ixx="100" ixy="0" ixz="0" iyy="100" iyz="0" izz="100" />
        </inertial>
        <visual>
            <origin xyz="0.5455062597123368 0 0" rpy="0 0 0"/>
            <geometry>
                <box size="1.0910125194246736 1 1" />
            </geometry>
            <material name="Blue">
                <color rgba="0 0 1.0 1.0"/>
            </material>
        </visual>
        <collision>
            <origin xyz="0.5455062597123368 0 0" rpy="0 0 0"/>
            <geometry>
                <box size="1.0910125194246736 1 1" />
            </geometry>
        </collision>
    </link>
    <joint name="rootLink1002_rootLink10020" type="revolute">
       <parent link="rootLink1002"/>
       <child  link="rootLink10020"/>
       <origin rpy="0 0 0" xyz="1.0910125194246736 0 0" />
     <axis xyz="0 1 0"/>
       <limit effort="0.0" lower="-3.14159" upper="3.14159" velocity="0.0"/>
    </joint>
    <link name="rootLink10020">
        <inertial>
            <origin xyz="0.5794448084090243 0 0" rpy="0 0 0"/>
            <mass value="1" />
            <inertia ixx="100" ixy="0" ixz="0" iyy="100" iyz="0" izz="100" />
        </inertial>
        <visual>
            <origin xyz="0.5794448084090243 0 0" rpy="0 0 0"/>
            <geometry>
                <box size="1.1588896168180487 1 1" />
            </geometry>
            <material name="Blue">
                <color rgba="0 0 1.0 1.0"/>
            </material>
        </visual>
        <collision>
            <origin xyz="0.5794448084090243 0 0" rpy="0 0 0"/>
            <geometry>
                <box size="1.1588896168180487 1 1" />
            </geometry>
        </collision>
    </link>
    <joint name="rootLink1002_rootLink10022" type="revolute">
       <parent link="rootLink1002"/>
       <child  link="rootLink10022"/>
       <origin rpy="0 0 0" xyz="0.5455062597123368 0.5 0" />
     <axis xyz="0 1 0"/>
       <limit effort="0.0" lower="-3.14159" upper="3.14159" velocity="0.0"/>
    </joint>
    <link name="rootLink10022">
        <inertial>
            <origin xyz="0 0.6511906641301626 0" rpy="0 0 0"/>
            <mass value="1" />
            <inertia ixx="100" ixy="0" ixz="0" iyy="100" iyz="0" izz="100" />
        </inertial>
        <visual>
            <origin xyz="0 0.6511906641301626 0" rpy="0 0 0"/>
            <geometry>
                <box size="1 1.3023813282603252 1" />
            </geometry>
            <material name="Green">
                <color rgba="0 1.0 0 1.0"/>
            </material>
        </visual>
        <collision>
            <origin xyz="0 0.6511906641301626 0" rpy="0 0 0"/>
            <geometry>
                <box size="1 1.3023813282603252 1" />
            </geometry>
        </collision>
    </link>
    <joint name="rootLink1_rootLink12" type="revolute">
       <parent link="rootLink1"/>
       <child  link="rootLink12"/>
       <origin rpy="0 0 0" xyz="0 0 1.982059288687386" />
     <axis xyz="0 1 0"/>
       <limit effort="0.0" lower="-3.14159" upper="3.14159" velocity="0.0"/>
    </joint>
    <link name="rootLink12">
        <inertial>
            <origin xyz="0 0 0.809234878443722" rpy="0 0 0"/>
            <mass value="1" />
            <inertia ixx="100" ixy="0" ixz="0" iyy="100" iyz="0" izz="100" />
        </inertial>
        <visual>
            <origin xyz="0 0 0.809234878443722" rpy="0 0 0"/>
            <geometry>
                <box size="1 1 1.618469756887444" />
            </geometry>
            <material name="Blue">
                <color rgba="0 0 1.0 1.0"/>
            </material>
        </visual>
        <collision>
            <origin xyz="0 0 0.809234878443722" rpy="0 0 0"/>
            <geometry>
                <box size="1 1 1.618469756887444" />
            </geometry>
        </collision>
    </link>
</robot>