<robot name = "robot">
    <link name="rootLink">
        <inertial>
            <origin xyz="0 0 0.5" rpy="0 0 0"/>
            <mass value="1" />
            <inertia ixx="100" ixy="0" ixz="0" iyy="100" iyz="0" izz="100" />
        </inertial>
        <visual>
            <origin xyz="0 0 0.5" rpy="0 0 0"/>
            <geometry>
                <box size="1 1 1" />
            </geometry>
            <material name="Blue">
                <color rgba="0 0 1.0 1.0"/>
            </material>
        </visual>
        <collision>
            <origin xyz="0 0 0.5" rpy="0 0 0"/>
            <geometry>
                <box size="1 1 1" />
            </geometry>
        </collision>
    </link>
    <joint name="rootLink_rootLink0" type="revolute">
       <parent link="rootLink"/>
       <child  link="rootLink0"/>
       <origin rpy="0 0 0" xyz="0 0 1.0" />
     <axis xyz="0 1 0"/>
       <limit effort="0.0" lower="-3.14159" upper="3.14159" velocity="0.0"/>
    </joint>
    <link name="rootLink0">
        <inertial>
            <origin xyz="0 0 0.5345412732737375" rpy="0 0 0"/>
            <mass value="1" />
            <inertia ixx="100" ixy="0" ixz="0" iyy="100" iyz="0" izz="100" />
        </inertial>
        <visual>
            <origin xyz="0 0 0.5345412732737375" rpy="0 0 0"/>
            <geometry>
                <box size="1 1 1.069082546547475" />
            </geometry>
            <material name="Green">
                <color rgba="0 1.0 0 1.0"/>
            </material>
        </visual>
        <collision>
            <origin xyz="0 0 0.5345412732737375" rpy="0 0 0"/>
            <geometry>
                <box size="1 1 1.069082546547475" />
            </geometry>
        </collision>
    </link>
    <joint name="rootLink0_rootLink00" type="revolute">
       <parent link="rootLink0"/>
       <child  link="rootLink00"/>
       <origin rpy="0 0 0" xyz="0 -0.5 0.5345412732737375" />
     <axis xyz="0 0 1"/>
       <limit effort="0.0" lower="-3.14159" upper="3.14159" velocity="0.0"/>
    </joint>
    <link name="rootLink00">
        <inertial>
            <origin xyz="0 -0.5789772311247845 0" rpy="0 0 0"/>
            <mass value="1" />
            <inertia ixx="100" ixy="0" ixz="0" iyy="100" iyz="0" izz="100" />
        </inertial>
        <visual>
            <origin xyz="0 -0.5789772311247845 0" rpy="0 0 0"/>
            <geometry>
                <box size="1 1.157954462249569 1" />
            </geometry>
            <material name="Green">
                <color rgba="0 1.0 0 1.0"/>
            </material>
        </visual>
        <collision>
            <origin xyz="0 -0.5789772311247845 0" rpy="0 0 0"/>
            <geometry>
                <box size="1 1.157954462249569 1" />
            </geometry>
        </collision>
    </link>
    <joint name="rootLink00_rootLink000" type="revolute">
       <parent link="rootLink00"/>
       <child  link="rootLink000"/>
       <origin rpy="0 0 0" xyz="0 -0.5789772311247845 0.5" />
     <axis xyz="1 0 0"/>
       <limit effort="0.0" lower="-3.14159" upper="3.14159" velocity="0.0"/>
    </joint>
    <link name="rootLink000">
        <inertial>
            <origin xyz="0 0 0.9813134519897605" rpy="0 0 0"/>
            <mass value="1" />
            <inertia ixx="100" ixy="0" ixz="0" iyy="100" iyz="0" izz="100" />
        </inertial>
        <visual>
            <origin xyz="0 0 0.9813134519897605" rpy="0 0 0"/>
            <geometry>
                <box size="1 1 1.962626903979521" />
            </geometry>
            <material name="Green">
                <color rgba="0 1.0 0 1.0"/>
            </material>
        </visual>
        <collision>
            <origin xyz="0 0 0.9813134519897605" rpy="0 0 0"/>
            <geometry>
                <box size="1 1 1.962626903979521" />
            </geometry>
        </collision>
    </link>
    <joint name="rootLink000_rootLink0000" type="revolute">
       <parent link="rootLink000"/>
       <child  link="rootLink0000"/>
       <origin rpy="0 0 0" xyz="0.5 0 0.9813134519897605" />
     <axis xyz="0 1 0"/>
       <limit effort="0.0" lower="-3.14159" upper="3.14159" velocity="0.0"/>
    </joint>
    <link name="rootLink0000">
        <inertial>
            <origin xyz="0.9082693758957116 0 0" rpy="0 0 0"/>
            <mass value="1" />
            <inertia ixx="100" ixy="0" ixz="0" iyy="100" iyz="0" izz="100" />
        </inertial>
        <visual>
            <origin xyz="0.9082693758957116 0 0" rpy="0 0 0"/>
            <geometry>
                <box size="1.816538751791423 1 1" />
            </geometry>
            <material name="Blue">
                <color rgba="0 0 1.0 1.0"/>
            </material>
        </visual>
        <collision>
            <origin xyz="0.9082693758957116 0 0" rpy="0 0 0"/>
            <geometry>
                <box size="1.816538751791423 1 1" />
            </geometry>
        </collision>
    </link>
    <joint name="rootLink0000_rootLink00001" type="revolute">
       <parent link="rootLink0000"/>
       <child  link="rootLink00001"/>
       <origin rpy="0 0 0" xyz="0.9082693758957116 0 0.5" />
     <axis xyz="1 0 0"/>
       <limit effort="0.0" lower="-3.14159" upper="3.14159" velocity="0.0"/>
    </joint>
    <link name="rootLink00001">
        <inertial>
            <origin xyz="0 0 0.5182541809973433" rpy="0 0 0"/>
            <mass value="1" />
            <inertia ixx="100" ixy="0" ixz="0" iyy="100" iyz="0" izz="100" />
        </inertial>
        <visual>
            <origin xyz="0 0 0.5182541809973433" rpy="0 0 0"/>
            <geometry>
                <box size="1 1 1.0365083619946867" />
            </geometry>
            <material name="Blue">
                <color rgba="0 0 1.0 1.0"/>
            </material>
        </visual>
        <collision>
            <origin xyz="0 0 0.5182541809973433" rpy="0 0 0"/>
            <geometry>
                <box size="1 1 1.0365083619946867" />
            </geometry>
        </collision>
    </link>
    <joint name="rootLink0000_rootLink00003" type="revolute">
       <parent link="rootLink0000"/>
       <child  link="rootLink00003"/>
       <origin rpy="0 0 0" xyz="0.9082693758957116 0.5 0" />
     <axis xyz="1 0 0"/>
       <limit effort="0.0" lower="-3.14159" upper="3.14159" velocity="0.0"/>
    </joint>
    <link name="rootLink00003">
        <inertial>
            <origin xyz="0 0.5748771190306109 0" rpy="0 0 0"/>
            <mass value="1" />
            <inertia ixx="100" ixy="0" ixz="0" iyy="100" iyz="0" izz="100" />
        </inertial>
        <visual>
            <origin xyz="0 0.5748771190306109 0" rpy="0 0 0"/>
            <geometry>
                <box size="1 1.1497542380612218 1" />
            </geometry>
            <material name="Green">
                <color rgba="0 1.0 0 1.0"/>
            </material>
        </visual>
        <collision>
            <origin xyz="0 0.5748771190306109 0" rpy="0 0 0"/>
            <geometry>
                <box size="1 1.1497542380612218 1" />
            </geometry>
        </collision>
    </link>
    <joint name="rootLink00003_rootLink000030" type="revolute">
       <parent link="rootLink00003"/>
       <child  link="rootLink000030"/>
       <origin rpy="0 0 0" xyz="0 0.5748771190306109 -0.5" />
     <axis xyz="0 0 1"/>
       <limit effort="0.0" lower="-3.14159" upper="3.14159" velocity="0.0"/>
    </joint>
    <link name="rootLink000030">
        <inertial>
            <origin xyz="0 0 -0.8142947448194652" rpy="0 0 0"/>
            <mass value="1" />
            <inertia ixx="100" ixy="0" ixz="0" iyy="100" iyz="0" izz="100" />
        </inertial>
        <visual>
            <origin xyz="0 0 -0.8142947448194652" rpy="0 0 0"/>
            <geometry>
                <box size="1 1 1.6285894896389304" />
            </geometry>
            <material name="Blue">
                <color rgba="0 0 1.0 1.0"/>
            </material>
        </visual>
        <collision>
            <origin xyz="0 0 -0.8142947448194652" rpy="0 0 0"/>
            <geometry>
                <box size="1 1 1.6285894896389304" />
            </geometry>
        </collision>
    </link>
</robot>