<robot name = "robot">
    <link name="rootLink">
        <inertial>
            <origin xyz="0 0 0.5" rpy="0 0 0"/>
            <mass value="1" />
            <inertia ixx="100" ixy="0" ixz="0" iyy="100" iyz="0" izz="100" />
        </inertial>
        <visual>
            <origin xyz="0 0 0.5" rpy="0 0 0"/>
            <geometry>
                <box size="1 1 1" />
            </geometry>
            <material name="Blue">
                <color rgba="0 0 1.0 1.0"/>
            </material>
        </visual>
        <collision>
            <origin xyz="0 0 0.5" rpy="0 0 0"/>
            <geometry>
                <box size="1 1 1" />
            </geometry>
        </collision>
    </link>
    <joint name="rootLink_rootLink0" type="revolute">
       <parent link="rootLink"/>
       <child  link="rootLink0"/>
       <origin rpy="0 0 0" xyz="0 0 1.0" />
     <axis xyz="0 0 1"/>
       <limit effort="0.0" lower="-3.14159" upper="3.14159" velocity="0.0"/>
    </joint>
    <link name="rootLink0">
        <inertial>
            <origin xyz="0 0 0.5231012439279966" rpy="0 0 0"/>
            <mass value="1" />
            <inertia ixx="100" ixy="0" ixz="0" iyy="100" iyz="0" izz="100" />
        </inertial>
        <visual>
            <origin xyz="0 0 0.5231012439279966" rpy="0 0 0"/>
            <geometry>
                <box size="1 1 1.0462024878559932" />
            </geometry>
            <material name="Green">
                <color rgba="0 1.0 0 1.0"/>
            </material>
        </visual>
        <collision>
            <origin xyz="0 0 0.5231012439279966" rpy="0 0 0"/>
            <geometry>
                <box size="1 1 1.0462024878559932" />
            </geometry>
        </collision>
    </link>
    <joint name="rootLink0_rootLink00" type="revolute">
       <parent link="rootLink0"/>
       <child  link="rootLink00"/>
       <origin rpy="0 0 0" xyz="0 -0.5 0.5231012439279966" />
     <axis xyz="0 0 1"/>
       <limit effort="0.0" lower="-3.14159" upper="3.14159" velocity="0.0"/>
    </joint>
    <link name="rootLink00">
        <inertial>
            <origin xyz="0 -0.7441864176784315 0" rpy="0 0 0"/>
            <mass value="1" />
            <inertia ixx="100" ixy="0" ixz="0" iyy="100" iyz="0" izz="100" />
        </inertial>
        <visual>
            <origin xyz="0 -0.7441864176784315 0" rpy="0 0 0"/>
            <geometry>
                <box size="1 1.488372835356863 1" />
            </geometry>
            <material name="Green">
                <color rgba="0 1.0 0 1.0"/>
            </material>
        </visual>
        <collision>
            <origin xyz="0 -0.7441864176784315 0" rpy="0 0 0"/>
            <geometry>
                <box size="1 1.488372835356863 1" />
            </geometry>
        </collision>
    </link>
    <joint name="rootLink00_rootLink000" type="revolute">
       <parent link="rootLink00"/>
       <child  link="rootLink000"/>
       <origin rpy="0 0 0" xyz="0.5 -0.7441864176784315 0" />
     <axis xyz="0 1 0"/>
       <limit effort="0.0" lower="-3.14159" upper="3.14159" velocity="0.0"/>
    </joint>
    <link name="rootLink000">
        <inertial>
            <origin xyz="0.6716314339260421 0 0" rpy="0 0 0"/>
            <mass value="1" />
            <inertia ixx="100" ixy="0" ixz="0" iyy="100" iyz="0" izz="100" />
        </inertial>
        <visual>
            <origin xyz="0.6716314339260421 0 0" rpy="0 0 0"/>
            <geometry>
                <box size="1.3432628678520842 1 1" />
            </geometry>
            <material name="Green">
                <color rgba="0 1.0 0 1.0"/>
            </material>
        </visual>
        <collision>
            <origin xyz="0.6716314339260421 0 0" rpy="0 0 0"/>
            <geometry>
                <box size="1.3432628678520842 1 1" />
            </geometry>
        </collision>
    </link>
    <joint name="rootLink000_rootLink0000" type="revolute">
       <parent link="rootLink000"/>
       <child  link="rootLink0000"/>
       <origin rpy="0 0 0" xyz="0.6716314339260421 0 0.5" />
     <axis xyz="0 1 0"/>
       <limit effort="0.0" lower="-3.14159" upper="3.14159" velocity="0.0"/>
    </joint>
    <link name="rootLink0000">
        <inertial>
            <origin xyz="0 0 0.8049882924939593" rpy="0 0 0"/>
            <mass value="1" />
            <inertia ixx="100" ixy="0" ixz="0" iyy="100" iyz="0" izz="100" />
        </inertial>
        <visual>
            <origin xyz="0 0 0.8049882924939593" rpy="0 0 0"/>
            <geometry>
                <box size="1 1 1.6099765849879186" />
            </geometry>
            <material name="Blue">
                <color rgba="0 0 1.0 1.0"/>
            </material>
        </visual>
        <collision>
            <origin xyz="0 0 0.8049882924939593" rpy="0 0 0"/>
            <geometry>
                <box size="1 1 1.6099765849879186" />
            </geometry>
        </collision>
    </link>
    <joint name="rootLink0000_rootLink00001" type="revolute">
       <parent link="rootLink0000"/>
       <child  link="rootLink00001"/>
       <origin rpy="0 0 0" xyz="0.5 0 0.8049882924939593" />
     <axis xyz="0 1 0"/>
       <limit effort="0.0" lower="-3.14159" upper="3.14159" velocity="0.0"/>
    </joint>
    <link name="rootLink00001">
        <inertial>
            <origin xyz="0.794835992929434 0 0" rpy="0 0 0"/>
            <mass value="1" />
            <inertia ixx="100" ixy="0" ixz="0" iyy="100" iyz="0" izz="100" />
        </inertial>
        <visual>
            <origin xyz="0.794835992929434 0 0" rpy="0 0 0"/>
            <geometry>
                <box size="1.589671985858868 1 1" />
            </geometry>
            <material name="Blue">
                <color rgba="0 0 1.0 1.0"/>
            </material>
        </visual>
        <collision>
            <origin xyz="0.794835992929434 0 0" rpy="0 0 0"/>
            <geometry>
                <box size="1.589671985858868 1 1" />
            </geometry>
        </collision>
    </link>
    <joint name="rootLink00001_rootLink000010" type="revolute">
       <parent link="rootLink00001"/>
       <child  link="rootLink000010"/>
       <origin rpy="0 0 0" xyz="0.794835992929434 0 0.5" />
     <axis xyz="0 0 1"/>
       <limit effort="0.0" lower="-3.14159" upper="3.14159" velocity="0.0"/>
    </joint>
    <link name="rootLink000010">
        <inertial>
            <origin xyz="0 0 0.7314046560770018" rpy="0 0 0"/>
            <mass value="1" />
            <inertia ixx="100" ixy="0" ixz="0" iyy="100" iyz="0" izz="100" />
        </inertial>
        <visual>
            <origin xyz="0 0 0.7314046560770018" rpy="0 0 0"/>
            <geometry>
                <box size="1 1 1.4628093121540036" />
            </geometry>
            <material name="Green">
                <color rgba="0 1.0 0 1.0"/>
            </material>
        </visual>
        <collision>
            <origin xyz="0 0 0.7314046560770018" rpy="0 0 0"/>
            <geometry>
                <box size="1 1 1.4628093121540036" />
            </geometry>
        </collision>
    </link>
    <joint name="rootLink00_rootLink001" type="revolute">
       <parent link="rootLink00"/>
       <child  link="rootLink001"/>
       <origin rpy="0 0 0" xyz="0 -0.7441864176784315 0.5" />
     <axis xyz="0 1 0"/>
       <limit effort="0.0" lower="-3.14159" upper="3.14159" velocity="0.0"/>
    </joint>
    <link name="rootLink001">
        <inertial>
            <origin xyz="0 0 0.7500881069248797" rpy="0 0 0"/>
            <mass value="1" />
            <inertia ixx="100" ixy="0" ixz="0" iyy="100" iyz="0" izz="100" />
        </inertial>
        <visual>
            <origin xyz="0 0 0.7500881069248797" rpy="0 0 0"/>
            <geometry>
                <box size="1 1 1.5001762138497594" />
            </geometry>
            <material name="Blue">
                <color rgba="0 0 1.0 1.0"/>
            </material>
        </visual>
        <collision>
            <origin xyz="0 0 0.7500881069248797" rpy="0 0 0"/>
            <geometry>
                <box size="1 1 1.5001762138497594" />
            </geometry>
        </collision>
    </link>
    <joint name="rootLink001_rootLink0010" type="revolute">
       <parent link="rootLink001"/>
       <child  link="rootLink0010"/>
       <origin rpy="0 0 0" xyz="0 0.5 0.7500881069248797" />
     <axis xyz="0 1 0"/>
       <limit effort="0.0" lower="-3.14159" upper="3.14159" velocity="0.0"/>
    </joint>
    <link name="rootLink0010">
        <inertial>
            <origin xyz="0 0.5428469101024862 0" rpy="0 0 0"/>
            <mass value="1" />
            <inertia ixx="100" ixy="0" ixz="0" iyy="100" iyz="0" izz="100" />
        </inertial>
        <visual>
            <origin xyz="0 0.5428469101024862 0" rpy="0 0 0"/>
            <geometry>
                <box size="1 1.0856938202049724 1" />
            </geometry>
            <material name="Green">
                <color rgba="0 1.0 0 1.0"/>
            </material>
        </visual>
        <collision>
            <origin xyz="0 0.5428469101024862 0" rpy="0 0 0"/>
            <geometry>
                <box size="1 1.0856938202049724 1" />
            </geometry>
        </collision>
    </link>
    <joint name="rootLink001_rootLink0011" type="revolute">
       <parent link="rootLink001"/>
       <child  link="rootLink0011"/>
       <origin rpy="0 0 0" xyz="0 0 1.5001762138497594" />
     <axis xyz="0 0 1"/>
       <limit effort="0.0" lower="-3.14159" upper="3.14159" velocity="0.0"/>
    </joint>
    <link name="rootLink0011">
        <inertial>
            <origin xyz="0 0 0.5710973712535895" rpy="0 0 0"/>
            <mass value="1" />
            <inertia ixx="100" ixy="0" ixz="0" iyy="100" iyz="0" izz="100" />
        </inertial>
        <visual>
            <origin xyz="0 0 0.5710973712535895" rpy="0 0 0"/>
            <geometry>
                <box size="1 1 1.142194742507179" />
            </geometry>
            <material name="Blue">
                <color rgba="0 0 1.0 1.0"/>
            </material>
        </visual>
        <collision>
            <origin xyz="0 0 0.5710973712535895" rpy="0 0 0"/>
            <geometry>
                <box size="1 1 1.142194742507179" />
            </geometry>
        </collision>
    </link>
    <joint name="rootLink0011_rootLink00110" type="revolute">
       <parent link="rootLink0011"/>
       <child  link="rootLink00110"/>
       <origin rpy="0 0 0" xyz="-0.5 0 0.5710973712535895" />
     <axis xyz="0 0 1"/>
       <limit effort="0.0" lower="-3.14159" upper="3.14159" velocity="0.0"/>
    </joint>
    <link name="rootLink00110">
        <inertial>
            <origin xyz="-0.77967968033781 0 0" rpy="0 0 0"/>
            <mass value="1" />
            <inertia ixx="100" ixy="0" ixz="0" iyy="100" iyz="0" izz="100" />
        </inertial>
        <visual>
            <origin xyz="-0.77967968033781 0 0" rpy="0 0 0"/>
            <geometry>
                <box size="1.55935936067562 1 1" />
            </geometry>
            <material name="Blue">
                <color rgba="0 0 1.0 1.0"/>
            </material>
        </visual>
        <collision>
            <origin xyz="-0.77967968033781 0 0" rpy="0 0 0"/>
            <geometry>
                <box size="1.55935936067562 1 1" />
            </geometry>
        </collision>
    </link>
    <joint name="rootLink0011_rootLink00111" type="revolute">
       <parent link="rootLink0011"/>
       <child  link="rootLink00111"/>
       <origin rpy="0 0 0" xyz="0 -0.5 0.5710973712535895" />
     <axis xyz="0 1 0"/>
       <limit effort="0.0" lower="-3.14159" upper="3.14159" velocity="0.0"/>
    </joint>
    <link name="rootLink00111">
        <inertial>
            <origin xyz="0 -0.5735450537854258 0" rpy="0 0 0"/>
            <mass value="1" />
            <inertia ixx="100" ixy="0" ixz="0" iyy="100" iyz="0" izz="100" />
        </inertial>
        <visual>
            <origin xyz="0 -0.5735450537854258 0" rpy="0 0 0"/>
            <geometry>
                <box size="1 1.1470901075708515 1" />
            </geometry>
            <material name="Blue">
                <color rgba="0 0 1.0 1.0"/>
            </material>
        </visual>
        <collision>
            <origin xyz="0 -0.5735450537854258 0" rpy="0 0 0"/>
            <geometry>
                <box size="1 1.1470901075708515 1" />
            </geometry>
        </collision>
    </link>
    <joint name="rootLink0011_rootLink00113" type="revolute">
       <parent link="rootLink0011"/>
       <child  link="rootLink00113"/>
       <origin rpy="0 0 0" xyz="0 0 1.142194742507179" />
     <axis xyz="1 0 0"/>
       <limit effort="0.0" lower="-3.14159" upper="3.14159" velocity="0.0"/>
    </joint>
    <link name="rootLink00113">
        <inertial>
            <origin xyz="0 0 0.7379204716027559" rpy="0 0 0"/>
            <mass value="1" />
            <inertia ixx="100" ixy="0" ixz="0" iyy="100" iyz="0" izz="100" />
        </inertial>
        <visual>
            <origin xyz="0 0 0.7379204716027559" rpy="0 0 0"/>
            <geometry>
                <box size="1 1 1.4758409432055117" />
            </geometry>
            <material name="Blue">
                <color rgba="0 0 1.0 1.0"/>
            </material>
        </visual>
        <collision>
            <origin xyz="0 0 0.7379204716027559" rpy="0 0 0"/>
            <geometry>
                <box size="1 1 1.4758409432055117" />
            </geometry>
        </collision>
    </link>
    <joint name="rootLink00113_rootLink001130" type="revolute">
       <parent link="rootLink00113"/>
       <child  link="rootLink001130"/>
       <origin rpy="0 0 0" xyz="-0.5 0 0.7379204716027559" />
     <axis xyz="1 0 0"/>
       <limit effort="0.0" lower="-3.14159" upper="3.14159" velocity="0.0"/>
    </joint>
    <link name="rootLink001130">
        <inertial>
            <origin xyz="-0.9113457296278006 0 0" rpy="0 0 0"/>
            <mass value="1" />
            <inertia ixx="100" ixy="0" ixz="0" iyy="100" iyz="0" izz="100" />
        </inertial>
        <visual>
            <origin xyz="-0.9113457296278006 0 0" rpy="0 0 0"/>
            <geometry>
                <box size="1.8226914592556012 1 1" />
            </geometry>
            <material name="Green">
                <color rgba="0 1.0 0 1.0"/>
            </material>
        </visual>
        <collision>
            <origin xyz="-0.9113457296278006 0 0" rpy="0 0 0"/>
            <geometry>
                <box size="1.8226914592556012 1 1" />
            </geometry>
        </collision>
    </link>
    <joint name="rootLink00113_rootLink001131" type="revolute">
       <parent link="rootLink00113"/>
       <child  link="rootLink001131"/>
       <origin rpy="0 0 0" xyz="0 0 1.4758409432055117" />
     <axis xyz="0 0 1"/>
       <limit effort="0.0" lower="-3.14159" upper="3.14159" velocity="0.0"/>
    </joint>
    <link name="rootLink001131">
        <inertial>
            <origin xyz="0 0 0.7295104493289596" rpy="0 0 0"/>
            <mass value="1" />
            <inertia ixx="100" ixy="0" ixz="0" iyy="100" iyz="0" izz="100" />
        </inertial>
        <visual>
            <origin xyz="0 0 0.7295104493289596" rpy="0 0 0"/>
            <geometry>
                <box size="1 1 1.4590208986579192" />
            </geometry>
            <material name="Green">
                <color rgba="0 1.0 0 1.0"/>
            </material>
        </visual>
        <collision>
            <origin xyz="0 0 0.7295104493289596" rpy="0 0 0"/>
            <geometry>
                <box size="1 1 1.4590208986579192" />
            </geometry>
        </collision>
    </link>
    <joint name="rootLink00_rootLink002" type="revolute">
       <parent link="rootLink00"/>
       <child  link="rootLink002"/>
       <origin rpy="0 0 0" xyz="0 -1.488372835356863 0" />
     <axis xyz="0 1 0"/>
       <limit effort="0.0" lower="-3.14159" upper="3.14159" velocity="0.0"/>
    </joint>
    <link name="rootLink002">
        <inertial>
            <origin xyz="0 -0.9784761203381029 0" rpy="0 0 0"/>
            <mass value="1" />
            <inertia ixx="100" ixy="0" ixz="0" iyy="100" iyz="0" izz="100" />
        </inertial>
        <visual>
            <origin xyz="0 -0.9784761203381029 0" rpy="0 0 0"/>
            <geometry>
                <box size="1 1.9569522406762059 1" />
            </geometry>
            <material name="Blue">
                <color rgba="0 0 1.0 1.0"/>
            </material>
        </visual>
        <collision>
            <origin xyz="0 -0.9784761203381029 0" rpy="0 0 0"/>
            <geometry>
                <box size="1 1.9569522406762059 1" />
            </geometry>
        </collision>
    </link>
    <joint name="rootLink002_rootLink0020" type="revolute">
       <parent link="rootLink002"/>
       <child  link="rootLink0020"/>
       <origin rpy="0 0 0" xyz="0 -0.9784761203381029 0.5" />
     <axis xyz="1 0 0"/>
       <limit effort="0.0" lower="-3.14159" upper="3.14159" velocity="0.0"/>
    </joint>
    <link name="rootLink0020">
        <inertial>
            <origin xyz="0 0 0.6325123337929476" rpy="0 0 0"/>
            <mass value="1" />
            <inertia ixx="100" ixy="0" ixz="0" iyy="100" iyz="0" izz="100" />
        </inertial>
        <visual>
            <origin xyz="0 0 0.6325123337929476" rpy="0 0 0"/>
            <geometry>
                <box size="1 1 1.2650246675858952" />
            </geometry>
            <material name="Green">
                <color rgba="0 1.0 0 1.0"/>
            </material>
        </visual>
        <collision>
            <origin xyz="0 0 0.6325123337929476" rpy="0 0 0"/>
            <geometry>
                <box size="1 1 1.2650246675858952" />
            </geometry>
        </collision>
    </link>
    <joint name="rootLink0020_rootLink00200" type="revolute">
       <parent link="rootLink0020"/>
       <child  link="rootLink00200"/>
       <origin rpy="0 0 0" xyz="0 -0.5 0.6325123337929476" />
     <axis xyz="0 0 1"/>
       <limit effort="0.0" lower="-3.14159" upper="3.14159" velocity="0.0"/>
    </joint>
    <link name="rootLink00200">
        <inertial>
            <origin xyz="0 -0.9521338915982024 0" rpy="0 0 0"/>
            <mass value="1" />
            <inertia ixx="100" ixy="0" ixz="0" iyy="100" iyz="0" izz="100" />
        </inertial>
        <visual>
            <origin xyz="0 -0.9521338915982024 0" rpy="0 0 0"/>
            <geometry>
                <box size="1 1.9042677831964048 1" />
            </geometry>
            <material name="Blue">
                <color rgba="0 0 1.0 1.0"/>
            </material>
        </visual>
        <collision>
            <origin xyz="0 -0.9521338915982024 0" rpy="0 0 0"/>
            <geometry>
                <box size="1 1.9042677831964048 1" />
            </geometry>
        </collision>
    </link>
    <joint name="rootLink0_rootLink01" type="revolute">
       <parent link="rootLink0"/>
       <child  link="rootLink01"/>
       <origin rpy="0 0 0" xyz="-0.5 0 0.5231012439279966" />
     <axis xyz="1 0 0"/>
       <limit effort="0.0" lower="-3.14159" upper="3.14159" velocity="0.0"/>
    </joint>
    <link name="rootLink01">
        <inertial>
            <origin xyz="-0.8641725553807974 0 0" rpy="0 0 0"/>
            <mass value="1" />
            <inertia ixx="100" ixy="0" ixz="0" iyy="100" iyz="0" izz="100" />
        </inertial>
        <visual>
            <origin xyz="-0.8641725553807974 0 0" rpy="0 0 0"/>
            <geometry>
                <box size="1.7283451107615948 1 1" />
            </geometry>
            <material name="Blue">
                <color rgba="0 0 1.0 1.0"/>
            </material>
        </visual>
        <collision>
            <origin xyz="-0.8641725553807974 0 0" rpy="0 0 0"/>
            <geometry>
                <box size="1.7283451107615948 1 1" />
            </geometry>
        </collision>
    </link>
    <joint name="rootLink01_rootLink010" type="revolute">
       <parent link="rootLink01"/>
       <child  link="rootLink010"/>
       <origin rpy="0 0 0" xyz="-0.8641725553807974 0.5 0" />
     <axis xyz="0 0 1"/>
       <limit effort="0.0" lower="-3.14159" upper="3.14159" velocity="0.0"/>
    </joint>
    <link name="rootLink010">
        <inertial>
            <origin xyz="0 0.7434640320473058 0" rpy="0 0 0"/>
            <mass value="1" />
            <inertia ixx="100" ixy="0" ixz="0" iyy="100" iyz="0" izz="100" />
        </inertial>
        <visual>
            <origin xyz="0 0.7434640320473058 0" rpy="0 0 0"/>
            <geometry>
                <box size="1 1.4869280640946116 1" />
            </geometry>
            <material name="Blue">
                <color rgba="0 0 1.0 1.0"/>
            </material>
        </visual>
        <collision>
            <origin xyz="0 0.7434640320473058 0" rpy="0 0 0"/>
            <geometry>
                <box size="1 1.4869280640946116 1" />
            </geometry>
        </collision>
    </link>
    <joint name="rootLink010_rootLink0101" type="revolute">
       <parent link="rootLink010"/>
       <child  link="rootLink0101"/>
       <origin rpy="0 0 0" xyz="0.5 0.7434640320473058 0" />
     <axis xyz="1 0 0"/>
       <limit effort="0.0" lower="-3.14159" upper="3.14159" velocity="0.0"/>
    </joint>
    <link name="rootLink0101">
        <inertial>
            <origin xyz="0.5181236884684526 0 0" rpy="0 0 0"/>
            <mass value="1" />
            <inertia ixx="100" ixy="0" ixz="0" iyy="100" iyz="0" izz="100" />
        </inertial>
        <visual>
            <origin xyz="0.5181236884684526 0 0" rpy="0 0 0"/>
            <geometry>
                <box size="1.0362473769369052 1 1" />
            </geometry>
            <material name="Green">
                <color rgba="0 1.0 0 1.0"/>
            </material>
        </visual>
        <collision>
            <origin xyz="0.5181236884684526 0 0" rpy="0 0 0"/>
            <geometry>
                <box size="1.0362473769369052 1 1" />
            </geometry>
        </collision>
    </link>
    <joint name="rootLink0101_rootLink01010" type="revolute">
       <parent link="rootLink0101"/>
       <child  link="rootLink01010"/>
       <origin rpy="0 0 0" xyz="1.0362473769369052 0 0" />
     <axis xyz="0 1 0"/>
       <limit effort="0.0" lower="-3.14159" upper="3.14159" velocity="0.0"/>
    </joint>
    <link name="rootLink01010">
        <inertial>
            <origin xyz="0.5385367570089941 0 0" rpy="0 0 0"/>
            <mass value="1" />
            <inertia ixx="100" ixy="0" ixz="0" iyy="100" iyz="0" izz="100" />
        </inertial>
        <visual>
            <origin xyz="0.5385367570089941 0 0" rpy="0 0 0"/>
            <geometry>
                <box size="1.0770735140179881 1 1" />
            </geometry>
            <material name="Blue">
                <color rgba="0 0 1.0 1.0"/>
            </material>
        </visual>
        <collision>
            <origin xyz="0.5385367570089941 0 0" rpy="0 0 0"/>
            <geometry>
                <box size="1.0770735140179881 1 1" />
            </geometry>
        </collision>
    </link>
    <joint name="rootLink01_rootLink011" type="revolute">
       <parent link="rootLink01"/>
       <child  link="rootLink011"/>
       <origin rpy="0 0 0" xyz="0.0 0 0" />
     <axis xyz="0 1 0"/>
       <limit effort="0.0" lower="-3.14159" upper="3.14159" velocity="0.0"/>
    </joint>
    <link name="rootLink011">
        <inertial>
            <origin xyz="0.8317881622743145 0 0" rpy="0 0 0"/>
            <mass value="1" />
            <inertia ixx="100" ixy="0" ixz="0" iyy="100" iyz="0" izz="100" />
        </inertial>
        <visual>
            <origin xyz="0.8317881622743145 0 0" rpy="0 0 0"/>
            <geometry>
                <box size="1.663576324548629 1 1" />
            </geometry>
            <material name="Blue">
                <color rgba="0 0 1.0 1.0"/>
            </material>
        </visual>
        <collision>
            <origin xyz="0.8317881622743145 0 0" rpy="0 0 0"/>
            <geometry>
                <box size="1.663576324548629 1 1" />
            </geometry>
        </collision>
    </link>
    <joint name="rootLink01_rootLink013" type="revolute">
       <parent link="rootLink01"/>
       <child  link="rootLink013"/>
       <origin rpy="0 0 0" xyz="-0.8641725553807974 0 0.5" />
     <axis xyz="1 0 0"/>
       <limit effort="0.0" lower="-3.14159" upper="3.14159" velocity="0.0"/>
    </joint>
    <link name="rootLink013">
        <inertial>
            <origin xyz="0 0 0.5345416834835786" rpy="0 0 0"/>
            <mass value="1" />
            <inertia ixx="100" ixy="0" ixz="0" iyy="100" iyz="0" izz="100" />
        </inertial>
        <visual>
            <origin xyz="0 0 0.5345416834835786" rpy="0 0 0"/>
            <geometry>
                <box size="1 1 1.0690833669671571" />
            </geometry>
            <material name="Blue">
                <color rgba="0 0 1.0 1.0"/>
            </material>
        </visual>
        <collision>
            <origin xyz="0 0 0.5345416834835786" rpy="0 0 0"/>
            <geometry>
                <box size="1 1 1.0690833669671571" />
            </geometry>
        </collision>
    </link>
    <joint name="rootLink013_rootLink0130" type="revolute">
       <parent link="rootLink013"/>
       <child  link="rootLink0130"/>
       <origin rpy="0 0 0" xyz="0 -0.5 0.5345416834835786" />
     <axis xyz="0 0 1"/>
       <limit effort="0.0" lower="-3.14159" upper="3.14159" velocity="0.0"/>
    </joint>
    <link name="rootLink0130">
        <inertial>
            <origin xyz="0 -0.7797210876628473 0" rpy="0 0 0"/>
            <mass value="1" />
            <inertia ixx="100" ixy="0" ixz="0" iyy="100" iyz="0" izz="100" />
        </inertial>
        <visual>
            <origin xyz="0 -0.7797210876628473 0" rpy="0 0 0"/>
            <geometry>
                <box size="1 1.5594421753256946 1" />
            </geometry>
            <material name="Blue">
                <color rgba="0 0 1.0 1.0"/>
            </material>
        </visual>
        <collision>
            <origin xyz="0 -0.7797210876628473 0" rpy="0 0 0"/>
            <geometry>
                <box size="1 1.5594421753256946 1" />
            </geometry>
        </collision>
    </link>
    <joint name="rootLink0130_rootLink01300" type="revolute">
       <parent link="rootLink0130"/>
       <child  link="rootLink01300"/>
       <origin rpy="0 0 0" xyz="0 -0.7797210876628473 0.5" />
     <axis xyz="0 0 1"/>
       <limit effort="0.0" lower="-3.14159" upper="3.14159" velocity="0.0"/>
    </joint>
    <link name="rootLink01300">
        <inertial>
            <origin xyz="0 0 0.8202801622366573" rpy="0 0 0"/>
            <mass value="1" />
            <inertia ixx="100" ixy="0" ixz="0" iyy="100" iyz="0" izz="100" />
        </inertial>
        <visual>
            <origin xyz="0 0 0.8202801622366573" rpy="0 0 0"/>
            <geometry>
                <box size="1 1 1.6405603244733147" />
            </geometry>
            <material name="Blue">
                <color rgba="0 0 1.0 1.0"/>
            </material>
        </visual>
        <collision>
            <origin xyz="0 0 0.8202801622366573" rpy="0 0 0"/>
            <geometry>
                <box size="1 1 1.6405603244733147" />
            </geometry>
        </collision>
    </link>
    <joint name="rootLink01300_rootLink013001" type="revolute">
       <parent link="rootLink01300"/>
       <child  link="rootLink013001"/>
       <origin rpy="0 0 0" xyz="0 0.5 0.8202801622366573" />
     <axis xyz="0 0 1"/>
       <limit effort="0.0" lower="-3.14159" upper="3.14159" velocity="0.0"/>
    </joint>
    <link name="rootLink013001">
        <inertial>
            <origin xyz="0 0.8049696115041134 0" rpy="0 0 0"/>
            <mass value="1" />
            <inertia ixx="100" ixy="0" ixz="0" iyy="100" iyz="0" izz="100" />
        </inertial>
        <visual>
            <origin xyz="0 0.8049696115041134 0" rpy="0 0 0"/>
            <geometry>
                <box size="1 1.6099392230082268 1" />
            </geometry>
            <material name="Blue">
                <color rgba="0 0 1.0 1.0"/>
            </material>
        </visual>
        <collision>
            <origin xyz="0 0.8049696115041134 0" rpy="0 0 0"/>
            <geometry>
                <box size="1 1.6099392230082268 1" />
            </geometry>
        </collision>
    </link>
    <joint name="rootLink013001_rootLink0130010" type="revolute">
       <parent link="rootLink013001"/>
       <child  link="rootLink0130010"/>
       <origin rpy="0 0 0" xyz="0.5 0.8049696115041134 0" />
     <axis xyz="0 0 1"/>
       <limit effort="0.0" lower="-3.14159" upper="3.14159" velocity="0.0"/>
    </joint>
    <link name="rootLink0130010">
        <inertial>
            <origin xyz="0.8362856036098929 0 0" rpy="0 0 0"/>
            <mass value="1" />
            <inertia ixx="100" ixy="0" ixz="0" iyy="100" iyz="0" izz="100" />
        </inertial>
        <visual>
            <origin xyz="0.8362856036098929 0 0" rpy="0 0 0"/>
            <geometry>
                <box size="1.6725712072197858 1 1" />
            </geometry>
            <material name="Blue">
                <color rgba="0 0 1.0 1.0"/>
            </material>
        </visual>
        <collision>
            <origin xyz="0.8362856036098929 0 0" rpy="0 0 0"/>
            <geometry>
                <box size="1.6725712072197858 1 1" />
            </geometry>
        </collision>
    </link>
    <joint name="rootLink013001_rootLink0130012" type="revolute">
       <parent link="rootLink013001"/>
       <child  link="rootLink0130012"/>
       <origin rpy="0 0 0" xyz="0 0.0 0" />
     <axis xyz="1 0 0"/>
       <limit effort="0.0" lower="-3.14159" upper="3.14159" velocity="0.0"/>
    </joint>
    <link name="rootLink0130012">
        <inertial>
            <origin xyz="0 -0.5042555437356694 0" rpy="0 0 0"/>
            <mass value="1" />
            <inertia ixx="100" ixy="0" ixz="0" iyy="100" iyz="0" izz="100" />
        </inertial>
        <visual>
            <origin xyz="0 -0.5042555437356694 0" rpy="0 0 0"/>
            <geometry>
                <box size="1 1.0085110874713388 1" />
            </geometry>
            <material name="Green">
                <color rgba="0 1.0 0 1.0"/>
            </material>
        </visual>
        <collision>
            <origin xyz="0 -0.5042555437356694 0" rpy="0 0 0"/>
            <geometry>
                <box size="1 1.0085110874713388 1" />
            </geometry>
        </collision>
    </link>
    <joint name="rootLink0130_rootLink01303" type="revolute">
       <parent link="rootLink0130"/>
       <child  link="rootLink01303"/>
       <origin rpy="0 0 0" xyz="0.5 -0.7797210876628473 0" />
     <axis xyz="1 0 0"/>
       <limit effort="0.0" lower="-3.14159" upper="3.14159" velocity="0.0"/>
    </joint>
    <link name="rootLink01303">
        <inertial>
            <origin xyz="0.5100768317306913 0 0" rpy="0 0 0"/>
            <mass value="1" />
            <inertia ixx="100" ixy="0" ixz="0" iyy="100" iyz="0" izz="100" />
        </inertial>
        <visual>
            <origin xyz="0.5100768317306913 0 0" rpy="0 0 0"/>
            <geometry>
                <box size="1.0201536634613826 1 1" />
            </geometry>
            <material name="Green">
                <color rgba="0 1.0 0 1.0"/>
            </material>
        </visual>
        <collision>
            <origin xyz="0.5100768317306913 0 0" rpy="0 0 0"/>
            <geometry>
                <box size="1.0201536634613826 1 1" />
            </geometry>
        </collision>
    </link>
    <joint name="rootLink013_rootLink0131" type="revolute">
       <parent link="rootLink013"/>
       <child  link="rootLink0131"/>
       <origin rpy="0 0 0" xyz="-0.5 0 0.5345416834835786" />
     <axis xyz="0 1 0"/>
       <limit effort="0.0" lower="-3.14159" upper="3.14159" velocity="0.0"/>
    </joint>
    <link name="rootLink0131">
        <inertial>
            <origin xyz="-0.9213136152427966 0 0" rpy="0 0 0"/>
            <mass value="1" />
            <inertia ixx="100" ixy="0" ixz="0" iyy="100" iyz="0" izz="100" />
        </inertial>
        <visual>
            <origin xyz="-0.9213136152427966 0 0" rpy="0 0 0"/>
            <geometry>
                <box size="1.8426272304855933 1 1" />
            </geometry>
            <material name="Green">
                <color rgba="0 1.0 0 1.0"/>
            </material>
        </visual>
        <collision>
            <origin xyz="-0.9213136152427966 0 0" rpy="0 0 0"/>
            <geometry>
                <box size="1.8426272304855933 1 1" />
            </geometry>
        </collision>
    </link>
</robot>