<robot name = "robot">
    <link name="rootLink">
        <inertial>
            <origin xyz="0 0 0.5" rpy="0 0 0"/>
            <mass value="1" />
            <inertia ixx="100" ixy="0" ixz="0" iyy="100" iyz="0" izz="100" />
        </inertial>
        <visual>
            <origin xyz="0 0 0.5" rpy="0 0 0"/>
            <geometry>
                <box size="1 1 1" />
            </geometry>
            <material name="Blue">
                <color rgba="0 0 1.0 1.0"/>
            </material>
        </visual>
        <collision>
            <origin xyz="0 0 0.5" rpy="0 0 0"/>
            <geometry>
                <box size="1 1 1" />
            </geometry>
        </collision>
    </link>
    <joint name="rootLink_rootLink0" type="revolute">
       <parent link="rootLink"/>
       <child  link="rootLink0"/>
       <origin rpy="0 0 0" xyz="0 0 1.0" />
     <axis xyz="0 0 1"/>
       <limit effort="0.0" lower="-3.14159" upper="3.14159" velocity="0.0"/>
    </joint>
    <link name="rootLink0">
        <inertial>
            <origin xyz="0 0 0.8897989718769341" rpy="0 0 0"/>
            <mass value="1" />
            <inertia ixx="100" ixy="0" ixz="0" iyy="100" iyz="0" izz="100" />
        </inertial>
        <visual>
            <origin xyz="0 0 0.8897989718769341" rpy="0 0 0"/>
            <geometry>
                <box size="1 1 1.7795979437538683" />
            </geometry>
            <material name="Green">
                <color rgba="0 1.0 0 1.0"/>
            </material>
        </visual>
        <collision>
            <origin xyz="0 0 0.8897989718769341" rpy="0 0 0"/>
            <geometry>
                <box size="1 1 1.7795979437538683" />
            </geometry>
        </collision>
    </link>
    <joint name="rootLink0_rootLink00" type="revolute">
       <parent link="rootLink0"/>
       <child  link="rootLink00"/>
       <origin rpy="0 0 0" xyz="0.5 0 0.8897989718769341" />
     <axis xyz="0 1 0"/>
       <limit effort="0.0" lower="-3.14159" upper="3.14159" velocity="0.0"/>
    </joint>
    <link name="rootLink00">
        <inertial>
            <origin xyz="0.9669555581269179 0 0" rpy="0 0 0"/>
            <mass value="1" />
            <inertia ixx="100" ixy="0" ixz="0" iyy="100" iyz="0" izz="100" />
        </inertial>
        <visual>
            <origin xyz="0.9669555581269179 0 0" rpy="0 0 0"/>
            <geometry>
                <box size="1.9339111162538358 1 1" />
            </geometry>
            <material name="Blue">
                <color rgba="0 0 1.0 1.0"/>
            </material>
        </visual>
        <collision>
            <origin xyz="0.9669555581269179 0 0" rpy="0 0 0"/>
            <geometry>
                <box size="1.9339111162538358 1 1" />
            </geometry>
        </collision>
    </link>
    <joint name="rootLink00_rootLink000" type="revolute">
       <parent link="rootLink00"/>
       <child  link="rootLink000"/>
       <origin rpy="0 0 0" xyz="0.9669555581269179 0 -0.5" />
     <axis xyz="1 0 0"/>
       <limit effort="0.0" lower="-3.14159" upper="3.14159" velocity="0.0"/>
    </joint>
    <link name="rootLink000">
        <inertial>
            <origin xyz="0 0 -0.5441944912272418" rpy="0 0 0"/>
            <mass value="1" />
            <inertia ixx="100" ixy="0" ixz="0" iyy="100" iyz="0" izz="100" />
        </inertial>
        <visual>
            <origin xyz="0 0 -0.5441944912272418" rpy="0 0 0"/>
            <geometry>
                <box size="1 1 1.0883889824544837" />
            </geometry>
            <material name="Blue">
                <color rgba="0 0 1.0 1.0"/>
            </material>
        </visual>
        <collision>
            <origin xyz="0 0 -0.5441944912272418" rpy="0 0 0"/>
            <geometry>
                <box size="1 1 1.0883889824544837" />
            </geometry>
        </collision>
    </link>
    <joint name="rootLink000_rootLink0000" type="revolute">
       <parent link="rootLink000"/>
       <child  link="rootLink0000"/>
       <origin rpy="0 0 0" xyz="0 -0.5 -0.5441944912272418" />
     <axis xyz="1 0 0"/>
       <limit effort="0.0" lower="-3.14159" upper="3.14159" velocity="0.0"/>
    </joint>
    <link name="rootLink0000">
        <inertial>
            <origin xyz="0 -0.7990518358442634 0" rpy="0 0 0"/>
            <mass value="1" />
            <inertia ixx="100" ixy="0" ixz="0" iyy="100" iyz="0" izz="100" />
        </inertial>
        <visual>
            <origin xyz="0 -0.7990518358442634 0" rpy="0 0 0"/>
            <geometry>
                <box size="1 1.5981036716885269 1" />
            </geometry>
            <material name="Blue">
                <color rgba="0 0 1.0 1.0"/>
            </material>
        </visual>
        <collision>
            <origin xyz="0 -0.7990518358442634 0" rpy="0 0 0"/>
            <geometry>
                <box size="1 1.5981036716885269 1" />
            </geometry>
        </collision>
    </link>
</robot>