<robot name = "robot">
    <link name="rootLink">
        <inertial>
            <origin xyz="0 0 0.5" rpy="0 0 0"/>
            <mass value="1" />
            <inertia ixx="100" ixy="0" ixz="0" iyy="100" iyz="0" izz="100" />
        </inertial>
        <visual>
            <origin xyz="0 0 0.5" rpy="0 0 0"/>
            <geometry>
                <box size="1 1 1" />
            </geometry>
            <material name="Blue">
                <color rgba="0 0 1.0 1.0"/>
            </material>
        </visual>
        <collision>
            <origin xyz="0 0 0.5" rpy="0 0 0"/>
            <geometry>
                <box size="1 1 1" />
            </geometry>
        </collision>
    </link>
    <joint name="rootLink_rootLink0" type="revolute">
       <parent link="rootLink"/>
       <child  link="rootLink0"/>
       <origin rpy="0 0 0" xyz="0 0.5 0.5" />
     <axis xyz="1 0 0"/>
       <limit effort="0.0" lower="-3.14159" upper="3.14159" velocity="0.0"/>
    </joint>
    <link name="rootLink0">
        <inertial>
            <origin xyz="0 0.8135001982699273 0" rpy="0 0 0"/>
            <mass value="1" />
            <inertia ixx="100" ixy="0" ixz="0" iyy="100" iyz="0" izz="100" />
        </inertial>
        <visual>
            <origin xyz="0 0.8135001982699273 0" rpy="0 0 0"/>
            <geometry>
                <box size="1 1.6270003965398545 1" />
            </geometry>
            <material name="Green">
                <color rgba="0 1.0 0 1.0"/>
            </material>
        </visual>
        <collision>
            <origin xyz="0 0.8135001982699273 0" rpy="0 0 0"/>
            <geometry>
                <box size="1 1.6270003965398545 1" />
            </geometry>
        </collision>
    </link>
    <joint name="rootLink0_rootLink00" type="revolute">
       <parent link="rootLink0"/>
       <child  link="rootLink00"/>
       <origin rpy="0 0 0" xyz="0 0.8135001982699273 0.5" />
     <axis xyz="0 1 0"/>
       <limit effort="0.0" lower="-3.14159" upper="3.14159" velocity="0.0"/>
    </joint>
    <link name="rootLink00">
        <inertial>
            <origin xyz="0 0 0.7936014420630051" rpy="0 0 0"/>
            <mass value="1" />
            <inertia ixx="100" ixy="0" ixz="0" iyy="100" iyz="0" izz="100" />
        </inertial>
        <visual>
            <origin xyz="0 0 0.7936014420630051" rpy="0 0 0"/>
            <geometry>
                <box size="1 1 1.5872028841260102" />
            </geometry>
            <material name="Blue">
                <color rgba="0 0 1.0 1.0"/>
            </material>
        </visual>
        <collision>
            <origin xyz="0 0 0.7936014420630051" rpy="0 0 0"/>
            <geometry>
                <box size="1 1 1.5872028841260102" />
            </geometry>
        </collision>
    </link>
    <joint name="rootLink00_rootLink000" type="revolute">
       <parent link="rootLink00"/>
       <child  link="rootLink000"/>
       <origin rpy="0 0 0" xyz="0 0 1.5872028841260102" />
     <axis xyz="0 1 0"/>
       <limit effort="0.0" lower="-3.14159" upper="3.14159" velocity="0.0"/>
    </joint>
    <link name="rootLink000">
        <inertial>
            <origin xyz="0 0 0.7002995889697026" rpy="0 0 0"/>
            <mass value="1" />
            <inertia ixx="100" ixy="0" ixz="0" iyy="100" iyz="0" izz="100" />
        </inertial>
        <visual>
            <origin xyz="0 0 0.7002995889697026" rpy="0 0 0"/>
            <geometry>
                <box size="1 1 1.4005991779394051" />
            </geometry>
            <material name="Blue">
                <color rgba="0 0 1.0 1.0"/>
            </material>
        </visual>
        <collision>
            <origin xyz="0 0 0.7002995889697026" rpy="0 0 0"/>
            <geometry>
                <box size="1 1 1.4005991779394051" />
            </geometry>
        </collision>
    </link>
    <joint name="rootLink00_rootLink001" type="revolute">
       <parent link="rootLink00"/>
       <child  link="rootLink001"/>
       <origin rpy="0 0 0" xyz="0.5 0 0.7936014420630051" />
     <axis xyz="0 0 1"/>
       <limit effort="0.0" lower="-3.14159" upper="3.14159" velocity="0.0"/>
    </joint>
    <link name="rootLink001">
        <inertial>
            <origin xyz="0.5933159289527408 0 0" rpy="0 0 0"/>
            <mass value="1" />
            <inertia ixx="100" ixy="0" ixz="0" iyy="100" iyz="0" izz="100" />
        </inertial>
        <visual>
            <origin xyz="0.5933159289527408 0 0" rpy="0 0 0"/>
            <geometry>
                <box size="1.1866318579054815 1 1" />
            </geometry>
            <material name="Green">
                <color rgba="0 1.0 0 1.0"/>
            </material>
        </visual>
        <collision>
            <origin xyz="0.5933159289527408 0 0" rpy="0 0 0"/>
            <geometry>
                <box size="1.1866318579054815 1 1" />
            </geometry>
        </collision>
    </link>
    <joint name="rootLink00_rootLink003" type="revolute">
       <parent link="rootLink00"/>
       <child  link="rootLink003"/>
       <origin rpy="0 0 0" xyz="0 0.5 0.7936014420630051" />
     <axis xyz="0 0 1"/>
       <limit effort="0.0" lower="-3.14159" upper="3.14159" velocity="0.0"/>
    </joint>
    <link name="rootLink003">
        <inertial>
            <origin xyz="0 0.5950972009130722 0" rpy="0 0 0"/>
            <mass value="1" />
            <inertia ixx="100" ixy="0" ixz="0" iyy="100" iyz="0" izz="100" />
        </inertial>
        <visual>
            <origin xyz="0 0.5950972009130722 0" rpy="0 0 0"/>
            <geometry>
                <box size="1 1.1901944018261443 1" />
            </geometry>
            <material name="Green">
                <color rgba="0 1.0 0 1.0"/>
            </material>
        </visual>
        <collision>
            <origin xyz="0 0.5950972009130722 0" rpy="0 0 0"/>
            <geometry>
                <box size="1 1.1901944018261443 1" />
            </geometry>
        </collision>
    </link>
    <joint name="rootLink003_rootLink0030" type="revolute">
       <parent link="rootLink003"/>
       <child  link="rootLink0030"/>
       <origin rpy="0 0 0" xyz="0 0.5950972009130722 0.5" />
     <axis xyz="0 0 1"/>
       <limit effort="0.0" lower="-3.14159" upper="3.14159" velocity="0.0"/>
    </joint>
    <link name="rootLink0030">
        <inertial>
            <origin xyz="0 0 0.9805305455319453" rpy="0 0 0"/>
            <mass value="1" />
            <inertia ixx="100" ixy="0" ixz="0" iyy="100" iyz="0" izz="100" />
        </inertial>
        <visual>
            <origin xyz="0 0 0.9805305455319453" rpy="0 0 0"/>
            <geometry>
                <box size="1 1 1.9610610910638906" />
            </geometry>
            <material name="Blue">
                <color rgba="0 0 1.0 1.0"/>
            </material>
        </visual>
        <collision>
            <origin xyz="0 0 0.9805305455319453" rpy="0 0 0"/>
            <geometry>
                <box size="1 1 1.9610610910638906" />
            </geometry>
        </collision>
    </link>
    <joint name="rootLink0030_rootLink00300" type="revolute">
       <parent link="rootLink0030"/>
       <child  link="rootLink00300"/>
       <origin rpy="0 0 0" xyz="0 0 1.9610610910638906" />
     <axis xyz="0 1 0"/>
       <limit effort="0.0" lower="-3.14159" upper="3.14159" velocity="0.0"/>
    </joint>
    <link name="rootLink00300">
        <inertial>
            <origin xyz="0 0 0.5018098007611256" rpy="0 0 0"/>
            <mass value="1" />
            <inertia ixx="100" ixy="0" ixz="0" iyy="100" iyz="0" izz="100" />
        </inertial>
        <visual>
            <origin xyz="0 0 0.5018098007611256" rpy="0 0 0"/>
            <geometry>
                <box size="1 1 1.0036196015222512" />
            </geometry>
            <material name="Green">
                <color rgba="0 1.0 0 1.0"/>
            </material>
        </visual>
        <collision>
            <origin xyz="0 0 0.5018098007611256" rpy="0 0 0"/>
            <geometry>
                <box size="1 1 1.0036196015222512" />
            </geometry>
        </collision>
    </link>
    <joint name="rootLink0030_rootLink00301" type="revolute">
       <parent link="rootLink0030"/>
       <child  link="rootLink00301"/>
       <origin rpy="0 0 0" xyz="0.5 0 0.9805305455319453" />
     <axis xyz="1 0 0"/>
       <limit effort="0.0" lower="-3.14159" upper="3.14159" velocity="0.0"/>
    </joint>
    <link name="rootLink00301">
        <inertial>
            <origin xyz="0.541267072399744 0 0" rpy="0 0 0"/>
            <mass value="1" />
            <inertia ixx="100" ixy="0" ixz="0" iyy="100" iyz="0" izz="100" />
        </inertial>
        <visual>
            <origin xyz="0.541267072399744 0 0" rpy="0 0 0"/>
            <geometry>
                <box size="1.082534144799488 1 1" />
            </geometry>
            <material name="Blue">
                <color rgba="0 0 1.0 1.0"/>
            </material>
        </visual>
        <collision>
            <origin xyz="0.541267072399744 0 0" rpy="0 0 0"/>
            <geometry>
                <box size="1.082534144799488 1 1" />
            </geometry>
        </collision>
    </link>
    <joint name="rootLink0030_rootLink00304" type="revolute">
       <parent link="rootLink0030"/>
       <child  link="rootLink00304"/>
       <origin rpy="0 0 0" xyz="0 0.5 0.9805305455319453" />
     <axis xyz="0 0 1"/>
       <limit effort="0.0" lower="-3.14159" upper="3.14159" velocity="0.0"/>
    </joint>
    <link name="rootLink00304">
        <inertial>
            <origin xyz="0 0.8845534301314486 0" rpy="0 0 0"/>
            <mass value="1" />
            <inertia ixx="100" ixy="0" ixz="0" iyy="100" iyz="0" izz="100" />
        </inertial>
        <visual>
            <origin xyz="0 0.8845534301314486 0" rpy="0 0 0"/>
            <geometry>
                <box size="1 1.7691068602628972 1" />
            </geometry>
            <material name="Blue">
                <color rgba="0 0 1.0 1.0"/>
            </material>
        </visual>
        <collision>
            <origin xyz="0 0.8845534301314486 0" rpy="0 0 0"/>
            <geometry>
                <box size="1 1.7691068602628972 1" />
            </geometry>
        </collision>
    </link>
    <joint name="rootLink003_rootLink0031" type="revolute">
       <parent link="rootLink003"/>
       <child  link="rootLink0031"/>
       <origin rpy="0 0 0" xyz="0 1.1901944018261443 0" />
     <axis xyz="0 0 1"/>
       <limit effort="0.0" lower="-3.14159" upper="3.14159" velocity="0.0"/>
    </joint>
    <link name="rootLink0031">
        <inertial>
            <origin xyz="0 0.9332401464557696 0" rpy="0 0 0"/>
            <mass value="1" />
            <inertia ixx="100" ixy="0" ixz="0" iyy="100" iyz="0" izz="100" />
        </inertial>
        <visual>
            <origin xyz="0 0.9332401464557696 0" rpy="0 0 0"/>
            <geometry>
                <box size="1 1.8664802929115392 1" />
            </geometry>
            <material name="Blue">
                <color rgba="0 0 1.0 1.0"/>
            </material>
        </visual>
        <collision>
            <origin xyz="0 0.9332401464557696 0" rpy="0 0 0"/>
            <geometry>
                <box size="1 1.8664802929115392 1" />
            </geometry>
        </collision>
    </link>
    <joint name="rootLink0031_rootLink00310" type="revolute">
       <parent link="rootLink0031"/>
       <child  link="rootLink00310"/>
       <origin rpy="0 0 0" xyz="0 1.8664802929115392 0" />
     <axis xyz="0 1 0"/>
       <limit effort="0.0" lower="-3.14159" upper="3.14159" velocity="0.0"/>
    </joint>
    <link name="rootLink00310">
        <inertial>
            <origin xyz="0 0.6232909582953232 0" rpy="0 0 0"/>
            <mass value="1" />
            <inertia ixx="100" ixy="0" ixz="0" iyy="100" iyz="0" izz="100" />
        </inertial>
        <visual>
            <origin xyz="0 0.6232909582953232 0" rpy="0 0 0"/>
            <geometry>
                <box size="1 1.2465819165906464 1" />
            </geometry>
            <material name="Green">
                <color rgba="0 1.0 0 1.0"/>
            </material>
        </visual>
        <collision>
            <origin xyz="0 0.6232909582953232 0" rpy="0 0 0"/>
            <geometry>
                <box size="1 1.2465819165906464 1" />
            </geometry>
        </collision>
    </link>
    <joint name="rootLink0031_rootLink00311" type="revolute">
       <parent link="rootLink0031"/>
       <child  link="rootLink00311"/>
       <origin rpy="0 0 0" xyz="0.5 0.9332401464557696 0" />
     <axis xyz="0 0 1"/>
       <limit effort="0.0" lower="-3.14159" upper="3.14159" velocity="0.0"/>
    </joint>
    <link name="rootLink00311">
        <inertial>
            <origin xyz="0.8469567394029018 0 0" rpy="0 0 0"/>
            <mass value="1" />
            <inertia ixx="100" ixy="0" ixz="0" iyy="100" iyz="0" izz="100" />
        </inertial>
        <visual>
            <origin xyz="0.8469567394029018 0 0" rpy="0 0 0"/>
            <geometry>
                <box size="1.6939134788058037 1 1" />
            </geometry>
            <material name="Blue">
                <color rgba="0 0 1.0 1.0"/>
            </material>
        </visual>
        <collision>
            <origin xyz="0.8469567394029018 0 0" rpy="0 0 0"/>
            <geometry>
                <box size="1.6939134788058037 1 1" />
            </geometry>
        </collision>
    </link>
    <joint name="rootLink0_rootLink01" type="revolute">
       <parent link="rootLink0"/>
       <child  link="rootLink01"/>
       <origin rpy="0 0 0" xyz="0.5 0.8135001982699273 0" />
     <axis xyz="0 0 1"/>
       <limit effort="0.0" lower="-3.14159" upper="3.14159" velocity="0.0"/>
    </joint>
    <link name="rootLink01">
        <inertial>
            <origin xyz="0.9239795630551733 0 0" rpy="0 0 0"/>
            <mass value="1" />
            <inertia ixx="100" ixy="0" ixz="0" iyy="100" iyz="0" izz="100" />
        </inertial>
        <visual>
            <origin xyz="0.9239795630551733 0 0" rpy="0 0 0"/>
            <geometry>
                <box size="1.8479591261103465 1 1" />
            </geometry>
            <material name="Blue">
                <color rgba="0 0 1.0 1.0"/>
            </material>
        </visual>
        <collision>
            <origin xyz="0.9239795630551733 0 0" rpy="0 0 0"/>
            <geometry>
                <box size="1.8479591261103465 1 1" />
            </geometry>
        </collision>
    </link>
    <joint name="rootLink01_rootLink010" type="revolute">
       <parent link="rootLink01"/>
       <child  link="rootLink010"/>
       <origin rpy="0 0 0" xyz="0.9239795630551733 0 0.5" />
     <axis xyz="0 0 1"/>
       <limit effort="0.0" lower="-3.14159" upper="3.14159" velocity="0.0"/>
    </joint>
    <link name="rootLink010">
        <inertial>
            <origin xyz="0 0 0.7972724642233032" rpy="0 0 0"/>
            <mass value="1" />
            <inertia ixx="100" ixy="0" ixz="0" iyy="100" iyz="0" izz="100" />
        </inertial>
        <visual>
            <origin xyz="0 0 0.7972724642233032" rpy="0 0 0"/>
            <geometry>
                <box size="1 1 1.5945449284466064" />
            </geometry>
            <material name="Green">
                <color rgba="0 1.0 0 1.0"/>
            </material>
        </visual>
        <collision>
            <origin xyz="0 0 0.7972724642233032" rpy="0 0 0"/>
            <geometry>
                <box size="1 1 1.5945449284466064" />
            </geometry>
        </collision>
    </link>
    <joint name="rootLink01_rootLink011" type="revolute">
       <parent link="rootLink01"/>
       <child  link="rootLink011"/>
       <origin rpy="0 0 0" xyz="1.8479591261103465 0 0" />
     <axis xyz="0 0 1"/>
       <limit effort="0.0" lower="-3.14159" upper="3.14159" velocity="0.0"/>
    </joint>
    <link name="rootLink011">
        <inertial>
            <origin xyz="0.6119675542888169 0 0" rpy="0 0 0"/>
            <mass value="1" />
            <inertia ixx="100" ixy="0" ixz="0" iyy="100" iyz="0" izz="100" />
        </inertial>
        <visual>
            <origin xyz="0.6119675542888169 0 0" rpy="0 0 0"/>
            <geometry>
                <box size="1.2239351085776338 1 1" />
            </geometry>
            <material name="Green">
                <color rgba="0 1.0 0 1.0"/>
            </material>
        </visual>
        <collision>
            <origin xyz="0.6119675542888169 0 0" rpy="0 0 0"/>
            <geometry>
                <box size="1.2239351085776338 1 1" />
            </geometry>
        </collision>
    </link>
    <joint name="rootLink0_rootLink03" type="revolute">
       <parent link="rootLink0"/>
       <child  link="rootLink03"/>
       <origin rpy="0 0 0" xyz="0 1.6270003965398545 0" />
     <axis xyz="1 0 0"/>
       <limit effort="0.0" lower="-3.14159" upper="3.14159" velocity="0.0"/>
    </joint>
    <link name="rootLink03">
        <inertial>
            <origin xyz="0 0.9354409355301735 0" rpy="0 0 0"/>
            <mass value="1" />
            <inertia ixx="100" ixy="0" ixz="0" iyy="100" iyz="0" izz="100" />
        </inertial>
        <visual>
            <origin xyz="0 0.9354409355301735 0" rpy="0 0 0"/>
            <geometry>
                <box size="1 1.870881871060347 1" />
            </geometry>
            <material name="Green">
                <color rgba="0 1.0 0 1.0"/>
            </material>
        </visual>
        <collision>
            <origin xyz="0 0.9354409355301735 0" rpy="0 0 0"/>
            <geometry>
                <box size="1 1.870881871060347 1" />
            </geometry>
        </collision>
    </link>
</robot>