<robot name = "robot">
    <link name="rootLink">
        <inertial>
            <origin xyz="0 0 0.5" rpy="0 0 0"/>
            <mass value="1" />
            <inertia ixx="100" ixy="0" ixz="0" iyy="100" iyz="0" izz="100" />
        </inertial>
        <visual>
            <origin xyz="0 0 0.5" rpy="0 0 0"/>
            <geometry>
                <box size="1 1 1" />
            </geometry>
            <material name="Blue">
                <color rgba="0 0 1.0 1.0"/>
            </material>
        </visual>
        <collision>
            <origin xyz="0 0 0.5" rpy="0 0 0"/>
            <geometry>
                <box size="1 1 1" />
            </geometry>
        </collision>
    </link>
    <joint name="rootLink_rootLink0" type="revolute">
       <parent link="rootLink"/>
       <child  link="rootLink0"/>
       <origin rpy="0 0 0" xyz="0 0 1.0" />
     <axis xyz="1 0 0"/>
       <limit effort="0.0" lower="-3.14159" upper="3.14159" velocity="0.0"/>
    </joint>
    <link name="rootLink0">
        <inertial>
            <origin xyz="0 0 0.8623620337789628" rpy="0 0 0"/>
            <mass value="1" />
            <inertia ixx="100" ixy="0" ixz="0" iyy="100" iyz="0" izz="100" />
        </inertial>
        <visual>
            <origin xyz="0 0 0.8623620337789628" rpy="0 0 0"/>
            <geometry>
                <box size="1 1 1.7247240675579256" />
            </geometry>
            <material name="Blue">
                <color rgba="0 0 1.0 1.0"/>
            </material>
        </visual>
        <collision>
            <origin xyz="0 0 0.8623620337789628" rpy="0 0 0"/>
            <geometry>
                <box size="1 1 1.7247240675579256" />
            </geometry>
        </collision>
    </link>
    <joint name="rootLink0_rootLink00" type="revolute">
       <parent link="rootLink0"/>
       <child  link="rootLink00"/>
       <origin rpy="0 0 0" xyz="0 0 1.7247240675579256" />
     <axis xyz="1 0 0"/>
       <limit effort="0.0" lower="-3.14159" upper="3.14159" velocity="0.0"/>
    </joint>
    <link name="rootLink00">
        <inertial>
            <origin xyz="0 0 0.6260803873553998" rpy="0 0 0"/>
            <mass value="1" />
            <inertia ixx="100" ixy="0" ixz="0" iyy="100" iyz="0" izz="100" />
        </inertial>
        <visual>
            <origin xyz="0 0 0.6260803873553998" rpy="0 0 0"/>
            <geometry>
                <box size="1 1 1.2521607747107997" />
            </geometry>
            <material name="Green">
                <color rgba="0 1.0 0 1.0"/>
            </material>
        </visual>
        <collision>
            <origin xyz="0 0 0.6260803873553998" rpy="0 0 0"/>
            <geometry>
                <box size="1 1 1.2521607747107997" />
            </geometry>
        </collision>
    </link>
    <joint name="rootLink00_rootLink000" type="revolute">
       <parent link="rootLink00"/>
       <child  link="rootLink000"/>
       <origin rpy="0 0 0" xyz="0 0.5 0.6260803873553998" />
     <axis xyz="1 0 0"/>
       <limit effort="0.0" lower="-3.14159" upper="3.14159" velocity="0.0"/>
    </joint>
    <link name="rootLink000">
        <inertial>
            <origin xyz="0 0.8718551031863804 0" rpy="0 0 0"/>
            <mass value="1" />
            <inertia ixx="100" ixy="0" ixz="0" iyy="100" iyz="0" izz="100" />
        </inertial>
        <visual>
            <origin xyz="0 0.8718551031863804 0" rpy="0 0 0"/>
            <geometry>
                <box size="1 1.7437102063727608 1" />
            </geometry>
            <material name="Green">
                <color rgba="0 1.0 0 1.0"/>
            </material>
        </visual>
        <collision>
            <origin xyz="0 0.8718551031863804 0" rpy="0 0 0"/>
            <geometry>
                <box size="1 1.7437102063727608 1" />
            </geometry>
        </collision>
    </link>
    <joint name="rootLink000_rootLink0000" type="revolute">
       <parent link="rootLink000"/>
       <child  link="rootLink0000"/>
       <origin rpy="0 0 0" xyz="0.5 0.8718551031863804 0" />
     <axis xyz="1 0 0"/>
       <limit effort="0.0" lower="-3.14159" upper="3.14159" velocity="0.0"/>
    </joint>
    <link name="rootLink0000">
        <inertial>
            <origin xyz="0.985214484761673 0 0" rpy="0 0 0"/>
            <mass value="1" />
            <inertia ixx="100" ixy="0" ixz="0" iyy="100" iyz="0" izz="100" />
        </inertial>
        <visual>
            <origin xyz="0.985214484761673 0 0" rpy="0 0 0"/>
            <geometry>
                <box size="1.970428969523346 1 1" />
            </geometry>
            <material name="Green">
                <color rgba="0 1.0 0 1.0"/>
            </material>
        </visual>
        <collision>
            <origin xyz="0.985214484761673 0 0" rpy="0 0 0"/>
            <geometry>
                <box size="1.970428969523346 1 1" />
            </geometry>
        </collision>
    </link>
    <joint name="rootLink000_rootLink0001" type="revolute">
       <parent link="rootLink000"/>
       <child  link="rootLink0001"/>
       <origin rpy="0 0 0" xyz="0 0.8718551031863804 -0.5" />
     <axis xyz="0 0 1"/>
       <limit effort="0.0" lower="-3.14159" upper="3.14159" velocity="0.0"/>
    </joint>
    <link name="rootLink0001">
        <inertial>
            <origin xyz="0 0 -0.8240759750122344" rpy="0 0 0"/>
            <mass value="1" />
            <inertia ixx="100" ixy="0" ixz="0" iyy="100" iyz="0" izz="100" />
        </inertial>
        <visual>
            <origin xyz="0 0 -0.8240759750122344" rpy="0 0 0"/>
            <geometry>
                <box size="1 1 1.6481519500244688" />
            </geometry>
            <material name="Blue">
                <color rgba="0 0 1.0 1.0"/>
            </material>
        </visual>
        <collision>
            <origin xyz="0 0 -0.8240759750122344" rpy="0 0 0"/>
            <geometry>
                <box size="1 1 1.6481519500244688" />
            </geometry>
        </collision>
    </link>
    <joint name="rootLink0_rootLink02" type="revolute">
       <parent link="rootLink0"/>
       <child  link="rootLink02"/>
       <origin rpy="0 0 0" xyz="0.5 0 0.8623620337789628" />
     <axis xyz="1 0 0"/>
       <limit effort="0.0" lower="-3.14159" upper="3.14159" velocity="0.0"/>
    </joint>
    <link name="rootLink02">
        <inertial>
            <origin xyz="0.8860889832607262 0 0" rpy="0 0 0"/>
            <mass value="1" />
            <inertia ixx="100" ixy="0" ixz="0" iyy="100" iyz="0" izz="100" />
        </inertial>
        <visual>
            <origin xyz="0.8860889832607262 0 0" rpy="0 0 0"/>
            <geometry>
                <box size="1.7721779665214523 1 1" />
            </geometry>
            <material name="Blue">
                <color rgba="0 0 1.0 1.0"/>
            </material>
        </visual>
        <collision>
            <origin xyz="0.8860889832607262 0 0" rpy="0 0 0"/>
            <geometry>
                <box size="1.7721779665214523 1 1" />
            </geometry>
        </collision>
    </link>
    <joint name="rootLink02_rootLink020" type="revolute">
       <parent link="rootLink02"/>
       <child  link="rootLink020"/>
       <origin rpy="0 0 0" xyz="0.8860889832607262 0.5 0" />
     <axis xyz="0 1 0"/>
       <limit effort="0.0" lower="-3.14159" upper="3.14159" velocity="0.0"/>
    </joint>
    <link name="rootLink020">
        <inertial>
            <origin xyz="0 0.7248363100366364 0" rpy="0 0 0"/>
            <mass value="1" />
            <inertia ixx="100" ixy="0" ixz="0" iyy="100" iyz="0" izz="100" />
        </inertial>
        <visual>
            <origin xyz="0 0.7248363100366364 0" rpy="0 0 0"/>
            <geometry>
                <box size="1 1.4496726200732728 1" />
            </geometry>
            <material name="Blue">
                <color rgba="0 0 1.0 1.0"/>
            </material>
        </visual>
        <collision>
            <origin xyz="0 0.7248363100366364 0" rpy="0 0 0"/>
            <geometry>
                <box size="1 1.4496726200732728 1" />
            </geometry>
        </collision>
    </link>
    <joint name="rootLink020_rootLink0200" type="revolute">
       <parent link="rootLink020"/>
       <child  link="rootLink0200"/>
       <origin rpy="0 0 0" xyz="0 0.7248363100366364 0.5" />
     <axis xyz="0 1 0"/>
       <limit effort="0.0" lower="-3.14159" upper="3.14159" velocity="0.0"/>
    </joint>
    <link name="rootLink0200">
        <inertial>
            <origin xyz="0 0 0.6229696547977777" rpy="0 0 0"/>
            <mass value="1" />
            <inertia ixx="100" ixy="0" ixz="0" iyy="100" iyz="0" izz="100" />
        </inertial>
        <visual>
            <origin xyz="0 0 0.6229696547977777" rpy="0 0 0"/>
            <geometry>
                <box size="1 1 1.2459393095955553" />
            </geometry>
            <material name="Blue">
                <color rgba="0 0 1.0 1.0"/>
            </material>
        </visual>
        <collision>
            <origin xyz="0 0 0.6229696547977777" rpy="0 0 0"/>
            <geometry>
                <box size="1 1 1.2459393095955553" />
            </geometry>
        </collision>
    </link>
    <joint name="rootLink020_rootLink0202" type="revolute">
       <parent link="rootLink020"/>
       <child  link="rootLink0202"/>
       <origin rpy="0 0 0" xyz="0.5 0.7248363100366364 0" />
     <axis xyz="0 0 1"/>
       <limit effort="0.0" lower="-3.14159" upper="3.14159" velocity="0.0"/>
    </joint>
    <link name="rootLink0202">
        <inertial>
            <origin xyz="0.6147341698765124 0 0" rpy="0 0 0"/>
            <mass value="1" />
            <inertia ixx="100" ixy="0" ixz="0" iyy="100" iyz="0" izz="100" />
        </inertial>
        <visual>
            <origin xyz="0.6147341698765124 0 0" rpy="0 0 0"/>
            <geometry>
                <box size="1.2294683397530248 1 1" />
            </geometry>
            <material name="Green">
                <color rgba="0 1.0 0 1.0"/>
            </material>
        </visual>
        <collision>
            <origin xyz="0.6147341698765124 0 0" rpy="0 0 0"/>
            <geometry>
                <box size="1.2294683397530248 1 1" />
            </geometry>
        </collision>
    </link>
    <joint name="rootLink0202_rootLink02020" type="revolute">
       <parent link="rootLink0202"/>
       <child  link="rootLink02020"/>
       <origin rpy="0 0 0" xyz="0.6147341698765124 -0.5 0" />
     <axis xyz="1 0 0"/>
       <limit effort="0.0" lower="-3.14159" upper="3.14159" velocity="0.0"/>
    </joint>
    <link name="rootLink02020">
        <inertial>
            <origin xyz="0 -0.8277777121249997 0" rpy="0 0 0"/>
            <mass value="1" />
            <inertia ixx="100" ixy="0" ixz="0" iyy="100" iyz="0" izz="100" />
        </inertial>
        <visual>
            <origin xyz="0 -0.8277777121249997 0" rpy="0 0 0"/>
            <geometry>
                <box size="1 1.6555554242499995 1" />
            </geometry>
            <material name="Blue">
                <color rgba="0 0 1.0 1.0"/>
            </material>
        </visual>
        <collision>
            <origin xyz="0 -0.8277777121249997 0" rpy="0 0 0"/>
            <geometry>
                <box size="1 1.6555554242499995 1" />
            </geometry>
        </collision>
    </link>
    <joint name="rootLink02_rootLink022" type="revolute">
       <parent link="rootLink02"/>
       <child  link="rootLink022"/>
       <origin rpy="0 0 0" xyz="0.8860889832607262 0 0.5" />
     <axis xyz="0 1 0"/>
       <limit effort="0.0" lower="-3.14159" upper="3.14159" velocity="0.0"/>
    </joint>
    <link name="rootLink022">
        <inertial>
            <origin xyz="0 0 0.6022768889756649" rpy="0 0 0"/>
            <mass value="1" />
            <inertia ixx="100" ixy="0" ixz="0" iyy="100" iyz="0" izz="100" />
        </inertial>
        <visual>
            <origin xyz="0 0 0.6022768889756649" rpy="0 0 0"/>
            <geometry>
                <box size="1 1 1.2045537779513298" />
            </geometry>
            <material name="Blue">
                <color rgba="0 0 1.0 1.0"/>
            </material>
        </visual>
        <collision>
            <origin xyz="0 0 0.6022768889756649" rpy="0 0 0"/>
            <geometry>
                <box size="1 1 1.2045537779513298" />
            </geometry>
        </collision>
    </link>
    <joint name="rootLink022_rootLink0220" type="revolute">
       <parent link="rootLink022"/>
       <child  link="rootLink0220"/>
       <origin rpy="0 0 0" xyz="0 0.5 0.6022768889756649" />
     <axis xyz="1 0 0"/>
       <limit effort="0.0" lower="-3.14159" upper="3.14159" velocity="0.0"/>
    </joint>
    <link name="rootLink0220">
        <inertial>
            <origin xyz="0 0.5616423858969326 0" rpy="0 0 0"/>
            <mass value="1" />
            <inertia ixx="100" ixy="0" ixz="0" iyy="100" iyz="0" izz="100" />
        </inertial>
        <visual>
            <origin xyz="0 0.5616423858969326 0" rpy="0 0 0"/>
            <geometry>
                <box size="1 1.1232847717938652 1" />
            </geometry>
            <material name="Green">
                <color rgba="0 1.0 0 1.0"/>
            </material>
        </visual>
        <collision>
            <origin xyz="0 0.5616423858969326 0" rpy="0 0 0"/>
            <geometry>
                <box size="1 1.1232847717938652 1" />
            </geometry>
        </collision>
    </link>
    <joint name="rootLink0_rootLink03" type="revolute">
       <parent link="rootLink0"/>
       <child  link="rootLink03"/>
       <origin rpy="0 0 0" xyz="0 -0.5 0.8623620337789628" />
     <axis xyz="1 0 0"/>
       <limit effort="0.0" lower="-3.14159" upper="3.14159" velocity="0.0"/>
    </joint>
    <link name="rootLink03">
        <inertial>
            <origin xyz="0 -0.7046136346234982 0" rpy="0 0 0"/>
            <mass value="1" />
            <inertia ixx="100" ixy="0" ixz="0" iyy="100" iyz="0" izz="100" />
        </inertial>
        <visual>
            <origin xyz="0 -0.7046136346234982 0" rpy="0 0 0"/>
            <geometry>
                <box size="1 1.4092272692469965 1" />
            </geometry>
            <material name="Green">
                <color rgba="0 1.0 0 1.0"/>
            </material>
        </visual>
        <collision>
            <origin xyz="0 -0.7046136346234982 0" rpy="0 0 0"/>
            <geometry>
                <box size="1 1.4092272692469965 1" />
            </geometry>
        </collision>
    </link>
</robot>