<robot name = "robot">
    <link name="rootLink">
        <inertial>
            <origin xyz="0 0 0.5" rpy="0 0 0"/>
            <mass value="1" />
            <inertia ixx="100" ixy="0" ixz="0" iyy="100" iyz="0" izz="100" />
        </inertial>
        <visual>
            <origin xyz="0 0 0.5" rpy="0 0 0"/>
            <geometry>
                <box size="1 1 1" />
            </geometry>
            <material name="Green">
                <color rgba="0 1.0 0 1.0"/>
            </material>
        </visual>
        <collision>
            <origin xyz="0 0 0.5" rpy="0 0 0"/>
            <geometry>
                <box size="1 1 1" />
            </geometry>
        </collision>
    </link>
    <joint name="rootLink_rootLink0" type="revolute">
       <parent link="rootLink"/>
       <child  link="rootLink0"/>
       <origin rpy="0 0 0" xyz="0 0 1.0" />
     <axis xyz="0 0 1"/>
       <limit effort="0.0" lower="-3.14159" upper="3.14159" velocity="0.0"/>
    </joint>
    <link name="rootLink0">
        <inertial>
            <origin xyz="0 0 0.7262948795880374" rpy="0 0 0"/>
            <mass value="1" />
            <inertia ixx="100" ixy="0" ixz="0" iyy="100" iyz="0" izz="100" />
        </inertial>
        <visual>
            <origin xyz="0 0 0.7262948795880374" rpy="0 0 0"/>
            <geometry>
                <box size="1 1 1.4525897591760748" />
            </geometry>
            <material name="Blue">
                <color rgba="0 0 1.0 1.0"/>
            </material>
        </visual>
        <collision>
            <origin xyz="0 0 0.7262948795880374" rpy="0 0 0"/>
            <geometry>
                <box size="1 1 1.4525897591760748" />
            </geometry>
        </collision>
    </link>
    <joint name="rootLink0_rootLink00" type="revolute">
       <parent link="rootLink0"/>
       <child  link="rootLink00"/>
       <origin rpy="0 0 0" xyz="0 0.5 0.7262948795880374" />
     <axis xyz="0 1 0"/>
       <limit effort="0.0" lower="-3.14159" upper="3.14159" velocity="0.0"/>
    </joint>
    <link name="rootLink00">
        <inertial>
            <origin xyz="0 0.6041194962512434 0" rpy="0 0 0"/>
            <mass value="1" />
            <inertia ixx="100" ixy="0" ixz="0" iyy="100" iyz="0" izz="100" />
        </inertial>
        <visual>
            <origin xyz="0 0.6041194962512434 0" rpy="0 0 0"/>
            <geometry>
                <box size="1 1.2082389925024868 1" />
            </geometry>
            <material name="Green">
                <color rgba="0 1.0 0 1.0"/>
            </material>
        </visual>
        <collision>
            <origin xyz="0 0.6041194962512434 0" rpy="0 0 0"/>
            <geometry>
                <box size="1 1.2082389925024868 1" />
            </geometry>
        </collision>
    </link>
    <joint name="rootLink00_rootLink000" type="revolute">
       <parent link="rootLink00"/>
       <child  link="rootLink000"/>
       <origin rpy="0 0 0" xyz="0.5 0.6041194962512434 0" />
     <axis xyz="1 0 0"/>
       <limit effort="0.0" lower="-3.14159" upper="3.14159" velocity="0.0"/>
    </joint>
    <link name="rootLink000">
        <inertial>
            <origin xyz="0.9574545282269485 0 0" rpy="0 0 0"/>
            <mass value="1" />
            <inertia ixx="100" ixy="0" ixz="0" iyy="100" iyz="0" izz="100" />
        </inertial>
        <visual>
            <origin xyz="0.9574545282269485 0 0" rpy="0 0 0"/>
            <geometry>
                <box size="1.914909056453897 1 1" />
            </geometry>
            <material name="Green">
                <color rgba="0 1.0 0 1.0"/>
            </material>
        </visual>
        <collision>
            <origin xyz="0.9574545282269485 0 0" rpy="0 0 0"/>
            <geometry>
                <box size="1.914909056453897 1 1" />
            </geometry>
        </collision>
    </link>
    <joint name="rootLink000_rootLink0000" type="revolute">
       <parent link="rootLink000"/>
       <child  link="rootLink0000"/>
       <origin rpy="0 0 0" xyz="0.9574545282269485 0.5 0" />
     <axis xyz="1 0 0"/>
       <limit effort="0.0" lower="-3.14159" upper="3.14159" velocity="0.0"/>
    </joint>
    <link name="rootLink0000">
        <inertial>
            <origin xyz="0 0.6956547634299204 0" rpy="0 0 0"/>
            <mass value="1" />
            <inertia ixx="100" ixy="0" ixz="0" iyy="100" iyz="0" izz="100" />
        </inertial>
        <visual>
            <origin xyz="0 0.6956547634299204 0" rpy="0 0 0"/>
            <geometry>
                <box size="1 1.3913095268598408 1" />
            </geometry>
            <material name="Green">
                <color rgba="0 1.0 0 1.0"/>
            </material>
        </visual>
        <collision>
            <origin xyz="0 0.6956547634299204 0" rpy="0 0 0"/>
            <geometry>
                <box size="1 1.3913095268598408 1" />
            </geometry>
        </collision>
    </link>
    <joint name="rootLink00_rootLink001" type="revolute">
       <parent link="rootLink00"/>
       <child  link="rootLink001"/>
       <origin rpy="0 0 0" xyz="0 0.0 0" />
     <axis xyz="0 1 0"/>
       <limit effort="0.0" lower="-3.14159" upper="3.14159" velocity="0.0"/>
    </joint>
    <link name="rootLink001">
        <inertial>
            <origin xyz="0 -0.5285082070999065 0" rpy="0 0 0"/>
            <mass value="1" />
            <inertia ixx="100" ixy="0" ixz="0" iyy="100" iyz="0" izz="100" />
        </inertial>
        <visual>
            <origin xyz="0 -0.5285082070999065 0" rpy="0 0 0"/>
            <geometry>
                <box size="1 1.057016414199813 1" />
            </geometry>
            <material name="Green">
                <color rgba="0 1.0 0 1.0"/>
            </material>
        </visual>
        <collision>
            <origin xyz="0 -0.5285082070999065 0" rpy="0 0 0"/>
            <geometry>
                <box size="1 1.057016414199813 1" />
            </geometry>
        </collision>
    </link>
    <joint name="rootLink0_rootLink01" type="revolute">
       <parent link="rootLink0"/>
       <child  link="rootLink01"/>
       <origin rpy="0 0 0" xyz="-0.5 0 0.7262948795880374" />
     <axis xyz="1 0 0"/>
       <limit effort="0.0" lower="-3.14159" upper="3.14159" velocity="0.0"/>
    </joint>
    <link name="rootLink01">
        <inertial>
            <origin xyz="-0.5743159883410941 0 0" rpy="0 0 0"/>
            <mass value="1" />
            <inertia ixx="100" ixy="0" ixz="0" iyy="100" iyz="0" izz="100" />
        </inertial>
        <visual>
            <origin xyz="-0.5743159883410941 0 0" rpy="0 0 0"/>
            <geometry>
                <box size="1.1486319766821882 1 1" />
            </geometry>
            <material name="Blue">
                <color rgba="0 0 1.0 1.0"/>
            </material>
        </visual>
        <collision>
            <origin xyz="-0.5743159883410941 0 0" rpy="0 0 0"/>
            <geometry>
                <box size="1.1486319766821882 1 1" />
            </geometry>
        </collision>
    </link>
    <joint name="rootLink01_rootLink010" type="revolute">
       <parent link="rootLink01"/>
       <child  link="rootLink010"/>
       <origin rpy="0 0 0" xyz="-0.5743159883410941 -0.5 0" />
     <axis xyz="0 0 1"/>
       <limit effort="0.0" lower="-3.14159" upper="3.14159" velocity="0.0"/>
    </joint>
    <link name="rootLink010">
        <inertial>
            <origin xyz="0 -0.7061220222796654 0" rpy="0 0 0"/>
            <mass value="1" />
            <inertia ixx="100" ixy="0" ixz="0" iyy="100" iyz="0" izz="100" />
        </inertial>
        <visual>
            <origin xyz="0 -0.7061220222796654 0" rpy="0 0 0"/>
            <geometry>
                <box size="1 1.4122440445593307 1" />
            </geometry>
            <material name="Green">
                <color rgba="0 1.0 0 1.0"/>
            </material>
        </visual>
        <collision>
            <origin xyz="0 -0.7061220222796654 0" rpy="0 0 0"/>
            <geometry>
                <box size="1 1.4122440445593307 1" />
            </geometry>
        </collision>
    </link>
    <joint name="rootLink010_rootLink0100" type="revolute">
       <parent link="rootLink010"/>
       <child  link="rootLink0100"/>
       <origin rpy="0 0 0" xyz="0 -0.7061220222796654 -0.5" />
     <axis xyz="1 0 0"/>
       <limit effort="0.0" lower="-3.14159" upper="3.14159" velocity="0.0"/>
    </joint>
    <link name="rootLink0100">
        <inertial>
            <origin xyz="0 0 -0.5603589558844022" rpy="0 0 0"/>
            <mass value="1" />
            <inertia ixx="100" ixy="0" ixz="0" iyy="100" iyz="0" izz="100" />
        </inertial>
        <visual>
            <origin xyz="0 0 -0.5603589558844022" rpy="0 0 0"/>
            <geometry>
                <box size="1 1 1.1207179117688044" />
            </geometry>
            <material name="Blue">
                <color rgba="0 0 1.0 1.0"/>
            </material>
        </visual>
        <collision>
            <origin xyz="0 0 -0.5603589558844022" rpy="0 0 0"/>
            <geometry>
                <box size="1 1 1.1207179117688044" />
            </geometry>
        </collision>
    </link>
    <joint name="rootLink010_rootLink0101" type="revolute">
       <parent link="rootLink010"/>
       <child  link="rootLink0101"/>
       <origin rpy="0 0 0" xyz="0.5 -0.7061220222796654 0" />
     <axis xyz="0 0 1"/>
       <limit effort="0.0" lower="-3.14159" upper="3.14159" velocity="0.0"/>
    </joint>
    <link name="rootLink0101">
        <inertial>
            <origin xyz="0.5293851267702042 0 0" rpy="0 0 0"/>
            <mass value="1" />
            <inertia ixx="100" ixy="0" ixz="0" iyy="100" iyz="0" izz="100" />
        </inertial>
        <visual>
            <origin xyz="0.5293851267702042 0 0" rpy="0 0 0"/>
            <geometry>
                <box size="1.0587702535404084 1 1" />
            </geometry>
            <material name="Blue">
                <color rgba="0 0 1.0 1.0"/>
            </material>
        </visual>
        <collision>
            <origin xyz="0.5293851267702042 0 0" rpy="0 0 0"/>
            <geometry>
                <box size="1.0587702535404084 1 1" />
            </geometry>
        </collision>
    </link>
    <joint name="rootLink0101_rootLink01013" type="revolute">
       <parent link="rootLink0101"/>
       <child  link="rootLink01013"/>
       <origin rpy="0 0 0" xyz="1.0587702535404084 0 0" />
     <axis xyz="0 1 0"/>
       <limit effort="0.0" lower="-3.14159" upper="3.14159" velocity="0.0"/>
    </joint>
    <link name="rootLink01013">
        <inertial>
            <origin xyz="0.5859894008834889 0 0" rpy="0 0 0"/>
            <mass value="1" />
            <inertia ixx="100" ixy="0" ixz="0" iyy="100" iyz="0" izz="100" />
        </inertial>
        <visual>
            <origin xyz="0.5859894008834889 0 0" rpy="0 0 0"/>
            <geometry>
                <box size="1.1719788017669779 1 1" />
            </geometry>
            <material name="Blue">
                <color rgba="0 0 1.0 1.0"/>
            </material>
        </visual>
        <collision>
            <origin xyz="0.5859894008834889 0 0" rpy="0 0 0"/>
            <geometry>
                <box size="1.1719788017669779 1 1" />
            </geometry>
        </collision>
    </link>
    <joint name="rootLink0_rootLink02" type="revolute">
       <parent link="rootLink0"/>
       <child  link="rootLink02"/>
       <origin rpy="0 0 0" xyz="0 0 1.4525897591760748" />
     <axis xyz="1 0 0"/>
       <limit effort="0.0" lower="-3.14159" upper="3.14159" velocity="0.0"/>
    </joint>
    <link name="rootLink02">
        <inertial>
            <origin xyz="0 0 0.8477297334434418" rpy="0 0 0"/>
            <mass value="1" />
            <inertia ixx="100" ixy="0" ixz="0" iyy="100" iyz="0" izz="100" />
        </inertial>
        <visual>
            <origin xyz="0 0 0.8477297334434418" rpy="0 0 0"/>
            <geometry>
                <box size="1 1 1.6954594668868836" />
            </geometry>
            <material name="Blue">
                <color rgba="0 0 1.0 1.0"/>
            </material>
        </visual>
        <collision>
            <origin xyz="0 0 0.8477297334434418" rpy="0 0 0"/>
            <geometry>
                <box size="1 1 1.6954594668868836" />
            </geometry>
        </collision>
    </link>
    <joint name="rootLink02_rootLink020" type="revolute">
       <parent link="rootLink02"/>
       <child  link="rootLink020"/>
       <origin rpy="0 0 0" xyz="0 0.5 0.8477297334434418" />
     <axis xyz="1 0 0"/>
       <limit effort="0.0" lower="-3.14159" upper="3.14159" velocity="0.0"/>
    </joint>
    <link name="rootLink020">
        <inertial>
            <origin xyz="0 0.5783236704989385 0" rpy="0 0 0"/>
            <mass value="1" />
            <inertia ixx="100" ixy="0" ixz="0" iyy="100" iyz="0" izz="100" />
        </inertial>
        <visual>
            <origin xyz="0 0.5783236704989385 0" rpy="0 0 0"/>
            <geometry>
                <box size="1 1.156647340997877 1" />
            </geometry>
            <material name="Green">
                <color rgba="0 1.0 0 1.0"/>
            </material>
        </visual>
        <collision>
            <origin xyz="0 0.5783236704989385 0" rpy="0 0 0"/>
            <geometry>
                <box size="1 1.156647340997877 1" />
            </geometry>
        </collision>
    </link>
    <joint name="rootLink020_rootLink0200" type="revolute">
       <parent link="rootLink020"/>
       <child  link="rootLink0200"/>
       <origin rpy="0 0 0" xyz="0.5 0.5783236704989385 0" />
     <axis xyz="0 0 1"/>
       <limit effort="0.0" lower="-3.14159" upper="3.14159" velocity="0.0"/>
    </joint>
    <link name="rootLink0200">
        <inertial>
            <origin xyz="0.9232575979671055 0 0" rpy="0 0 0"/>
            <mass value="1" />
            <inertia ixx="100" ixy="0" ixz="0" iyy="100" iyz="0" izz="100" />
        </inertial>
        <visual>
            <origin xyz="0.9232575979671055 0 0" rpy="0 0 0"/>
            <geometry>
                <box size="1.846515195934211 1 1" />
            </geometry>
            <material name="Green">
                <color rgba="0 1.0 0 1.0"/>
            </material>
        </visual>
        <collision>
            <origin xyz="0.9232575979671055 0 0" rpy="0 0 0"/>
            <geometry>
                <box size="1.846515195934211 1 1" />
            </geometry>
        </collision>
    </link>
</robot>