<robot name = "robot">
    <link name="rootLink">
        <inertial>
            <origin xyz="0 0 0.5" rpy="0 0 0"/>
            <mass value="1" />
            <inertia ixx="100" ixy="0" ixz="0" iyy="100" iyz="0" izz="100" />
        </inertial>
        <visual>
            <origin xyz="0 0 0.5" rpy="0 0 0"/>
            <geometry>
                <box size="1 1 1" />
            </geometry>
            <material name="Green">
                <color rgba="0 1.0 0 1.0"/>
            </material>
        </visual>
        <collision>
            <origin xyz="0 0 0.5" rpy="0 0 0"/>
            <geometry>
                <box size="1 1 1" />
            </geometry>
        </collision>
    </link>
    <joint name="rootLink_rootLink0" type="revolute">
       <parent link="rootLink"/>
       <child  link="rootLink0"/>
       <origin rpy="0 0 0" xyz="0 0 1.0" />
     <axis xyz="0 1 0"/>
       <limit effort="0.0" lower="-3.14159" upper="3.14159" velocity="0.0"/>
    </joint>
    <link name="rootLink0">
        <inertial>
            <origin xyz="0 0 0.928556336909977" rpy="0 0 0"/>
            <mass value="1" />
            <inertia ixx="100" ixy="0" ixz="0" iyy="100" iyz="0" izz="100" />
        </inertial>
        <visual>
            <origin xyz="0 0 0.928556336909977" rpy="0 0 0"/>
            <geometry>
                <box size="1 1 1.857112673819954" />
            </geometry>
            <material name="Green">
                <color rgba="0 1.0 0 1.0"/>
            </material>
        </visual>
        <collision>
            <origin xyz="0 0 0.928556336909977" rpy="0 0 0"/>
            <geometry>
                <box size="1 1 1.857112673819954" />
            </geometry>
        </collision>
    </link>
    <joint name="rootLink0_rootLink00" type="revolute">
       <parent link="rootLink0"/>
       <child  link="rootLink00"/>
       <origin rpy="0 0 0" xyz="0.5 0 0.928556336909977" />
     <axis xyz="0 0 1"/>
       <limit effort="0.0" lower="-3.14159" upper="3.14159" velocity="0.0"/>
    </joint>
    <link name="rootLink00">
        <inertial>
            <origin xyz="0.8833177299073383 0 0" rpy="0 0 0"/>
            <mass value="1" />
            <inertia ixx="100" ixy="0" ixz="0" iyy="100" iyz="0" izz="100" />
        </inertial>
        <visual>
            <origin xyz="0.8833177299073383 0 0" rpy="0 0 0"/>
            <geometry>
                <box size="1.7666354598146765 1 1" />
            </geometry>
            <material name="Blue">
                <color rgba="0 0 1.0 1.0"/>
            </material>
        </visual>
        <collision>
            <origin xyz="0.8833177299073383 0 0" rpy="0 0 0"/>
            <geometry>
                <box size="1.7666354598146765 1 1" />
            </geometry>
        </collision>
    </link>
    <joint name="rootLink00_rootLink000" type="revolute">
       <parent link="rootLink00"/>
       <child  link="rootLink000"/>
       <origin rpy="0 0 0" xyz="1.7666354598146765 0 0" />
     <axis xyz="1 0 0"/>
       <limit effort="0.0" lower="-3.14159" upper="3.14159" velocity="0.0"/>
    </joint>
    <link name="rootLink000">
        <inertial>
            <origin xyz="0.6843437827536588 0 0" rpy="0 0 0"/>
            <mass value="1" />
            <inertia ixx="100" ixy="0" ixz="0" iyy="100" iyz="0" izz="100" />
        </inertial>
        <visual>
            <origin xyz="0.6843437827536588 0 0" rpy="0 0 0"/>
            <geometry>
                <box size="1.3686875655073176 1 1" />
            </geometry>
            <material name="Blue">
                <color rgba="0 0 1.0 1.0"/>
            </material>
        </visual>
        <collision>
            <origin xyz="0.6843437827536588 0 0" rpy="0 0 0"/>
            <geometry>
                <box size="1.3686875655073176 1 1" />
            </geometry>
        </collision>
    </link>
    <joint name="rootLink000_rootLink0001" type="revolute">
       <parent link="rootLink000"/>
       <child  link="rootLink0001"/>
       <origin rpy="0 0 0" xyz="0.6843437827536588 -0.5 0" />
     <axis xyz="0 0 1"/>
       <limit effort="0.0" lower="-3.14159" upper="3.14159" velocity="0.0"/>
    </joint>
    <link name="rootLink0001">
        <inertial>
            <origin xyz="0 -0.9022610171098919 0" rpy="0 0 0"/>
            <mass value="1" />
            <inertia ixx="100" ixy="0" ixz="0" iyy="100" iyz="0" izz="100" />
        </inertial>
        <visual>
            <origin xyz="0 -0.9022610171098919 0" rpy="0 0 0"/>
            <geometry>
                <box size="1 1.8045220342197839 1" />
            </geometry>
            <material name="Blue">
                <color rgba="0 0 1.0 1.0"/>
            </material>
        </visual>
        <collision>
            <origin xyz="0 -0.9022610171098919 0" rpy="0 0 0"/>
            <geometry>
                <box size="1 1.8045220342197839 1" />
            </geometry>
        </collision>
    </link>
    <joint name="rootLink0001_rootLink00010" type="revolute">
       <parent link="rootLink0001"/>
       <child  link="rootLink00010"/>
       <origin rpy="0 0 0" xyz="-0.5 -0.9022610171098919 0" />
     <axis xyz="1 0 0"/>
       <limit effort="0.0" lower="-3.14159" upper="3.14159" velocity="0.0"/>
    </joint>
    <link name="rootLink00010">
        <inertial>
            <origin xyz="-0.8263785165885282 0 0" rpy="0 0 0"/>
            <mass value="1" />
            <inertia ixx="100" ixy="0" ixz="0" iyy="100" iyz="0" izz="100" />
        </inertial>
        <visual>
            <origin xyz="-0.8263785165885282 0 0" rpy="0 0 0"/>
            <geometry>
                <box size="1.6527570331770565 1 1" />
            </geometry>
            <material name="Green">
                <color rgba="0 1.0 0 1.0"/>
            </material>
        </visual>
        <collision>
            <origin xyz="-0.8263785165885282 0 0" rpy="0 0 0"/>
            <geometry>
                <box size="1.6527570331770565 1 1" />
            </geometry>
        </collision>
    </link>
    <joint name="rootLink00_rootLink003" type="revolute">
       <parent link="rootLink00"/>
       <child  link="rootLink003"/>
       <origin rpy="0 0 0" xyz="0.8833177299073383 0 -0.5" />
     <axis xyz="0 0 1"/>
       <limit effort="0.0" lower="-3.14159" upper="3.14159" velocity="0.0"/>
    </joint>
    <link name="rootLink003">
        <inertial>
            <origin xyz="0 0 -0.5115427619592957" rpy="0 0 0"/>
            <mass value="1" />
            <inertia ixx="100" ixy="0" ixz="0" iyy="100" iyz="0" izz="100" />
        </inertial>
        <visual>
            <origin xyz="0 0 -0.5115427619592957" rpy="0 0 0"/>
            <geometry>
                <box size="1 1 1.0230855239185914" />
            </geometry>
            <material name="Blue">
                <color rgba="0 0 1.0 1.0"/>
            </material>
        </visual>
        <collision>
            <origin xyz="0 0 -0.5115427619592957" rpy="0 0 0"/>
            <geometry>
                <box size="1 1 1.0230855239185914" />
            </geometry>
        </collision>
    </link>
    <joint name="rootLink003_rootLink0030" type="revolute">
       <parent link="rootLink003"/>
       <child  link="rootLink0030"/>
       <origin rpy="0 0 0" xyz="0 0 0.0" />
     <axis xyz="0 1 0"/>
       <limit effort="0.0" lower="-3.14159" upper="3.14159" velocity="0.0"/>
    </joint>
    <link name="rootLink0030">
        <inertial>
            <origin xyz="0 0 0.5650853844489357" rpy="0 0 0"/>
            <mass value="1" />
            <inertia ixx="100" ixy="0" ixz="0" iyy="100" iyz="0" izz="100" />
        </inertial>
        <visual>
            <origin xyz="0 0 0.5650853844489357" rpy="0 0 0"/>
            <geometry>
                <box size="1 1 1.1301707688978715" />
            </geometry>
            <material name="Green">
                <color rgba="0 1.0 0 1.0"/>
            </material>
        </visual>
        <collision>
            <origin xyz="0 0 0.5650853844489357" rpy="0 0 0"/>
            <geometry>
                <box size="1 1 1.1301707688978715" />
            </geometry>
        </collision>
    </link>
    <joint name="rootLink003_rootLink0031" type="revolute">
       <parent link="rootLink003"/>
       <child  link="rootLink0031"/>
       <origin rpy="0 0 0" xyz="0.5 0 -0.5115427619592957" />
     <axis xyz="0 1 0"/>
       <limit effort="0.0" lower="-3.14159" upper="3.14159" velocity="0.0"/>
    </joint>
    <link name="rootLink0031">
        <inertial>
            <origin xyz="0.6217068531359018 0 0" rpy="0 0 0"/>
            <mass value="1" />
            <inertia ixx="100" ixy="0" ixz="0" iyy="100" iyz="0" izz="100" />
        </inertial>
        <visual>
            <origin xyz="0.6217068531359018 0 0" rpy="0 0 0"/>
            <geometry>
                <box size="1.2434137062718036 1 1" />
            </geometry>
            <material name="Blue">
                <color rgba="0 0 1.0 1.0"/>
            </material>
        </visual>
        <collision>
            <origin xyz="0.6217068531359018 0 0" rpy="0 0 0"/>
            <geometry>
                <box size="1.2434137062718036 1 1" />
            </geometry>
        </collision>
    </link>
    <joint name="rootLink0031_rootLink00310" type="revolute">
       <parent link="rootLink0031"/>
       <child  link="rootLink00310"/>
       <origin rpy="0 0 0" xyz="0.6217068531359018 0.5 0" />
     <axis xyz="0 1 0"/>
       <limit effort="0.0" lower="-3.14159" upper="3.14159" velocity="0.0"/>
    </joint>
    <link name="rootLink00310">
        <inertial>
            <origin xyz="0 0.7684790163680835 0" rpy="0 0 0"/>
            <mass value="1" />
            <inertia ixx="100" ixy="0" ixz="0" iyy="100" iyz="0" izz="100" />
        </inertial>
        <visual>
            <origin xyz="0 0.7684790163680835 0" rpy="0 0 0"/>
            <geometry>
                <box size="1 1.536958032736167 1" />
            </geometry>
            <material name="Green">
                <color rgba="0 1.0 0 1.0"/>
            </material>
        </visual>
        <collision>
            <origin xyz="0 0.7684790163680835 0" rpy="0 0 0"/>
            <geometry>
                <box size="1 1.536958032736167 1" />
            </geometry>
        </collision>
    </link>
    <joint name="rootLink00_rootLink004" type="revolute">
       <parent link="rootLink00"/>
       <child  link="rootLink004"/>
       <origin rpy="0 0 0" xyz="0.8833177299073383 0.5 0" />
     <axis xyz="1 0 0"/>
       <limit effort="0.0" lower="-3.14159" upper="3.14159" velocity="0.0"/>
    </joint>
    <link name="rootLink004">
        <inertial>
            <origin xyz="0 0.8180961234176158 0" rpy="0 0 0"/>
            <mass value="1" />
            <inertia ixx="100" ixy="0" ixz="0" iyy="100" iyz="0" izz="100" />
        </inertial>
        <visual>
            <origin xyz="0 0.8180961234176158 0" rpy="0 0 0"/>
            <geometry>
                <box size="1 1.6361922468352317 1" />
            </geometry>
            <material name="Green">
                <color rgba="0 1.0 0 1.0"/>
            </material>
        </visual>
        <collision>
            <origin xyz="0 0.8180961234176158 0" rpy="0 0 0"/>
            <geometry>
                <box size="1 1.6361922468352317 1" />
            </geometry>
        </collision>
    </link>
    <joint name="rootLink004_rootLink0041" type="revolute">
       <parent link="rootLink004"/>
       <child  link="rootLink0041"/>
       <origin rpy="0 0 0" xyz="-0.5 0.8180961234176158 0" />
     <axis xyz="0 1 0"/>
       <limit effort="0.0" lower="-3.14159" upper="3.14159" velocity="0.0"/>
    </joint>
    <link name="rootLink0041">
        <inertial>
            <origin xyz="-0.7489577237103942 0 0" rpy="0 0 0"/>
            <mass value="1" />
            <inertia ixx="100" ixy="0" ixz="0" iyy="100" iyz="0" izz="100" />
        </inertial>
        <visual>
            <origin xyz="-0.7489577237103942 0 0" rpy="0 0 0"/>
            <geometry>
                <box size="1.4979154474207883 1 1" />
            </geometry>
            <material name="Blue">
                <color rgba="0 0 1.0 1.0"/>
            </material>
        </visual>
        <collision>
            <origin xyz="-0.7489577237103942 0 0" rpy="0 0 0"/>
            <geometry>
                <box size="1.4979154474207883 1 1" />
            </geometry>
        </collision>
    </link>
    <joint name="rootLink0041_rootLink00410" type="revolute">
       <parent link="rootLink0041"/>
       <child  link="rootLink00410"/>
       <origin rpy="0 0 0" xyz="-0.7489577237103942 0.5 0" />
     <axis xyz="0 1 0"/>
       <limit effort="0.0" lower="-3.14159" upper="3.14159" velocity="0.0"/>
    </joint>
    <link name="rootLink00410">
        <inertial>
            <origin xyz="0 0.6810342078157237 0" rpy="0 0 0"/>
            <mass value="1" />
            <inertia ixx="100" ixy="0" ixz="0" iyy="100" iyz="0" izz="100" />
        </inertial>
        <visual>
            <origin xyz="0 0.6810342078157237 0" rpy="0 0 0"/>
            <geometry>
                <box size="1 1.3620684156314473 1" />
            </geometry>
            <material name="Green">
                <color rgba="0 1.0 0 1.0"/>
            </material>
        </visual>
        <collision>
            <origin xyz="0 0.6810342078157237 0" rpy="0 0 0"/>
            <geometry>
                <box size="1 1.3620684156314473 1" />
            </geometry>
        </collision>
    </link>
    <joint name="rootLink00410_rootLink004101" type="revolute">
       <parent link="rootLink00410"/>
       <child  link="rootLink004101"/>
       <origin rpy="0 0 0" xyz="0.5 0.6810342078157237 0" />
     <axis xyz="1 0 0"/>
       <limit effort="0.0" lower="-3.14159" upper="3.14159" velocity="0.0"/>
    </joint>
    <link name="rootLink004101">
        <inertial>
            <origin xyz="0.8642119885629094 0 0" rpy="0 0 0"/>
            <mass value="1" />
            <inertia ixx="100" ixy="0" ixz="0" iyy="100" iyz="0" izz="100" />
        </inertial>
        <visual>
            <origin xyz="0.8642119885629094 0 0" rpy="0 0 0"/>
            <geometry>
                <box size="1.7284239771258187 1 1" />
            </geometry>
            <material name="Blue">
                <color rgba="0 0 1.0 1.0"/>
            </material>
        </visual>
        <collision>
            <origin xyz="0.8642119885629094 0 0" rpy="0 0 0"/>
            <geometry>
                <box size="1.7284239771258187 1 1" />
            </geometry>
        </collision>
    </link>
    <joint name="rootLink0041_rootLink00412" type="revolute">
       <parent link="rootLink0041"/>
       <child  link="rootLink00412"/>
       <origin rpy="0 0 0" xyz="0.0 0 0" />
     <axis xyz="1 0 0"/>
       <limit effort="0.0" lower="-3.14159" upper="3.14159" velocity="0.0"/>
    </joint>
    <link name="rootLink00412">
        <inertial>
            <origin xyz="0.6088510716003303 0 0" rpy="0 0 0"/>
            <mass value="1" />
            <inertia ixx="100" ixy="0" ixz="0" iyy="100" iyz="0" izz="100" />
        </inertial>
        <visual>
            <origin xyz="0.6088510716003303 0 0" rpy="0 0 0"/>
            <geometry>
                <box size="1.2177021432006605 1 1" />
            </geometry>
            <material name="Blue">
                <color rgba="0 0 1.0 1.0"/>
            </material>
        </visual>
        <collision>
            <origin xyz="0.6088510716003303 0 0" rpy="0 0 0"/>
            <geometry>
                <box size="1.2177021432006605 1 1" />
            </geometry>
        </collision>
    </link>
</robot>