<robot name = "robot">
    <link name="rootLink">
        <inertial>
            <origin xyz="0 0 0.5" rpy="0 0 0"/>
            <mass value="1" />
            <inertia ixx="100" ixy="0" ixz="0" iyy="100" iyz="0" izz="100" />
        </inertial>
        <visual>
            <origin xyz="0 0 0.5" rpy="0 0 0"/>
            <geometry>
                <box size="1 1 1" />
            </geometry>
            <material name="Green">
                <color rgba="0 1.0 0 1.0"/>
            </material>
        </visual>
        <collision>
            <origin xyz="0 0 0.5" rpy="0 0 0"/>
            <geometry>
                <box size="1 1 1" />
            </geometry>
        </collision>
    </link>
    <joint name="rootLink_rootLink0" type="revolute">
       <parent link="rootLink"/>
       <child  link="rootLink0"/>
       <origin rpy="0 0 0" xyz="0 0 1.0" />
     <axis xyz="0 1 0"/>
       <limit effort="0.0" lower="-3.14159" upper="3.14159" velocity="0.0"/>
    </joint>
    <link name="rootLink0">
        <inertial>
            <origin xyz="0 0 0.7245937771201987" rpy="0 0 0"/>
            <mass value="1" />
            <inertia ixx="100" ixy="0" ixz="0" iyy="100" iyz="0" izz="100" />
        </inertial>
        <visual>
            <origin xyz="0 0 0.7245937771201987" rpy="0 0 0"/>
            <geometry>
                <box size="1 1 1.4491875542403974" />
            </geometry>
            <material name="Green">
                <color rgba="0 1.0 0 1.0"/>
            </material>
        </visual>
        <collision>
            <origin xyz="0 0 0.7245937771201987" rpy="0 0 0"/>
            <geometry>
                <box size="1 1 1.4491875542403974" />
            </geometry>
        </collision>
    </link>
    <joint name="rootLink0_rootLink00" type="revolute">
       <parent link="rootLink0"/>
       <child  link="rootLink00"/>
       <origin rpy="0 0 0" xyz="0 -0.5 0.7245937771201987" />
     <axis xyz="0 1 0"/>
       <limit effort="0.0" lower="-3.14159" upper="3.14159" velocity="0.0"/>
    </joint>
    <link name="rootLink00">
        <inertial>
            <origin xyz="0 -0.7067219298205496 0" rpy="0 0 0"/>
            <mass value="1" />
            <inertia ixx="100" ixy="0" ixz="0" iyy="100" iyz="0" izz="100" />
        </inertial>
        <visual>
            <origin xyz="0 -0.7067219298205496 0" rpy="0 0 0"/>
            <geometry>
                <box size="1 1.4134438596410992 1" />
            </geometry>
            <material name="Blue">
                <color rgba="0 0 1.0 1.0"/>
            </material>
        </visual>
        <collision>
            <origin xyz="0 -0.7067219298205496 0" rpy="0 0 0"/>
            <geometry>
                <box size="1 1.4134438596410992 1" />
            </geometry>
        </collision>
    </link>
    <joint name="rootLink00_rootLink002" type="revolute">
       <parent link="rootLink00"/>
       <child  link="rootLink002"/>
       <origin rpy="0 0 0" xyz="0.5 -0.7067219298205496 0" />
     <axis xyz="1 0 0"/>
       <limit effort="0.0" lower="-3.14159" upper="3.14159" velocity="0.0"/>
    </joint>
    <link name="rootLink002">
        <inertial>
            <origin xyz="0.5865596297637117 0 0" rpy="0 0 0"/>
            <mass value="1" />
            <inertia ixx="100" ixy="0" ixz="0" iyy="100" iyz="0" izz="100" />
        </inertial>
        <visual>
            <origin xyz="0.5865596297637117 0 0" rpy="0 0 0"/>
            <geometry>
                <box size="1.1731192595274234 1 1" />
            </geometry>
            <material name="Green">
                <color rgba="0 1.0 0 1.0"/>
            </material>
        </visual>
        <collision>
            <origin xyz="0.5865596297637117 0 0" rpy="0 0 0"/>
            <geometry>
                <box size="1.1731192595274234 1 1" />
            </geometry>
        </collision>
    </link>
    <joint name="rootLink002_rootLink0020" type="revolute">
       <parent link="rootLink002"/>
       <child  link="rootLink0020"/>
       <origin rpy="0 0 0" xyz="0.5865596297637117 0 0.5" />
     <axis xyz="0 1 0"/>
       <limit effort="0.0" lower="-3.14159" upper="3.14159" velocity="0.0"/>
    </joint>
    <link name="rootLink0020">
        <inertial>
            <origin xyz="0 0 0.7874948140049975" rpy="0 0 0"/>
            <mass value="1" />
            <inertia ixx="100" ixy="0" ixz="0" iyy="100" iyz="0" izz="100" />
        </inertial>
        <visual>
            <origin xyz="0 0 0.7874948140049975" rpy="0 0 0"/>
            <geometry>
                <box size="1 1 1.574989628009995" />
            </geometry>
            <material name="Blue">
                <color rgba="0 0 1.0 1.0"/>
            </material>
        </visual>
        <collision>
            <origin xyz="0 0 0.7874948140049975" rpy="0 0 0"/>
            <geometry>
                <box size="1 1 1.574989628009995" />
            </geometry>
        </collision>
    </link>
    <joint name="rootLink0_rootLink02" type="revolute">
       <parent link="rootLink0"/>
       <child  link="rootLink02"/>
       <origin rpy="0 0 0" xyz="0.5 0 0.7245937771201987" />
     <axis xyz="1 0 0"/>
       <limit effort="0.0" lower="-3.14159" upper="3.14159" velocity="0.0"/>
    </joint>
    <link name="rootLink02">
        <inertial>
            <origin xyz="0.9887024401034425 0 0" rpy="0 0 0"/>
            <mass value="1" />
            <inertia ixx="100" ixy="0" ixz="0" iyy="100" iyz="0" izz="100" />
        </inertial>
        <visual>
            <origin xyz="0.9887024401034425 0 0" rpy="0 0 0"/>
            <geometry>
                <box size="1.977404880206885 1 1" />
            </geometry>
            <material name="Blue">
                <color rgba="0 0 1.0 1.0"/>
            </material>
        </visual>
        <collision>
            <origin xyz="0.9887024401034425 0 0" rpy="0 0 0"/>
            <geometry>
                <box size="1.977404880206885 1 1" />
            </geometry>
        </collision>
    </link>
    <joint name="rootLink02_rootLink020" type="revolute">
       <parent link="rootLink02"/>
       <child  link="rootLink020"/>
       <origin rpy="0 0 0" xyz="0.9887024401034425 0.5 0" />
     <axis xyz="1 0 0"/>
       <limit effort="0.0" lower="-3.14159" upper="3.14159" velocity="0.0"/>
    </joint>
    <link name="rootLink020">
        <inertial>
            <origin xyz="0 0.9448218412532091 0" rpy="0 0 0"/>
            <mass value="1" />
            <inertia ixx="100" ixy="0" ixz="0" iyy="100" iyz="0" izz="100" />
        </inertial>
        <visual>
            <origin xyz="0 0.9448218412532091 0" rpy="0 0 0"/>
            <geometry>
                <box size="1 1.8896436825064182 1" />
            </geometry>
            <material name="Green">
                <color rgba="0 1.0 0 1.0"/>
            </material>
        </visual>
        <collision>
            <origin xyz="0 0.9448218412532091 0" rpy="0 0 0"/>
            <geometry>
                <box size="1 1.8896436825064182 1" />
            </geometry>
        </collision>
    </link>
    <joint name="rootLink02_rootLink021" type="revolute">
       <parent link="rootLink02"/>
       <child  link="rootLink021"/>
       <origin rpy="0 0 0" xyz="1.977404880206885 0 0" />
     <axis xyz="1 0 0"/>
       <limit effort="0.0" lower="-3.14159" upper="3.14159" velocity="0.0"/>
    </joint>
    <link name="rootLink021">
        <inertial>
            <origin xyz="0.9709967969436248 0 0" rpy="0 0 0"/>
            <mass value="1" />
            <inertia ixx="100" ixy="0" ixz="0" iyy="100" iyz="0" izz="100" />
        </inertial>
        <visual>
            <origin xyz="0.9709967969436248 0 0" rpy="0 0 0"/>
            <geometry>
                <box size="1.9419935938872497 1 1" />
            </geometry>
            <material name="Blue">
                <color rgba="0 0 1.0 1.0"/>
            </material>
        </visual>
        <collision>
            <origin xyz="0.9709967969436248 0 0" rpy="0 0 0"/>
            <geometry>
                <box size="1.9419935938872497 1 1" />
            </geometry>
        </collision>
    </link>
    <joint name="rootLink021_rootLink0210" type="revolute">
       <parent link="rootLink021"/>
       <child  link="rootLink0210"/>
       <origin rpy="0 0 0" xyz="0.9709967969436248 0 0.5" />
     <axis xyz="0 1 0"/>
       <limit effort="0.0" lower="-3.14159" upper="3.14159" velocity="0.0"/>
    </joint>
    <link name="rootLink0210">
        <inertial>
            <origin xyz="0 0 0.7674723136497443" rpy="0 0 0"/>
            <mass value="1" />
            <inertia ixx="100" ixy="0" ixz="0" iyy="100" iyz="0" izz="100" />
        </inertial>
        <visual>
            <origin xyz="0 0 0.7674723136497443" rpy="0 0 0"/>
            <geometry>
                <box size="1 1 1.5349446272994887" />
            </geometry>
            <material name="Green">
                <color rgba="0 1.0 0 1.0"/>
            </material>
        </visual>
        <collision>
            <origin xyz="0 0 0.7674723136497443" rpy="0 0 0"/>
            <geometry>
                <box size="1 1 1.5349446272994887" />
            </geometry>
        </collision>
    </link>
    <joint name="rootLink0210_rootLink02101" type="revolute">
       <parent link="rootLink0210"/>
       <child  link="rootLink02101"/>
       <origin rpy="0 0 0" xyz="0 0.5 0.7674723136497443" />
     <axis xyz="1 0 0"/>
       <limit effort="0.0" lower="-3.14159" upper="3.14159" velocity="0.0"/>
    </joint>
    <link name="rootLink02101">
        <inertial>
            <origin xyz="0 0.7268509781630963 0" rpy="0 0 0"/>
            <mass value="1" />
            <inertia ixx="100" ixy="0" ixz="0" iyy="100" iyz="0" izz="100" />
        </inertial>
        <visual>
            <origin xyz="0 0.7268509781630963 0" rpy="0 0 0"/>
            <geometry>
                <box size="1 1.4537019563261926 1" />
            </geometry>
            <material name="Green">
                <color rgba="0 1.0 0 1.0"/>
            </material>
        </visual>
        <collision>
            <origin xyz="0 0.7268509781630963 0" rpy="0 0 0"/>
            <geometry>
                <box size="1 1.4537019563261926 1" />
            </geometry>
        </collision>
    </link>
    <joint name="rootLink02101_rootLink021010" type="revolute">
       <parent link="rootLink02101"/>
       <child  link="rootLink021010"/>
       <origin rpy="0 0 0" xyz="0.5 0.7268509781630963 0" />
     <axis xyz="1 0 0"/>
       <limit effort="0.0" lower="-3.14159" upper="3.14159" velocity="0.0"/>
    </joint>
    <link name="rootLink021010">
        <inertial>
            <origin xyz="0.8070482537598663 0 0" rpy="0 0 0"/>
            <mass value="1" />
            <inertia ixx="100" ixy="0" ixz="0" iyy="100" iyz="0" izz="100" />
        </inertial>
        <visual>
            <origin xyz="0.8070482537598663 0 0" rpy="0 0 0"/>
            <geometry>
                <box size="1.6140965075197327 1 1" />
            </geometry>
            <material name="Green">
                <color rgba="0 1.0 0 1.0"/>
            </material>
        </visual>
        <collision>
            <origin xyz="0.8070482537598663 0 0" rpy="0 0 0"/>
            <geometry>
                <box size="1.6140965075197327 1 1" />
            </geometry>
        </collision>
    </link>
    <joint name="rootLink02101_rootLink021011" type="revolute">
       <parent link="rootLink02101"/>
       <child  link="rootLink021011"/>
       <origin rpy="0 0 0" xyz="0 0.7268509781630963 -0.5" />
     <axis xyz="0 0 1"/>
       <limit effort="0.0" lower="-3.14159" upper="3.14159" velocity="0.0"/>
    </joint>
    <link name="rootLink021011">
        <inertial>
            <origin xyz="0 0 -0.8631344445939174" rpy="0 0 0"/>
            <mass value="1" />
            <inertia ixx="100" ixy="0" ixz="0" iyy="100" iyz="0" izz="100" />
        </inertial>
        <visual>
            <origin xyz="0 0 -0.8631344445939174" rpy="0 0 0"/>
            <geometry>
                <box size="1 1 1.7262688891878348" />
            </geometry>
            <material name="Blue">
                <color rgba="0 0 1.0 1.0"/>
            </material>
        </visual>
        <collision>
            <origin xyz="0 0 -0.8631344445939174" rpy="0 0 0"/>
            <geometry>
                <box size="1 1 1.7262688891878348" />
            </geometry>
        </collision>
    </link>
    <joint name="rootLink021011_rootLink0210110" type="revolute">
       <parent link="rootLink021011"/>
       <child  link="rootLink0210110"/>
       <origin rpy="0 0 0" xyz="0 0 0.0" />
     <axis xyz="0 0 1"/>
       <limit effort="0.0" lower="-3.14159" upper="3.14159" velocity="0.0"/>
    </joint>
    <link name="rootLink0210110">
        <inertial>
            <origin xyz="0 0 0.5040081758845505" rpy="0 0 0"/>
            <mass value="1" />
            <inertia ixx="100" ixy="0" ixz="0" iyy="100" iyz="0" izz="100" />
        </inertial>
        <visual>
            <origin xyz="0 0 0.5040081758845505" rpy="0 0 0"/>
            <geometry>
                <box size="1 1 1.008016351769101" />
            </geometry>
            <material name="Blue">
                <color rgba="0 0 1.0 1.0"/>
            </material>
        </visual>
        <collision>
            <origin xyz="0 0 0.5040081758845505" rpy="0 0 0"/>
            <geometry>
                <box size="1 1 1.008016351769101" />
            </geometry>
        </collision>
    </link>
    <joint name="rootLink021011_rootLink0210111" type="revolute">
       <parent link="rootLink021011"/>
       <child  link="rootLink0210111"/>
       <origin rpy="0 0 0" xyz="0.5 0 -0.8631344445939174" />
     <axis xyz="1 0 0"/>
       <limit effort="0.0" lower="-3.14159" upper="3.14159" velocity="0.0"/>
    </joint>
    <link name="rootLink0210111">
        <inertial>
            <origin xyz="0.8490395813921394 0 0" rpy="0 0 0"/>
            <mass value="1" />
            <inertia ixx="100" ixy="0" ixz="0" iyy="100" iyz="0" izz="100" />
        </inertial>
        <visual>
            <origin xyz="0.8490395813921394 0 0" rpy="0 0 0"/>
            <geometry>
                <box size="1.6980791627842788 1 1" />
            </geometry>
            <material name="Blue">
                <color rgba="0 0 1.0 1.0"/>
            </material>
        </visual>
        <collision>
            <origin xyz="0.8490395813921394 0 0" rpy="0 0 0"/>
            <geometry>
                <box size="1.6980791627842788 1 1" />
            </geometry>
        </collision>
    </link>
    <joint name="rootLink021_rootLink0211" type="revolute">
       <parent link="rootLink021"/>
       <child  link="rootLink0211"/>
       <origin rpy="0 0 0" xyz="1.9419935938872497 0 0" />
     <axis xyz="0 1 0"/>
       <limit effort="0.0" lower="-3.14159" upper="3.14159" velocity="0.0"/>
    </joint>
    <link name="rootLink0211">
        <inertial>
            <origin xyz="0.6694368691077917 0 0" rpy="0 0 0"/>
            <mass value="1" />
            <inertia ixx="100" ixy="0" ixz="0" iyy="100" iyz="0" izz="100" />
        </inertial>
        <visual>
            <origin xyz="0.6694368691077917 0 0" rpy="0 0 0"/>
            <geometry>
                <box size="1.3388737382155833 1 1" />
            </geometry>
            <material name="Blue">
                <color rgba="0 0 1.0 1.0"/>
            </material>
        </visual>
        <collision>
            <origin xyz="0.6694368691077917 0 0" rpy="0 0 0"/>
            <geometry>
                <box size="1.3388737382155833 1 1" />
            </geometry>
        </collision>
    </link>
    <joint name="rootLink02_rootLink022" type="revolute">
       <parent link="rootLink02"/>
       <child  link="rootLink022"/>
       <origin rpy="0 0 0" xyz="0.9887024401034425 0 0.5" />
     <axis xyz="0 0 1"/>
       <limit effort="0.0" lower="-3.14159" upper="3.14159" velocity="0.0"/>
    </joint>
    <link name="rootLink022">
        <inertial>
            <origin xyz="0 0 0.6454414138105202" rpy="0 0 0"/>
            <mass value="1" />
            <inertia ixx="100" ixy="0" ixz="0" iyy="100" iyz="0" izz="100" />
        </inertial>
        <visual>
            <origin xyz="0 0 0.6454414138105202" rpy="0 0 0"/>
            <geometry>
                <box size="1 1 1.2908828276210405" />
            </geometry>
            <material name="Blue">
                <color rgba="0 0 1.0 1.0"/>
            </material>
        </visual>
        <collision>
            <origin xyz="0 0 0.6454414138105202" rpy="0 0 0"/>
            <geometry>
                <box size="1 1 1.2908828276210405" />
            </geometry>
        </collision>
    </link>
</robot>