<robot name = "robot">
    <link name="rootLink">
        <inertial>
            <origin xyz="0 0 0.5" rpy="0 0 0"/>
            <mass value="1" />
            <inertia ixx="100" ixy="0" ixz="0" iyy="100" iyz="0" izz="100" />
        </inertial>
        <visual>
            <origin xyz="0 0 0.5" rpy="0 0 0"/>
            <geometry>
                <box size="1 1 1" />
            </geometry>
            <material name="Blue">
                <color rgba="0 0 1.0 1.0"/>
            </material>
        </visual>
        <collision>
            <origin xyz="0 0 0.5" rpy="0 0 0"/>
            <geometry>
                <box size="1 1 1" />
            </geometry>
        </collision>
    </link>
    <joint name="rootLink_rootLink1" type="revolute">
       <parent link="rootLink"/>
       <child  link="rootLink1"/>
       <origin rpy="0 0 0" xyz="0 0 1.0" />
     <axis xyz="0 1 0"/>
       <limit effort="0.0" lower="-3.14159" upper="3.14159" velocity="0.0"/>
    </joint>
    <link name="rootLink1">
        <inertial>
            <origin xyz="0 0 0.7249507140014575" rpy="0 0 0"/>
            <mass value="1" />
            <inertia ixx="100" ixy="0" ixz="0" iyy="100" iyz="0" izz="100" />
        </inertial>
        <visual>
            <origin xyz="0 0 0.7249507140014575" rpy="0 0 0"/>
            <geometry>
                <box size="1 1 1.449901428002915" />
            </geometry>
            <material name="Blue">
                <color rgba="0 0 1.0 1.0"/>
            </material>
        </visual>
        <collision>
            <origin xyz="0 0 0.7249507140014575" rpy="0 0 0"/>
            <geometry>
                <box size="1 1 1.449901428002915" />
            </geometry>
        </collision>
    </link>
    <joint name="rootLink1_rootLink11" type="revolute">
       <parent link="rootLink1"/>
       <child  link="rootLink11"/>
       <origin rpy="0 0 0" xyz="0 0.5 0.7249507140014575" />
     <axis xyz="0 1 0"/>
       <limit effort="0.0" lower="-3.14159" upper="3.14159" velocity="0.0"/>
    </joint>
    <link name="rootLink11">
        <inertial>
            <origin xyz="0 0.9321684999818382 0" rpy="0 0 0"/>
            <mass value="1" />
            <inertia ixx="100" ixy="0" ixz="0" iyy="100" iyz="0" izz="100" />
        </inertial>
        <visual>
            <origin xyz="0 0.9321684999818382 0" rpy="0 0 0"/>
            <geometry>
                <box size="1 1.8643369999636763 1" />
            </geometry>
            <material name="Blue">
                <color rgba="0 0 1.0 1.0"/>
            </material>
        </visual>
        <collision>
            <origin xyz="0 0.9321684999818382 0" rpy="0 0 0"/>
            <geometry>
                <box size="1 1.8643369999636763 1" />
            </geometry>
        </collision>
    </link>
    <joint name="rootLink11_rootLink110" type="revolute">
       <parent link="rootLink11"/>
       <child  link="rootLink110"/>
       <origin rpy="0 0 0" xyz="0 1.8643369999636763 0" />
     <axis xyz="0 0 1"/>
       <limit effort="0.0" lower="-3.14159" upper="3.14159" velocity="0.0"/>
    </joint>
    <link name="rootLink110">
        <inertial>
            <origin xyz="0 0.9042635622580485 0" rpy="0 0 0"/>
            <mass value="1" />
            <inertia ixx="100" ixy="0" ixz="0" iyy="100" iyz="0" izz="100" />
        </inertial>
        <visual>
            <origin xyz="0 0.9042635622580485 0" rpy="0 0 0"/>
            <geometry>
                <box size="1 1.808527124516097 1" />
            </geometry>
            <material name="Blue">
                <color rgba="0 0 1.0 1.0"/>
            </material>
        </visual>
        <collision>
            <origin xyz="0 0.9042635622580485 0" rpy="0 0 0"/>
            <geometry>
                <box size="1 1.808527124516097 1" />
            </geometry>
        </collision>
    </link>
    <joint name="rootLink110_rootLink1100" type="revolute">
       <parent link="rootLink110"/>
       <child  link="rootLink1100"/>
       <origin rpy="0 0 0" xyz="0.5 0.9042635622580485 0" />
     <axis xyz="1 0 0"/>
       <limit effort="0.0" lower="-3.14159" upper="3.14159" velocity="0.0"/>
    </joint>
    <link name="rootLink1100">
        <inertial>
            <origin xyz="0.6245342488819894 0 0" rpy="0 0 0"/>
            <mass value="1" />
            <inertia ixx="100" ixy="0" ixz="0" iyy="100" iyz="0" izz="100" />
        </inertial>
        <visual>
            <origin xyz="0.6245342488819894 0 0" rpy="0 0 0"/>
            <geometry>
                <box size="1.2490684977639788 1 1" />
            </geometry>
            <material name="Blue">
                <color rgba="0 0 1.0 1.0"/>
            </material>
        </visual>
        <collision>
            <origin xyz="0.6245342488819894 0 0" rpy="0 0 0"/>
            <geometry>
                <box size="1.2490684977639788 1 1" />
            </geometry>
        </collision>
    </link>
    <joint name="rootLink1100_rootLink11000" type="revolute">
       <parent link="rootLink1100"/>
       <child  link="rootLink11000"/>
       <origin rpy="0 0 0" xyz="0.6245342488819894 0.5 0" />
     <axis xyz="0 1 0"/>
       <limit effort="0.0" lower="-3.14159" upper="3.14159" velocity="0.0"/>
    </joint>
    <link name="rootLink11000">
        <inertial>
            <origin xyz="0 0.7646505529788327 0" rpy="0 0 0"/>
            <mass value="1" />
            <inertia ixx="100" ixy="0" ixz="0" iyy="100" iyz="0" izz="100" />
        </inertial>
        <visual>
            <origin xyz="0 0.7646505529788327 0" rpy="0 0 0"/>
            <geometry>
                <box size="1 1.5293011059576653 1" />
            </geometry>
            <material name="Blue">
                <color rgba="0 0 1.0 1.0"/>
            </material>
        </visual>
        <collision>
            <origin xyz="0 0.7646505529788327 0" rpy="0 0 0"/>
            <geometry>
                <box size="1 1.5293011059576653 1" />
            </geometry>
        </collision>
    </link>
    <joint name="rootLink110_rootLink1101" type="revolute">
       <parent link="rootLink110"/>
       <child  link="rootLink1101"/>
       <origin rpy="0 0 0" xyz="0 0.9042635622580485 0.5" />
     <axis xyz="0 1 0"/>
       <limit effort="0.0" lower="-3.14159" upper="3.14159" velocity="0.0"/>
    </joint>
    <link name="rootLink1101">
        <inertial>
            <origin xyz="0 0 0.7750865532938926" rpy="0 0 0"/>
            <mass value="1" />
            <inertia ixx="100" ixy="0" ixz="0" iyy="100" iyz="0" izz="100" />
        </inertial>
        <visual>
            <origin xyz="0 0 0.7750865532938926" rpy="0 0 0"/>
            <geometry>
                <box size="1 1 1.5501731065877853" />
            </geometry>
            <material name="Blue">
                <color rgba="0 0 1.0 1.0"/>
            </material>
        </visual>
        <collision>
            <origin xyz="0 0 0.7750865532938926" rpy="0 0 0"/>
            <geometry>
                <box size="1 1 1.5501731065877853" />
            </geometry>
        </collision>
    </link>
    <joint name="rootLink110_rootLink1102" type="revolute">
       <parent link="rootLink110"/>
       <child  link="rootLink1102"/>
       <origin rpy="0 0 0" xyz="0 1.808527124516097 0" />
     <axis xyz="0 1 0"/>
       <limit effort="0.0" lower="-3.14159" upper="3.14159" velocity="0.0"/>
    </joint>
    <link name="rootLink1102">
        <inertial>
            <origin xyz="0 0.8994665979013754 0" rpy="0 0 0"/>
            <mass value="1" />
            <inertia ixx="100" ixy="0" ixz="0" iyy="100" iyz="0" izz="100" />
        </inertial>
        <visual>
            <origin xyz="0 0.8994665979013754 0" rpy="0 0 0"/>
            <geometry>
                <box size="1 1.7989331958027508 1" />
            </geometry>
            <material name="Blue">
                <color rgba="0 0 1.0 1.0"/>
            </material>
        </visual>
        <collision>
            <origin xyz="0 0.8994665979013754 0" rpy="0 0 0"/>
            <geometry>
                <box size="1 1.7989331958027508 1" />
            </geometry>
        </collision>
    </link>
    <joint name="rootLink1_rootLink13" type="revolute">
       <parent link="rootLink1"/>
       <child  link="rootLink13"/>
       <origin rpy="0 0 0" xyz="0.5 0 0.7249507140014575" />
     <axis xyz="0 1 0"/>
       <limit effort="0.0" lower="-3.14159" upper="3.14159" velocity="0.0"/>
    </joint>
    <link name="rootLink13">
        <inertial>
            <origin xyz="0.8871530319616447 0 0" rpy="0 0 0"/>
            <mass value="1" />
            <inertia ixx="100" ixy="0" ixz="0" iyy="100" iyz="0" izz="100" />
        </inertial>
        <visual>
            <origin xyz="0.8871530319616447 0 0" rpy="0 0 0"/>
            <geometry>
                <box size="1.7743060639232895 1 1" />
            </geometry>
            <material name="Blue">
                <color rgba="0 0 1.0 1.0"/>
            </material>
        </visual>
        <collision>
            <origin xyz="0.8871530319616447 0 0" rpy="0 0 0"/>
            <geometry>
                <box size="1.7743060639232895 1 1" />
            </geometry>
        </collision>
    </link>
    <joint name="rootLink13_rootLink130" type="revolute">
       <parent link="rootLink13"/>
       <child  link="rootLink130"/>
       <origin rpy="0 0 0" xyz="0.8871530319616447 0.5 0" />
     <axis xyz="0 1 0"/>
       <limit effort="0.0" lower="-3.14159" upper="3.14159" velocity="0.0"/>
    </joint>
    <link name="rootLink130">
        <inertial>
            <origin xyz="0 0.7645297969433626 0" rpy="0 0 0"/>
            <mass value="1" />
            <inertia ixx="100" ixy="0" ixz="0" iyy="100" iyz="0" izz="100" />
        </inertial>
        <visual>
            <origin xyz="0 0.7645297969433626 0" rpy="0 0 0"/>
            <geometry>
                <box size="1 1.5290595938867253 1" />
            </geometry>
            <material name="Green">
                <color rgba="0 1.0 0 1.0"/>
            </material>
        </visual>
        <collision>
            <origin xyz="0 0.7645297969433626 0" rpy="0 0 0"/>
            <geometry>
                <box size="1 1.5290595938867253 1" />
            </geometry>
        </collision>
    </link>
    <joint name="rootLink130_rootLink1300" type="revolute">
       <parent link="rootLink130"/>
       <child  link="rootLink1300"/>
       <origin rpy="0 0 0" xyz="0.5 0.7645297969433626 0" />
     <axis xyz="1 0 0"/>
       <limit effort="0.0" lower="-3.14159" upper="3.14159" velocity="0.0"/>
    </joint>
    <link name="rootLink1300">
        <inertial>
            <origin xyz="0.9734172674237785 0 0" rpy="0 0 0"/>
            <mass value="1" />
            <inertia ixx="100" ixy="0" ixz="0" iyy="100" iyz="0" izz="100" />
        </inertial>
        <visual>
            <origin xyz="0.9734172674237785 0 0" rpy="0 0 0"/>
            <geometry>
                <box size="1.946834534847557 1 1" />
            </geometry>
            <material name="Green">
                <color rgba="0 1.0 0 1.0"/>
            </material>
        </visual>
        <collision>
            <origin xyz="0.9734172674237785 0 0" rpy="0 0 0"/>
            <geometry>
                <box size="1.946834534847557 1 1" />
            </geometry>
        </collision>
    </link>
    <joint name="rootLink13_rootLink132" type="revolute">
       <parent link="rootLink13"/>
       <child  link="rootLink132"/>
       <origin rpy="0 0 0" xyz="1.7743060639232895 0 0" />
     <axis xyz="0 1 0"/>
       <limit effort="0.0" lower="-3.14159" upper="3.14159" velocity="0.0"/>
    </joint>
    <link name="rootLink132">
        <inertial>
            <origin xyz="0.5271999634301834 0 0" rpy="0 0 0"/>
            <mass value="1" />
            <inertia ixx="100" ixy="0" ixz="0" iyy="100" iyz="0" izz="100" />
        </inertial>
        <visual>
            <origin xyz="0.5271999634301834 0 0" rpy="0 0 0"/>
            <geometry>
                <box size="1.0543999268603668 1 1" />
            </geometry>
            <material name="Blue">
                <color rgba="0 0 1.0 1.0"/>
            </material>
        </visual>
        <collision>
            <origin xyz="0.5271999634301834 0 0" rpy="0 0 0"/>
            <geometry>
                <box size="1.0543999268603668 1 1" />
            </geometry>
        </collision>
    </link>
    <joint name="rootLink132_rootLink1320" type="revolute">
       <parent link="rootLink132"/>
       <child  link="rootLink1320"/>
       <origin rpy="0 0 0" xyz="1.0543999268603668 0 0" />
     <axis xyz="1 0 0"/>
       <limit effort="0.0" lower="-3.14159" upper="3.14159" velocity="0.0"/>
    </joint>
    <link name="rootLink1320">
        <inertial>
            <origin xyz="0.6052305362987281 0 0" rpy="0 0 0"/>
            <mass value="1" />
            <inertia ixx="100" ixy="0" ixz="0" iyy="100" iyz="0" izz="100" />
        </inertial>
        <visual>
            <origin xyz="0.6052305362987281 0 0" rpy="0 0 0"/>
            <geometry>
                <box size="1.2104610725974563 1 1" />
            </geometry>
            <material name="Green">
                <color rgba="0 1.0 0 1.0"/>
            </material>
        </visual>
        <collision>
            <origin xyz="0.6052305362987281 0 0" rpy="0 0 0"/>
            <geometry>
                <box size="1.2104610725974563 1 1" />
            </geometry>
        </collision>
    </link>
</robot>