<robot name = "robot">
    <link name="rootLink">
        <inertial>
            <origin xyz="0 0 0.5" rpy="0 0 0"/>
            <mass value="1" />
            <inertia ixx="100" ixy="0" ixz="0" iyy="100" iyz="0" izz="100" />
        </inertial>
        <visual>
            <origin xyz="0 0 0.5" rpy="0 0 0"/>
            <geometry>
                <box size="1 1 1" />
            </geometry>
            <material name="Green">
                <color rgba="0 1.0 0 1.0"/>
            </material>
        </visual>
        <collision>
            <origin xyz="0 0 0.5" rpy="0 0 0"/>
            <geometry>
                <box size="1 1 1" />
            </geometry>
        </collision>
    </link>
    <joint name="rootLink_rootLink3" type="revolute">
       <parent link="rootLink"/>
       <child  link="rootLink3"/>
       <origin rpy="0 0 0" xyz="0 0 1.0" />
     <axis xyz="1 0 0"/>
       <limit effort="0.0" lower="-3.14159" upper="3.14159" velocity="0.0"/>
    </joint>
    <link name="rootLink3">
        <inertial>
            <origin xyz="0 0 0.9951836568529271" rpy="0 0 0"/>
            <mass value="1" />
            <inertia ixx="100" ixy="0" ixz="0" iyy="100" iyz="0" izz="100" />
        </inertial>
        <visual>
            <origin xyz="0 0 0.9951836568529271" rpy="0 0 0"/>
            <geometry>
                <box size="1 1 1.9903673137058542" />
            </geometry>
            <material name="Blue">
                <color rgba="0 0 1.0 1.0"/>
            </material>
        </visual>
        <collision>
            <origin xyz="0 0 0.9951836568529271" rpy="0 0 0"/>
            <geometry>
                <box size="1 1 1.9903673137058542" />
            </geometry>
        </collision>
    </link>
    <joint name="rootLink3_rootLink30" type="revolute">
       <parent link="rootLink3"/>
       <child  link="rootLink30"/>
       <origin rpy="0 0 0" xyz="-0.5 0 0.9951836568529271" />
     <axis xyz="0 0 1"/>
       <limit effort="0.0" lower="-3.14159" upper="3.14159" velocity="0.0"/>
    </joint>
    <link name="rootLink30">
        <inertial>
            <origin xyz="-0.5060414036814673 0 0" rpy="0 0 0"/>
            <mass value="1" />
            <inertia ixx="100" ixy="0" ixz="0" iyy="100" iyz="0" izz="100" />
        </inertial>
        <visual>
            <origin xyz="-0.5060414036814673 0 0" rpy="0 0 0"/>
            <geometry>
                <box size="1.0120828073629347 1 1" />
            </geometry>
            <material name="Green">
                <color rgba="0 1.0 0 1.0"/>
            </material>
        </visual>
        <collision>
            <origin xyz="-0.5060414036814673 0 0" rpy="0 0 0"/>
            <geometry>
                <box size="1.0120828073629347 1 1" />
            </geometry>
        </collision>
    </link>
    <joint name="rootLink30_rootLink301" type="revolute">
       <parent link="rootLink30"/>
       <child  link="rootLink301"/>
       <origin rpy="0 0 0" xyz="-0.5060414036814673 0.5 0" />
     <axis xyz="1 0 0"/>
       <limit effort="0.0" lower="-3.14159" upper="3.14159" velocity="0.0"/>
    </joint>
    <link name="rootLink301">
        <inertial>
            <origin xyz="0 0.5135473249355026 0" rpy="0 0 0"/>
            <mass value="1" />
            <inertia ixx="100" ixy="0" ixz="0" iyy="100" iyz="0" izz="100" />
        </inertial>
        <visual>
            <origin xyz="0 0.5135473249355026 0" rpy="0 0 0"/>
            <geometry>
                <box size="1 1.0270946498710052 1" />
            </geometry>
            <material name="Green">
                <color rgba="0 1.0 0 1.0"/>
            </material>
        </visual>
        <collision>
            <origin xyz="0 0.5135473249355026 0" rpy="0 0 0"/>
            <geometry>
                <box size="1 1.0270946498710052 1" />
            </geometry>
        </collision>
    </link>
    <joint name="rootLink301_rootLink3010" type="revolute">
       <parent link="rootLink301"/>
       <child  link="rootLink3010"/>
       <origin rpy="0 0 0" xyz="0 0.5135473249355026 0.5" />
     <axis xyz="1 0 0"/>
       <limit effort="0.0" lower="-3.14159" upper="3.14159" velocity="0.0"/>
    </joint>
    <link name="rootLink3010">
        <inertial>
            <origin xyz="0 0 0.8693739653385242" rpy="0 0 0"/>
            <mass value="1" />
            <inertia ixx="100" ixy="0" ixz="0" iyy="100" iyz="0" izz="100" />
        </inertial>
        <visual>
            <origin xyz="0 0 0.8693739653385242" rpy="0 0 0"/>
            <geometry>
                <box size="1 1 1.7387479306770484" />
            </geometry>
            <material name="Green">
                <color rgba="0 1.0 0 1.0"/>
            </material>
        </visual>
        <collision>
            <origin xyz="0 0 0.8693739653385242" rpy="0 0 0"/>
            <geometry>
                <box size="1 1 1.7387479306770484" />
            </geometry>
        </collision>
    </link>
</robot>