<robot name = "robot">
    <link name="rootLink">
        <inertial>
            <origin xyz="0 0 0.5" rpy="0 0 0"/>
            <mass value="1" />
            <inertia ixx="100" ixy="0" ixz="0" iyy="100" iyz="0" izz="100" />
        </inertial>
        <visual>
            <origin xyz="0 0 0.5" rpy="0 0 0"/>
            <geometry>
                <box size="1 1 1" />
            </geometry>
            <material name="Green">
                <color rgba="0 1.0 0 1.0"/>
            </material>
        </visual>
        <collision>
            <origin xyz="0 0 0.5" rpy="0 0 0"/>
            <geometry>
                <box size="1 1 1" />
            </geometry>
        </collision>
    </link>
    <joint name="rootLink_rootLink2" type="revolute">
       <parent link="rootLink"/>
       <child  link="rootLink2"/>
       <origin rpy="0 0 0" xyz="0 0 1.0" />
     <axis xyz="0 1 0"/>
       <limit effort="0.0" lower="-3.14159" upper="3.14159" velocity="0.0"/>
    </joint>
    <link name="rootLink2">
        <inertial>
            <origin xyz="0 0 0.9841194472254338" rpy="0 0 0"/>
            <mass value="1" />
            <inertia ixx="100" ixy="0" ixz="0" iyy="100" iyz="0" izz="100" />
        </inertial>
        <visual>
            <origin xyz="0 0 0.9841194472254338" rpy="0 0 0"/>
            <geometry>
                <box size="1 1 1.9682388944508675" />
            </geometry>
            <material name="Blue">
                <color rgba="0 0 1.0 1.0"/>
            </material>
        </visual>
        <collision>
            <origin xyz="0 0 0.9841194472254338" rpy="0 0 0"/>
            <geometry>
                <box size="1 1 1.9682388944508675" />
            </geometry>
        </collision>
    </link>
    <joint name="rootLink2_rootLink20" type="revolute">
       <parent link="rootLink2"/>
       <child  link="rootLink20"/>
       <origin rpy="0 0 0" xyz="0 0 1.9682388944508675" />
     <axis xyz="1 0 0"/>
       <limit effort="0.0" lower="-3.14159" upper="3.14159" velocity="0.0"/>
    </joint>
    <link name="rootLink20">
        <inertial>
            <origin xyz="0 0 0.9089422257745373" rpy="0 0 0"/>
            <mass value="1" />
            <inertia ixx="100" ixy="0" ixz="0" iyy="100" iyz="0" izz="100" />
        </inertial>
        <visual>
            <origin xyz="0 0 0.9089422257745373" rpy="0 0 0"/>
            <geometry>
                <box size="1 1 1.8178844515490746" />
            </geometry>
            <material name="Blue">
                <color rgba="0 0 1.0 1.0"/>
            </material>
        </visual>
        <collision>
            <origin xyz="0 0 0.9089422257745373" rpy="0 0 0"/>
            <geometry>
                <box size="1 1 1.8178844515490746" />
            </geometry>
        </collision>
    </link>
    <joint name="rootLink20_rootLink200" type="revolute">
       <parent link="rootLink20"/>
       <child  link="rootLink200"/>
       <origin rpy="0 0 0" xyz="0 0 1.8178844515490746" />
     <axis xyz="1 0 0"/>
       <limit effort="0.0" lower="-3.14159" upper="3.14159" velocity="0.0"/>
    </joint>
    <joint name="rootLink20_rootLink201" type="revolute">
       <parent link="rootLink20"/>
       <child  link="rootLink201"/>
       <origin rpy="0 0 0" xyz="0 0.5 0.9089422257745373" />
     <axis xyz="1 0 0"/>
       <limit effort="0.0" lower="-3.14159" upper="3.14159" velocity="0.0"/>
    </joint>
    <link name="rootLink201">
        <inertial>
            <origin xyz="0 0.5643420684430305 0" rpy="0 0 0"/>
            <mass value="1" />
            <inertia ixx="100" ixy="0" ixz="0" iyy="100" iyz="0" izz="100" />
        </inertial>
        <visual>
            <origin xyz="0 0.5643420684430305 0" rpy="0 0 0"/>
            <geometry>
                <box size="1 1.128684136886061 1" />
            </geometry>
            <material name="Blue">
                <color rgba="0 0 1.0 1.0"/>
            </material>
        </visual>
        <collision>
            <origin xyz="0 0.5643420684430305 0" rpy="0 0 0"/>
            <geometry>
                <box size="1 1.128684136886061 1" />
            </geometry>
        </collision>
    </link>
    <joint name="rootLink201_rootLink2010" type="revolute">
       <parent link="rootLink201"/>
       <child  link="rootLink2010"/>
       <origin rpy="0 0 0" xyz="0 0.5643420684430305 -0.5" />
     <axis xyz="0 1 0"/>
       <limit effort="0.0" lower="-3.14159" upper="3.14159" velocity="0.0"/>
    </joint>
    <joint name="rootLink201_rootLink2011" type="revolute">
       <parent link="rootLink201"/>
       <child  link="rootLink2011"/>
       <origin rpy="0 0 0" xyz="0 1.128684136886061 0" />
     <axis xyz="1 0 0"/>
       <limit effort="0.0" lower="-3.14159" upper="3.14159" velocity="0.0"/>
    </joint>
    <link name="rootLink2011">
        <inertial>
            <origin xyz="0 0.7750596990300135 0" rpy="0 0 0"/>
            <mass value="1" />
            <inertia ixx="100" ixy="0" ixz="0" iyy="100" iyz="0" izz="100" />
        </inertial>
        <visual>
            <origin xyz="0 0.7750596990300135 0" rpy="0 0 0"/>
            <geometry>
                <box size="1 1.550119398060027 1" />
            </geometry>
            <material name="Blue">
                <color rgba="0 0 1.0 1.0"/>
            </material>
        </visual>
        <collision>
            <origin xyz="0 0.7750596990300135 0" rpy="0 0 0"/>
            <geometry>
                <box size="1 1.550119398060027 1" />
            </geometry>
        </collision>
    </link>
    <joint name="rootLink2011_rootLink20110" type="revolute">
       <parent link="rootLink2011"/>
       <child  link="rootLink20110"/>
       <origin rpy="0 0 0" xyz="0 1.550119398060027 0" />
     <axis xyz="1 0 0"/>
       <limit effort="0.0" lower="-3.14159" upper="3.14159" velocity="0.0"/>
    </joint>
    <joint name="rootLink2011_rootLink20111" type="revolute">
       <parent link="rootLink2011"/>
       <child  link="rootLink20111"/>
       <origin rpy="0 0 0" xyz="-0.5 0.7750596990300135 0" />
     <axis xyz="0 0 1"/>
       <limit effort="0.0" lower="-3.14159" upper="3.14159" velocity="0.0"/>
    </joint>
    <link name="rootLink20111">
        <inertial>
            <origin xyz="-0.5632887567888759 0 0" rpy="0 0 0"/>
            <mass value="1" />
            <inertia ixx="100" ixy="0" ixz="0" iyy="100" iyz="0" izz="100" />
        </inertial>
        <visual>
            <origin xyz="-0.5632887567888759 0 0" rpy="0 0 0"/>
            <geometry>
                <box size="1.1265775135777518 1 1" />
            </geometry>
            <material name="Blue">
                <color rgba="0 0 1.0 1.0"/>
            </material>
        </visual>
        <collision>
            <origin xyz="-0.5632887567888759 0 0" rpy="0 0 0"/>
            <geometry>
                <box size="1.1265775135777518 1 1" />
            </geometry>
        </collision>
    </link>
    <link name="rootLink20110">
        <inertial>
            <origin xyz="0 0.8700707653383934 0" rpy="0 0 0"/>
            <mass value="1" />
            <inertia ixx="100" ixy="0" ixz="0" iyy="100" iyz="0" izz="100" />
        </inertial>
        <visual>
            <origin xyz="0 0.8700707653383934 0" rpy="0 0 0"/>
            <geometry>
                <box size="1 1.740141530676787 1" />
            </geometry>
            <material name="Blue">
                <color rgba="0 0 1.0 1.0"/>
            </material>
        </visual>
        <collision>
            <origin xyz="0 0.8700707653383934 0" rpy="0 0 0"/>
            <geometry>
                <box size="1 1.740141530676787 1" />
            </geometry>
        </collision>
    </link>
    <joint name="rootLink20110_rootLink201100" type="revolute">
       <parent link="rootLink20110"/>
       <child  link="rootLink201100"/>
       <origin rpy="0 0 0" xyz="0 0.8700707653383934 -0.5" />
     <axis xyz="1 0 0"/>
       <limit effort="0.0" lower="-3.14159" upper="3.14159" velocity="0.0"/>
    </joint>
    <link name="rootLink201100">
        <inertial>
            <origin xyz="0 0 -0.5247886381387528" rpy="0 0 0"/>
            <mass value="1" />
            <inertia ixx="100" ixy="0" ixz="0" iyy="100" iyz="0" izz="100" />
        </inertial>
        <visual>
            <origin xyz="0 0 -0.5247886381387528" rpy="0 0 0"/>
            <geometry>
                <box size="1 1 1.0495772762775055" />
            </geometry>
            <material name="Green">
                <color rgba="0 1.0 0 1.0"/>
            </material>
        </visual>
        <collision>
            <origin xyz="0 0 -0.5247886381387528" rpy="0 0 0"/>
            <geometry>
                <box size="1 1 1.0495772762775055" />
            </geometry>
        </collision>
    </link>
    <link name="rootLink2010">
        <inertial>
            <origin xyz="0 0 -0.667640224240357" rpy="0 0 0"/>
            <mass value="1" />
            <inertia ixx="100" ixy="0" ixz="0" iyy="100" iyz="0" izz="100" />
        </inertial>
        <visual>
            <origin xyz="0 0 -0.667640224240357" rpy="0 0 0"/>
            <geometry>
                <box size="1 1 1.335280448480714" />
            </geometry>
            <material name="Blue">
                <color rgba="0 0 1.0 1.0"/>
            </material>
        </visual>
        <collision>
            <origin xyz="0 0 -0.667640224240357" rpy="0 0 0"/>
            <geometry>
                <box size="1 1 1.335280448480714" />
            </geometry>
        </collision>
    </link>
    <joint name="rootLink2010_rootLink20100" type="revolute">
       <parent link="rootLink2010"/>
       <child  link="rootLink20100"/>
       <origin rpy="0 0 0" xyz="0 0 0.0" />
     <axis xyz="1 0 0"/>
       <limit effort="0.0" lower="-3.14159" upper="3.14159" velocity="0.0"/>
    </joint>
    <link name="rootLink20100">
        <inertial>
            <origin xyz="0 0 0.9719220291192794" rpy="0 0 0"/>
            <mass value="1" />
            <inertia ixx="100" ixy="0" ixz="0" iyy="100" iyz="0" izz="100" />
        </inertial>
        <visual>
            <origin xyz="0 0 0.9719220291192794" rpy="0 0 0"/>
            <geometry>
                <box size="1 1 1.9438440582385588" />
            </geometry>
            <material name="Green">
                <color rgba="0 1.0 0 1.0"/>
            </material>
        </visual>
        <collision>
            <origin xyz="0 0 0.9719220291192794" rpy="0 0 0"/>
            <geometry>
                <box size="1 1 1.9438440582385588" />
            </geometry>
        </collision>
    </link>
    <joint name="rootLink20100_rootLink201000" type="revolute">
       <parent link="rootLink20100"/>
       <child  link="rootLink201000"/>
       <origin rpy="0 0 0" xyz="0.5 0 0.9719220291192794" />
     <axis xyz="0 1 0"/>
       <limit effort="0.0" lower="-3.14159" upper="3.14159" velocity="0.0"/>
    </joint>
    <link name="rootLink201000">
        <inertial>
            <origin xyz="0.8029708600517806 0 0" rpy="0 0 0"/>
            <mass value="1" />
            <inertia ixx="100" ixy="0" ixz="0" iyy="100" iyz="0" izz="100" />
        </inertial>
        <visual>
            <origin xyz="0.8029708600517806 0 0" rpy="0 0 0"/>
            <geometry>
                <box size="1.6059417201035613 1 1" />
            </geometry>
            <material name="Blue">
                <color rgba="0 0 1.0 1.0"/>
            </material>
        </visual>
        <collision>
            <origin xyz="0.8029708600517806 0 0" rpy="0 0 0"/>
            <geometry>
                <box size="1.6059417201035613 1 1" />
            </geometry>
        </collision>
    </link>
    <joint name="rootLink201000_rootLink2010000" type="revolute">
       <parent link="rootLink201000"/>
       <child  link="rootLink2010000"/>
       <origin rpy="0 0 0" xyz="0.8029708600517806 0 -0.5" />
     <axis xyz="0 1 0"/>
       <limit effort="0.0" lower="-3.14159" upper="3.14159" velocity="0.0"/>
    </joint>
    <joint name="rootLink201000_rootLink2010001" type="revolute">
       <parent link="rootLink201000"/>
       <child  link="rootLink2010001"/>
       <origin rpy="0 0 0" xyz="0.8029708600517806 -0.5 0" />
     <axis xyz="0 0 1"/>
       <limit effort="0.0" lower="-3.14159" upper="3.14159" velocity="0.0"/>
    </joint>
    <link name="rootLink2010001">
        <inertial>
            <origin xyz="0 -0.5035250679653251 0" rpy="0 0 0"/>
            <mass value="1" />
            <inertia ixx="100" ixy="0" ixz="0" iyy="100" iyz="0" izz="100" />
        </inertial>
        <visual>
            <origin xyz="0 -0.5035250679653251 0" rpy="0 0 0"/>
            <geometry>
                <box size="1 1.0070501359306503 1" />
            </geometry>
            <material name="Blue">
                <color rgba="0 0 1.0 1.0"/>
            </material>
        </visual>
        <collision>
            <origin xyz="0 -0.5035250679653251 0" rpy="0 0 0"/>
            <geometry>
                <box size="1 1.0070501359306503 1" />
            </geometry>
        </collision>
    </link>
    <link name="rootLink2010000">
        <inertial>
            <origin xyz="0 0 -0.975451669633314" rpy="0 0 0"/>
            <mass value="1" />
            <inertia ixx="100" ixy="0" ixz="0" iyy="100" iyz="0" izz="100" />
        </inertial>
        <visual>
            <origin xyz="0 0 -0.975451669633314" rpy="0 0 0"/>
            <geometry>
                <box size="1 1 1.950903339266628" />
            </geometry>
            <material name="Green">
                <color rgba="0 1.0 0 1.0"/>
            </material>
        </visual>
        <collision>
            <origin xyz="0 0 -0.975451669633314" rpy="0 0 0"/>
            <geometry>
                <box size="1 1 1.950903339266628" />
            </geometry>
        </collision>
    </link>
    <link name="rootLink200">
        <inertial>
            <origin xyz="0 0 0.5098155348968902" rpy="0 0 0"/>
            <mass value="1" />
            <inertia ixx="100" ixy="0" ixz="0" iyy="100" iyz="0" izz="100" />
        </inertial>
        <visual>
            <origin xyz="0 0 0.5098155348968902" rpy="0 0 0"/>
            <geometry>
                <box size="1 1 1.0196310697937805" />
            </geometry>
            <material name="Green">
                <color rgba="0 1.0 0 1.0"/>
            </material>
        </visual>
        <collision>
            <origin xyz="0 0 0.5098155348968902" rpy="0 0 0"/>
            <geometry>
                <box size="1 1 1.0196310697937805" />
            </geometry>
        </collision>
    </link>
</robot>