<robot name = "robot">
    <link name="rootLink">
        <inertial>
            <origin xyz="0 0 0.5" rpy="0 0 0"/>
            <mass value="1" />
            <inertia ixx="100" ixy="0" ixz="0" iyy="100" iyz="0" izz="100" />
        </inertial>
        <visual>
            <origin xyz="0 0 0.5" rpy="0 0 0"/>
            <geometry>
                <box size="1 1 1" />
            </geometry>
            <material name="Green">
                <color rgba="0 1.0 0 1.0"/>
            </material>
        </visual>
        <collision>
            <origin xyz="0 0 0.5" rpy="0 0 0"/>
            <geometry>
                <box size="1 1 1" />
            </geometry>
        </collision>
    </link>
    <joint name="rootLink_rootLink4" type="revolute">
       <parent link="rootLink"/>
       <child  link="rootLink4"/>
       <origin rpy="0 0 0" xyz="0 0 1.0" />
     <axis xyz="1 0 0"/>
       <limit effort="0.0" lower="-3.14159" upper="3.14159" velocity="0.0"/>
    </joint>
    <link name="rootLink4">
        <inertial>
            <origin xyz="0 0 0.9077866298778738" rpy="0 0 0"/>
            <mass value="1" />
            <inertia ixx="100" ixy="0" ixz="0" iyy="100" iyz="0" izz="100" />
        </inertial>
        <visual>
            <origin xyz="0 0 0.9077866298778738" rpy="0 0 0"/>
            <geometry>
                <box size="1 1 1.8155732597557477" />
            </geometry>
            <material name="Green">
                <color rgba="0 1.0 0 1.0"/>
            </material>
        </visual>
        <collision>
            <origin xyz="0 0 0.9077866298778738" rpy="0 0 0"/>
            <geometry>
                <box size="1 1 1.8155732597557477" />
            </geometry>
        </collision>
    </link>
    <joint name="rootLink4_rootLink41" type="revolute">
       <parent link="rootLink4"/>
       <child  link="rootLink41"/>
       <origin rpy="0 0 0" xyz="0 -0.5 0.9077866298778738" />
     <axis xyz="1 0 0"/>
       <limit effort="0.0" lower="-3.14159" upper="3.14159" velocity="0.0"/>
    </joint>
    <link name="rootLink41">
        <inertial>
            <origin xyz="0 -0.9550605033411044 0" rpy="0 0 0"/>
            <mass value="1" />
            <inertia ixx="100" ixy="0" ixz="0" iyy="100" iyz="0" izz="100" />
        </inertial>
        <visual>
            <origin xyz="0 -0.9550605033411044 0" rpy="0 0 0"/>
            <geometry>
                <box size="1 1.9101210066822087 1" />
            </geometry>
            <material name="Blue">
                <color rgba="0 0 1.0 1.0"/>
            </material>
        </visual>
        <collision>
            <origin xyz="0 -0.9550605033411044 0" rpy="0 0 0"/>
            <geometry>
                <box size="1 1.9101210066822087 1" />
            </geometry>
        </collision>
    </link>
    <joint name="rootLink41_rootLink410" type="revolute">
       <parent link="rootLink41"/>
       <child  link="rootLink410"/>
       <origin rpy="0 0 0" xyz="0 -0.9550605033411044 0.5" />
     <axis xyz="0 0 1"/>
       <limit effort="0.0" lower="-3.14159" upper="3.14159" velocity="0.0"/>
    </joint>
    <link name="rootLink410">
        <inertial>
            <origin xyz="0 0 0.7624655832117332" rpy="0 0 0"/>
            <mass value="1" />
            <inertia ixx="100" ixy="0" ixz="0" iyy="100" iyz="0" izz="100" />
        </inertial>
        <visual>
            <origin xyz="0 0 0.7624655832117332" rpy="0 0 0"/>
            <geometry>
                <box size="1 1 1.5249311664234664" />
            </geometry>
            <material name="Green">
                <color rgba="0 1.0 0 1.0"/>
            </material>
        </visual>
        <collision>
            <origin xyz="0 0 0.7624655832117332" rpy="0 0 0"/>
            <geometry>
                <box size="1 1 1.5249311664234664" />
            </geometry>
        </collision>
    </link>
    <joint name="rootLink410_rootLink4101" type="revolute">
       <parent link="rootLink410"/>
       <child  link="rootLink4101"/>
       <origin rpy="0 0 0" xyz="0 -0.5 0.7624655832117332" />
     <axis xyz="1 0 0"/>
       <limit effort="0.0" lower="-3.14159" upper="3.14159" velocity="0.0"/>
    </joint>
    <link name="rootLink4101">
        <inertial>
            <origin xyz="0 -0.703726964283106 0" rpy="0 0 0"/>
            <mass value="1" />
            <inertia ixx="100" ixy="0" ixz="0" iyy="100" iyz="0" izz="100" />
        </inertial>
        <visual>
            <origin xyz="0 -0.703726964283106 0" rpy="0 0 0"/>
            <geometry>
                <box size="1 1.407453928566212 1" />
            </geometry>
            <material name="Green">
                <color rgba="0 1.0 0 1.0"/>
            </material>
        </visual>
        <collision>
            <origin xyz="0 -0.703726964283106 0" rpy="0 0 0"/>
            <geometry>
                <box size="1 1.407453928566212 1" />
            </geometry>
        </collision>
    </link>
    <joint name="rootLink4101_rootLink41010" type="revolute">
       <parent link="rootLink4101"/>
       <child  link="rootLink41010"/>
       <origin rpy="0 0 0" xyz="0 0.0 0" />
     <axis xyz="0 0 1"/>
       <limit effort="0.0" lower="-3.14159" upper="3.14159" velocity="0.0"/>
    </joint>
    <link name="rootLink41010">
        <inertial>
            <origin xyz="0 0.6149367000101456 0" rpy="0 0 0"/>
            <mass value="1" />
            <inertia ixx="100" ixy="0" ixz="0" iyy="100" iyz="0" izz="100" />
        </inertial>
        <visual>
            <origin xyz="0 0.6149367000101456 0" rpy="0 0 0"/>
            <geometry>
                <box size="1 1.229873400020291 1" />
            </geometry>
            <material name="Green">
                <color rgba="0 1.0 0 1.0"/>
            </material>
        </visual>
        <collision>
            <origin xyz="0 0.6149367000101456 0" rpy="0 0 0"/>
            <geometry>
                <box size="1 1.229873400020291 1" />
            </geometry>
        </collision>
    </link>
    <joint name="rootLink41010_rootLink410100" type="revolute">
       <parent link="rootLink41010"/>
       <child  link="rootLink410100"/>
       <origin rpy="0 0 0" xyz="0 1.229873400020291 0" />
     <axis xyz="0 1 0"/>
       <limit effort="0.0" lower="-3.14159" upper="3.14159" velocity="0.0"/>
    </joint>
    <link name="rootLink410100">
        <inertial>
            <origin xyz="0 0.7440620867825056 0" rpy="0 0 0"/>
            <mass value="1" />
            <inertia ixx="100" ixy="0" ixz="0" iyy="100" iyz="0" izz="100" />
        </inertial>
        <visual>
            <origin xyz="0 0.7440620867825056 0" rpy="0 0 0"/>
            <geometry>
                <box size="1 1.4881241735650113 1" />
            </geometry>
            <material name="Green">
                <color rgba="0 1.0 0 1.0"/>
            </material>
        </visual>
        <collision>
            <origin xyz="0 0.7440620867825056 0" rpy="0 0 0"/>
            <geometry>
                <box size="1 1.4881241735650113 1" />
            </geometry>
        </collision>
    </link>
    <joint name="rootLink410100_rootLink4101000" type="revolute">
       <parent link="rootLink410100"/>
       <child  link="rootLink4101000"/>
       <origin rpy="0 0 0" xyz="0.5 0.7440620867825056 0" />
     <axis xyz="0 1 0"/>
       <limit effort="0.0" lower="-3.14159" upper="3.14159" velocity="0.0"/>
    </joint>
    <link name="rootLink4101000">
        <inertial>
            <origin xyz="0.8806248511137015 0 0" rpy="0 0 0"/>
            <mass value="1" />
            <inertia ixx="100" ixy="0" ixz="0" iyy="100" iyz="0" izz="100" />
        </inertial>
        <visual>
            <origin xyz="0.8806248511137015 0 0" rpy="0 0 0"/>
            <geometry>
                <box size="1.761249702227403 1 1" />
            </geometry>
            <material name="Blue">
                <color rgba="0 0 1.0 1.0"/>
            </material>
        </visual>
        <collision>
            <origin xyz="0.8806248511137015 0 0" rpy="0 0 0"/>
            <geometry>
                <box size="1.761249702227403 1 1" />
            </geometry>
        </collision>
    </link>
    <joint name="rootLink410100_rootLink4101001" type="revolute">
       <parent link="rootLink410100"/>
       <child  link="rootLink4101001"/>
       <origin rpy="0 0 0" xyz="0 0.7440620867825056 0.5" />
     <axis xyz="0 0 1"/>
       <limit effort="0.0" lower="-3.14159" upper="3.14159" velocity="0.0"/>
    </joint>
    <link name="rootLink4101001">
        <inertial>
            <origin xyz="0 0 0.6223353108212757" rpy="0 0 0"/>
            <mass value="1" />
            <inertia ixx="100" ixy="0" ixz="0" iyy="100" iyz="0" izz="100" />
        </inertial>
        <visual>
            <origin xyz="0 0 0.6223353108212757" rpy="0 0 0"/>
            <geometry>
                <box size="1 1 1.2446706216425514" />
            </geometry>
            <material name="Blue">
                <color rgba="0 0 1.0 1.0"/>
            </material>
        </visual>
        <collision>
            <origin xyz="0 0 0.6223353108212757" rpy="0 0 0"/>
            <geometry>
                <box size="1 1 1.2446706216425514" />
            </geometry>
        </collision>
    </link>
</robot>