<robot name = "robot">
    <link name="rootLink">
        <inertial>
            <origin xyz="0 0 0.5" rpy="0 0 0"/>
            <mass value="1" />
            <inertia ixx="100" ixy="0" ixz="0" iyy="100" iyz="0" izz="100" />
        </inertial>
        <visual>
            <origin xyz="0 0 0.5" rpy="0 0 0"/>
            <geometry>
                <box size="1 1 1" />
            </geometry>
            <material name="Blue">
                <color rgba="0 0 1.0 1.0"/>
            </material>
        </visual>
        <collision>
            <origin xyz="0 0 0.5" rpy="0 0 0"/>
            <geometry>
                <box size="1 1 1" />
            </geometry>
        </collision>
    </link>
    <joint name="rootLink_rootLink0" type="revolute">
       <parent link="rootLink"/>
       <child  link="rootLink0"/>
       <origin rpy="0 0 0" xyz="0 0 1.0" />
     <axis xyz="1 0 0"/>
       <limit effort="0.0" lower="-3.14159" upper="3.14159" velocity="0.0"/>
    </joint>
    <link name="rootLink0">
        <inertial>
            <origin xyz="0 0 0.522325862586857" rpy="0 0 0"/>
            <mass value="1" />
            <inertia ixx="100" ixy="0" ixz="0" iyy="100" iyz="0" izz="100" />
        </inertial>
        <visual>
            <origin xyz="0 0 0.522325862586857" rpy="0 0 0"/>
            <geometry>
                <box size="1 1 1.044651725173714" />
            </geometry>
            <material name="Blue">
                <color rgba="0 0 1.0 1.0"/>
            </material>
        </visual>
        <collision>
            <origin xyz="0 0 0.522325862586857" rpy="0 0 0"/>
            <geometry>
                <box size="1 1 1.044651725173714" />
            </geometry>
        </collision>
    </link>
    <joint name="rootLink0_rootLink00" type="revolute">
       <parent link="rootLink0"/>
       <child  link="rootLink00"/>
       <origin rpy="0 0 0" xyz="0 -0.5 0.522325862586857" />
     <axis xyz="0 0 1"/>
       <limit effort="0.0" lower="-3.14159" upper="3.14159" velocity="0.0"/>
    </joint>
    <link name="rootLink00">
        <inertial>
            <origin xyz="0 -0.5059754001667489 0" rpy="0 0 0"/>
            <mass value="1" />
            <inertia ixx="100" ixy="0" ixz="0" iyy="100" iyz="0" izz="100" />
        </inertial>
        <visual>
            <origin xyz="0 -0.5059754001667489 0" rpy="0 0 0"/>
            <geometry>
                <box size="1 1.0119508003334978 1" />
            </geometry>
            <material name="Green">
                <color rgba="0 1.0 0 1.0"/>
            </material>
        </visual>
        <collision>
            <origin xyz="0 -0.5059754001667489 0" rpy="0 0 0"/>
            <geometry>
                <box size="1 1.0119508003334978 1" />
            </geometry>
        </collision>
    </link>
    <joint name="rootLink00_rootLink000" type="revolute">
       <parent link="rootLink00"/>
       <child  link="rootLink000"/>
       <origin rpy="0 0 0" xyz="0 -0.5059754001667489 0.5" />
     <axis xyz="0 1 0"/>
       <limit effort="0.0" lower="-3.14159" upper="3.14159" velocity="0.0"/>
    </joint>
    <link name="rootLink000">
        <inertial>
            <origin xyz="0 0 0.5726882838753214" rpy="0 0 0"/>
            <mass value="1" />
            <inertia ixx="100" ixy="0" ixz="0" iyy="100" iyz="0" izz="100" />
        </inertial>
        <visual>
            <origin xyz="0 0 0.5726882838753214" rpy="0 0 0"/>
            <geometry>
                <box size="1 1 1.145376567750643" />
            </geometry>
            <material name="Green">
                <color rgba="0 1.0 0 1.0"/>
            </material>
        </visual>
        <collision>
            <origin xyz="0 0 0.5726882838753214" rpy="0 0 0"/>
            <geometry>
                <box size="1 1 1.145376567750643" />
            </geometry>
        </collision>
    </link>
    <joint name="rootLink000_rootLink0000" type="revolute">
       <parent link="rootLink000"/>
       <child  link="rootLink0000"/>
       <origin rpy="0 0 0" xyz="0 0.5 0.5726882838753214" />
     <axis xyz="0 1 0"/>
       <limit effort="0.0" lower="-3.14159" upper="3.14159" velocity="0.0"/>
    </joint>
    <link name="rootLink0000">
        <inertial>
            <origin xyz="0 0.9174143612144556 0" rpy="0 0 0"/>
            <mass value="1" />
            <inertia ixx="100" ixy="0" ixz="0" iyy="100" iyz="0" izz="100" />
        </inertial>
        <visual>
            <origin xyz="0 0.9174143612144556 0" rpy="0 0 0"/>
            <geometry>
                <box size="1 1.8348287224289113 1" />
            </geometry>
            <material name="Green">
                <color rgba="0 1.0 0 1.0"/>
            </material>
        </visual>
        <collision>
            <origin xyz="0 0.9174143612144556 0" rpy="0 0 0"/>
            <geometry>
                <box size="1 1.8348287224289113 1" />
            </geometry>
        </collision>
    </link>
    <joint name="rootLink0000_rootLink00000" type="revolute">
       <parent link="rootLink0000"/>
       <child  link="rootLink00000"/>
       <origin rpy="0 0 0" xyz="0 0.9174143612144556 -0.5" />
     <axis xyz="0 1 0"/>
       <limit effort="0.0" lower="-3.14159" upper="3.14159" velocity="0.0"/>
    </joint>
    <link name="rootLink00000">
        <inertial>
            <origin xyz="0 0 -0.5184495083532938" rpy="0 0 0"/>
            <mass value="1" />
            <inertia ixx="100" ixy="0" ixz="0" iyy="100" iyz="0" izz="100" />
        </inertial>
        <visual>
            <origin xyz="0 0 -0.5184495083532938" rpy="0 0 0"/>
            <geometry>
                <box size="1 1 1.0368990167065877" />
            </geometry>
            <material name="Green">
                <color rgba="0 1.0 0 1.0"/>
            </material>
        </visual>
        <collision>
            <origin xyz="0 0 -0.5184495083532938" rpy="0 0 0"/>
            <geometry>
                <box size="1 1 1.0368990167065877" />
            </geometry>
        </collision>
    </link>
    <joint name="rootLink00000_rootLink000000" type="revolute">
       <parent link="rootLink00000"/>
       <child  link="rootLink000000"/>
       <origin rpy="0 0 0" xyz="0 -0.5 -0.5184495083532938" />
     <axis xyz="0 1 0"/>
       <limit effort="0.0" lower="-3.14159" upper="3.14159" velocity="0.0"/>
    </joint>
    <link name="rootLink000000">
        <inertial>
            <origin xyz="0 -0.683957595124317 0" rpy="0 0 0"/>
            <mass value="1" />
            <inertia ixx="100" ixy="0" ixz="0" iyy="100" iyz="0" izz="100" />
        </inertial>
        <visual>
            <origin xyz="0 -0.683957595124317 0" rpy="0 0 0"/>
            <geometry>
                <box size="1 1.367915190248634 1" />
            </geometry>
            <material name="Green">
                <color rgba="0 1.0 0 1.0"/>
            </material>
        </visual>
        <collision>
            <origin xyz="0 -0.683957595124317 0" rpy="0 0 0"/>
            <geometry>
                <box size="1 1.367915190248634 1" />
            </geometry>
        </collision>
    </link>
    <joint name="rootLink00000_rootLink000002" type="revolute">
       <parent link="rootLink00000"/>
       <child  link="rootLink000002"/>
       <origin rpy="0 0 0" xyz="0 0 0.0" />
     <axis xyz="0 0 1"/>
       <limit effort="0.0" lower="-3.14159" upper="3.14159" velocity="0.0"/>
    </joint>
    <link name="rootLink000002">
        <inertial>
            <origin xyz="0 0 0.9590773589963376" rpy="0 0 0"/>
            <mass value="1" />
            <inertia ixx="100" ixy="0" ixz="0" iyy="100" iyz="0" izz="100" />
        </inertial>
        <visual>
            <origin xyz="0 0 0.9590773589963376" rpy="0 0 0"/>
            <geometry>
                <box size="1 1 1.9181547179926752" />
            </geometry>
            <material name="Blue">
                <color rgba="0 0 1.0 1.0"/>
            </material>
        </visual>
        <collision>
            <origin xyz="0 0 0.9590773589963376" rpy="0 0 0"/>
            <geometry>
                <box size="1 1 1.9181547179926752" />
            </geometry>
        </collision>
    </link>
    <joint name="rootLink00000_rootLink000003" type="revolute">
       <parent link="rootLink00000"/>
       <child  link="rootLink000003"/>
       <origin rpy="0 0 0" xyz="-0.5 0 -0.5184495083532938" />
     <axis xyz="0 0 1"/>
       <limit effort="0.0" lower="-3.14159" upper="3.14159" velocity="0.0"/>
    </joint>
    <link name="rootLink000003">
        <inertial>
            <origin xyz="-0.5126195881962077 0 0" rpy="0 0 0"/>
            <mass value="1" />
            <inertia ixx="100" ixy="0" ixz="0" iyy="100" iyz="0" izz="100" />
        </inertial>
        <visual>
            <origin xyz="-0.5126195881962077 0 0" rpy="0 0 0"/>
            <geometry>
                <box size="1.0252391763924154 1 1" />
            </geometry>
            <material name="Green">
                <color rgba="0 1.0 0 1.0"/>
            </material>
        </visual>
        <collision>
            <origin xyz="-0.5126195881962077 0 0" rpy="0 0 0"/>
            <geometry>
                <box size="1.0252391763924154 1 1" />
            </geometry>
        </collision>
    </link>
    <joint name="rootLink000_rootLink0001" type="revolute">
       <parent link="rootLink000"/>
       <child  link="rootLink0001"/>
       <origin rpy="0 0 0" xyz="0.5 0 0.5726882838753214" />
     <axis xyz="0 1 0"/>
       <limit effort="0.0" lower="-3.14159" upper="3.14159" velocity="0.0"/>
    </joint>
    <link name="rootLink0001">
        <inertial>
            <origin xyz="0.97923484950785 0 0" rpy="0 0 0"/>
            <mass value="1" />
            <inertia ixx="100" ixy="0" ixz="0" iyy="100" iyz="0" izz="100" />
        </inertial>
        <visual>
            <origin xyz="0.97923484950785 0 0" rpy="0 0 0"/>
            <geometry>
                <box size="1.9584696990157 1 1" />
            </geometry>
            <material name="Blue">
                <color rgba="0 0 1.0 1.0"/>
            </material>
        </visual>
        <collision>
            <origin xyz="0.97923484950785 0 0" rpy="0 0 0"/>
            <geometry>
                <box size="1.9584696990157 1 1" />
            </geometry>
        </collision>
    </link>
</robot>