<robot name = "robot">
    <link name="rootLink">
        <inertial>
            <origin xyz="0 0 0.5" rpy="0 0 0"/>
            <mass value="1" />
            <inertia ixx="100" ixy="0" ixz="0" iyy="100" iyz="0" izz="100" />
        </inertial>
        <visual>
            <origin xyz="0 0 0.5" rpy="0 0 0"/>
            <geometry>
                <box size="1 1 1" />
            </geometry>
            <material name="Blue">
                <color rgba="0 0 1.0 1.0"/>
            </material>
        </visual>
        <collision>
            <origin xyz="0 0 0.5" rpy="0 0 0"/>
            <geometry>
                <box size="1 1 1" />
            </geometry>
        </collision>
    </link>
    <joint name="rootLink_rootLink0" type="revolute">
       <parent link="rootLink"/>
       <child  link="rootLink0"/>
       <origin rpy="0 0 0" xyz="0 0 1.0" />
     <axis xyz="0 1 0"/>
       <limit effort="0.0" lower="-3.14159" upper="3.14159" velocity="0.0"/>
    </joint>
    <link name="rootLink0">
        <inertial>
            <origin xyz="0 0 0.6660454878491797" rpy="0 0 0"/>
            <mass value="1" />
            <inertia ixx="100" ixy="0" ixz="0" iyy="100" iyz="0" izz="100" />
        </inertial>
        <visual>
            <origin xyz="0 0 0.6660454878491797" rpy="0 0 0"/>
            <geometry>
                <box size="1 1 1.3320909756983594" />
            </geometry>
            <material name="Green">
                <color rgba="0 1.0 0 1.0"/>
            </material>
        </visual>
        <collision>
            <origin xyz="0 0 0.6660454878491797" rpy="0 0 0"/>
            <geometry>
                <box size="1 1 1.3320909756983594" />
            </geometry>
        </collision>
    </link>
    <joint name="rootLink0_rootLink00" type="revolute">
       <parent link="rootLink0"/>
       <child  link="rootLink00"/>
       <origin rpy="0 0 0" xyz="-0.5 0 0.6660454878491797" />
     <axis xyz="1 0 0"/>
       <limit effort="0.0" lower="-3.14159" upper="3.14159" velocity="0.0"/>
    </joint>
    <link name="rootLink00">
        <inertial>
            <origin xyz="-0.6987533340255115 0 0" rpy="0 0 0"/>
            <mass value="1" />
            <inertia ixx="100" ixy="0" ixz="0" iyy="100" iyz="0" izz="100" />
        </inertial>
        <visual>
            <origin xyz="-0.6987533340255115 0 0" rpy="0 0 0"/>
            <geometry>
                <box size="1.397506668051023 1 1" />
            </geometry>
            <material name="Blue">
                <color rgba="0 0 1.0 1.0"/>
            </material>
        </visual>
        <collision>
            <origin xyz="-0.6987533340255115 0 0" rpy="0 0 0"/>
            <geometry>
                <box size="1.397506668051023 1 1" />
            </geometry>
        </collision>
    </link>
    <joint name="rootLink00_rootLink001" type="revolute">
       <parent link="rootLink00"/>
       <child  link="rootLink001"/>
       <origin rpy="0 0 0" xyz="0.0 0 0" />
     <axis xyz="1 0 0"/>
       <limit effort="0.0" lower="-3.14159" upper="3.14159" velocity="0.0"/>
    </joint>
    <link name="rootLink001">
        <inertial>
            <origin xyz="0.7890142410264486 0 0" rpy="0 0 0"/>
            <mass value="1" />
            <inertia ixx="100" ixy="0" ixz="0" iyy="100" iyz="0" izz="100" />
        </inertial>
        <visual>
            <origin xyz="0.7890142410264486 0 0" rpy="0 0 0"/>
            <geometry>
                <box size="1.5780284820528971 1 1" />
            </geometry>
            <material name="Green">
                <color rgba="0 1.0 0 1.0"/>
            </material>
        </visual>
        <collision>
            <origin xyz="0.7890142410264486 0 0" rpy="0 0 0"/>
            <geometry>
                <box size="1.5780284820528971 1 1" />
            </geometry>
        </collision>
    </link>
    <joint name="rootLink00_rootLink002" type="revolute">
       <parent link="rootLink00"/>
       <child  link="rootLink002"/>
       <origin rpy="0 0 0" xyz="-0.6987533340255115 0.5 0" />
     <axis xyz="0 0 1"/>
       <limit effort="0.0" lower="-3.14159" upper="3.14159" velocity="0.0"/>
    </joint>
    <link name="rootLink002">
        <inertial>
            <origin xyz="0 0.5527277346653352 0" rpy="0 0 0"/>
            <mass value="1" />
            <inertia ixx="100" ixy="0" ixz="0" iyy="100" iyz="0" izz="100" />
        </inertial>
        <visual>
            <origin xyz="0 0.5527277346653352 0" rpy="0 0 0"/>
            <geometry>
                <box size="1 1.1054554693306704 1" />
            </geometry>
            <material name="Blue">
                <color rgba="0 0 1.0 1.0"/>
            </material>
        </visual>
        <collision>
            <origin xyz="0 0.5527277346653352 0" rpy="0 0 0"/>
            <geometry>
                <box size="1 1.1054554693306704 1" />
            </geometry>
        </collision>
    </link>
    <joint name="rootLink0_rootLink03" type="revolute">
       <parent link="rootLink0"/>
       <child  link="rootLink03"/>
       <origin rpy="0 0 0" xyz="0 -0.5 0.6660454878491797" />
     <axis xyz="0 0 1"/>
       <limit effort="0.0" lower="-3.14159" upper="3.14159" velocity="0.0"/>
    </joint>
    <link name="rootLink03">
        <inertial>
            <origin xyz="0 -0.698131001700362 0" rpy="0 0 0"/>
            <mass value="1" />
            <inertia ixx="100" ixy="0" ixz="0" iyy="100" iyz="0" izz="100" />
        </inertial>
        <visual>
            <origin xyz="0 -0.698131001700362 0" rpy="0 0 0"/>
            <geometry>
                <box size="1 1.396262003400724 1" />
            </geometry>
            <material name="Blue">
                <color rgba="0 0 1.0 1.0"/>
            </material>
        </visual>
        <collision>
            <origin xyz="0 -0.698131001700362 0" rpy="0 0 0"/>
            <geometry>
                <box size="1 1.396262003400724 1" />
            </geometry>
        </collision>
    </link>
    <joint name="rootLink03_rootLink030" type="revolute">
       <parent link="rootLink03"/>
       <child  link="rootLink030"/>
       <origin rpy="0 0 0" xyz="0 -0.698131001700362 0.5" />
     <axis xyz="1 0 0"/>
       <limit effort="0.0" lower="-3.14159" upper="3.14159" velocity="0.0"/>
    </joint>
    <link name="rootLink030">
        <inertial>
            <origin xyz="0 0 0.7168282168646902" rpy="0 0 0"/>
            <mass value="1" />
            <inertia ixx="100" ixy="0" ixz="0" iyy="100" iyz="0" izz="100" />
        </inertial>
        <visual>
            <origin xyz="0 0 0.7168282168646902" rpy="0 0 0"/>
            <geometry>
                <box size="1 1 1.4336564337293805" />
            </geometry>
            <material name="Blue">
                <color rgba="0 0 1.0 1.0"/>
            </material>
        </visual>
        <collision>
            <origin xyz="0 0 0.7168282168646902" rpy="0 0 0"/>
            <geometry>
                <box size="1 1 1.4336564337293805" />
            </geometry>
        </collision>
    </link>
    <joint name="rootLink030_rootLink0300" type="revolute">
       <parent link="rootLink030"/>
       <child  link="rootLink0300"/>
       <origin rpy="0 0 0" xyz="0 0.5 0.7168282168646902" />
     <axis xyz="0 1 0"/>
       <limit effort="0.0" lower="-3.14159" upper="3.14159" velocity="0.0"/>
    </joint>
    <link name="rootLink0300">
        <inertial>
            <origin xyz="0 0.7519370399699562 0" rpy="0 0 0"/>
            <mass value="1" />
            <inertia ixx="100" ixy="0" ixz="0" iyy="100" iyz="0" izz="100" />
        </inertial>
        <visual>
            <origin xyz="0 0.7519370399699562 0" rpy="0 0 0"/>
            <geometry>
                <box size="1 1.5038740799399124 1" />
            </geometry>
            <material name="Green">
                <color rgba="0 1.0 0 1.0"/>
            </material>
        </visual>
        <collision>
            <origin xyz="0 0.7519370399699562 0" rpy="0 0 0"/>
            <geometry>
                <box size="1 1.5038740799399124 1" />
            </geometry>
        </collision>
    </link>
</robot>