<robot name = "robot">
    <link name="rootLink">
        <inertial>
            <origin xyz="0 0 0.5" rpy="0 0 0"/>
            <mass value="1" />
            <inertia ixx="100" ixy="0" ixz="0" iyy="100" iyz="0" izz="100" />
        </inertial>
        <visual>
            <origin xyz="0 0 0.5" rpy="0 0 0"/>
            <geometry>
                <box size="1 1 1" />
            </geometry>
            <material name="Green">
                <color rgba="0 1.0 0 1.0"/>
            </material>
        </visual>
        <collision>
            <origin xyz="0 0 0.5" rpy="0 0 0"/>
            <geometry>
                <box size="1 1 1" />
            </geometry>
        </collision>
    </link>
    <joint name="rootLink_rootLink1" type="revolute">
       <parent link="rootLink"/>
       <child  link="rootLink1"/>
       <origin rpy="0 0 0" xyz="0 0 1.0" />
     <axis xyz="1 0 0"/>
       <limit effort="0.0" lower="-3.14159" upper="3.14159" velocity="0.0"/>
    </joint>
    <link name="rootLink1">
        <inertial>
            <origin xyz="0 0 0.659530109697448" rpy="0 0 0"/>
            <mass value="1" />
            <inertia ixx="100" ixy="0" ixz="0" iyy="100" iyz="0" izz="100" />
        </inertial>
        <visual>
            <origin xyz="0 0 0.659530109697448" rpy="0 0 0"/>
            <geometry>
                <box size="1 1 1.319060219394896" />
            </geometry>
            <material name="Blue">
                <color rgba="0 0 1.0 1.0"/>
            </material>
        </visual>
        <collision>
            <origin xyz="0 0 0.659530109697448" rpy="0 0 0"/>
            <geometry>
                <box size="1 1 1.319060219394896" />
            </geometry>
        </collision>
    </link>
    <joint name="rootLink1_rootLink10" type="revolute">
       <parent link="rootLink1"/>
       <child  link="rootLink10"/>
       <origin rpy="0 0 0" xyz="0.5 0 0.659530109697448" />
     <axis xyz="1 0 0"/>
       <limit effort="0.0" lower="-3.14159" upper="3.14159" velocity="0.0"/>
    </joint>
    <link name="rootLink10">
        <inertial>
            <origin xyz="0.9293293101021356 0 0" rpy="0 0 0"/>
            <mass value="1" />
            <inertia ixx="100" ixy="0" ixz="0" iyy="100" iyz="0" izz="100" />
        </inertial>
        <visual>
            <origin xyz="0.9293293101021356 0 0" rpy="0 0 0"/>
            <geometry>
                <box size="1.8586586202042712 1 1" />
            </geometry>
            <material name="Green">
                <color rgba="0 1.0 0 1.0"/>
            </material>
        </visual>
        <collision>
            <origin xyz="0.9293293101021356 0 0" rpy="0 0 0"/>
            <geometry>
                <box size="1.8586586202042712 1 1" />
            </geometry>
        </collision>
    </link>
    <joint name="rootLink10_rootLink100" type="revolute">
       <parent link="rootLink10"/>
       <child  link="rootLink100"/>
       <origin rpy="0 0 0" xyz="0.9293293101021356 -0.5 0" />
     <axis xyz="0 1 0"/>
       <limit effort="0.0" lower="-3.14159" upper="3.14159" velocity="0.0"/>
    </joint>
    <link name="rootLink100">
        <inertial>
            <origin xyz="0 -0.7190677358379618 0" rpy="0 0 0"/>
            <mass value="1" />
            <inertia ixx="100" ixy="0" ixz="0" iyy="100" iyz="0" izz="100" />
        </inertial>
        <visual>
            <origin xyz="0 -0.7190677358379618 0" rpy="0 0 0"/>
            <geometry>
                <box size="1 1.4381354716759236 1" />
            </geometry>
            <material name="Green">
                <color rgba="0 1.0 0 1.0"/>
            </material>
        </visual>
        <collision>
            <origin xyz="0 -0.7190677358379618 0" rpy="0 0 0"/>
            <geometry>
                <box size="1 1.4381354716759236 1" />
            </geometry>
        </collision>
    </link>
    <joint name="rootLink100_rootLink1000" type="revolute">
       <parent link="rootLink100"/>
       <child  link="rootLink1000"/>
       <origin rpy="0 0 0" xyz="0.5 -0.7190677358379618 0" />
     <axis xyz="1 0 0"/>
       <limit effort="0.0" lower="-3.14159" upper="3.14159" velocity="0.0"/>
    </joint>
    <link name="rootLink1000">
        <inertial>
            <origin xyz="0.7868115115263086 0 0" rpy="0 0 0"/>
            <mass value="1" />
            <inertia ixx="100" ixy="0" ixz="0" iyy="100" iyz="0" izz="100" />
        </inertial>
        <visual>
            <origin xyz="0.7868115115263086 0 0" rpy="0 0 0"/>
            <geometry>
                <box size="1.5736230230526171 1 1" />
            </geometry>
            <material name="Blue">
                <color rgba="0 0 1.0 1.0"/>
            </material>
        </visual>
        <collision>
            <origin xyz="0.7868115115263086 0 0" rpy="0 0 0"/>
            <geometry>
                <box size="1.5736230230526171 1 1" />
            </geometry>
        </collision>
    </link>
    <joint name="rootLink1_rootLink11" type="revolute">
       <parent link="rootLink1"/>
       <child  link="rootLink11"/>
       <origin rpy="0 0 0" xyz="0 0.5 0.659530109697448" />
     <axis xyz="1 0 0"/>
       <limit effort="0.0" lower="-3.14159" upper="3.14159" velocity="0.0"/>
    </joint>
    <link name="rootLink11">
        <inertial>
            <origin xyz="0 0.5537587308798204 0" rpy="0 0 0"/>
            <mass value="1" />
            <inertia ixx="100" ixy="0" ixz="0" iyy="100" iyz="0" izz="100" />
        </inertial>
        <visual>
            <origin xyz="0 0.5537587308798204 0" rpy="0 0 0"/>
            <geometry>
                <box size="1 1.1075174617596408 1" />
            </geometry>
            <material name="Green">
                <color rgba="0 1.0 0 1.0"/>
            </material>
        </visual>
        <collision>
            <origin xyz="0 0.5537587308798204 0" rpy="0 0 0"/>
            <geometry>
                <box size="1 1.1075174617596408 1" />
            </geometry>
        </collision>
    </link>
</robot>