<robot name = "robot">
    <link name="rootLink">
        <inertial>
            <origin xyz="0 0 0.5" rpy="0 0 0"/>
            <mass value="1" />
            <inertia ixx="100" ixy="0" ixz="0" iyy="100" iyz="0" izz="100" />
        </inertial>
        <visual>
            <origin xyz="0 0 0.5" rpy="0 0 0"/>
            <geometry>
                <box size="1 1 1" />
            </geometry>
            <material name="Green">
                <color rgba="0 1.0 0 1.0"/>
            </material>
        </visual>
        <collision>
            <origin xyz="0 0 0.5" rpy="0 0 0"/>
            <geometry>
                <box size="1 1 1" />
            </geometry>
        </collision>
    </link>
    <joint name="rootLink_rootLink4" type="revolute">
       <parent link="rootLink"/>
       <child  link="rootLink4"/>
       <origin rpy="0 0 0" xyz="0 0 1.0" />
     <axis xyz="1 0 0"/>
       <limit effort="0.0" lower="-3.14159" upper="3.14159" velocity="0.0"/>
    </joint>
    <link name="rootLink4">
        <inertial>
            <origin xyz="0 0 0.8513953514893833" rpy="0 0 0"/>
            <mass value="1" />
            <inertia ixx="100" ixy="0" ixz="0" iyy="100" iyz="0" izz="100" />
        </inertial>
        <visual>
            <origin xyz="0 0 0.8513953514893833" rpy="0 0 0"/>
            <geometry>
                <box size="1 1 1.7027907029787666" />
            </geometry>
            <material name="Blue">
                <color rgba="0 0 1.0 1.0"/>
            </material>
        </visual>
        <collision>
            <origin xyz="0 0 0.8513953514893833" rpy="0 0 0"/>
            <geometry>
                <box size="1 1 1.7027907029787666" />
            </geometry>
        </collision>
    </link>
    <joint name="rootLink4_rootLink40" type="revolute">
       <parent link="rootLink4"/>
       <child  link="rootLink40"/>
       <origin rpy="0 0 0" xyz="0 -0.5 0.8513953514893833" />
     <axis xyz="1 0 0"/>
       <limit effort="0.0" lower="-3.14159" upper="3.14159" velocity="0.0"/>
    </joint>
    <link name="rootLink40">
        <inertial>
            <origin xyz="0 -0.6699464264841872 0" rpy="0 0 0"/>
            <mass value="1" />
            <inertia ixx="100" ixy="0" ixz="0" iyy="100" iyz="0" izz="100" />
        </inertial>
        <visual>
            <origin xyz="0 -0.6699464264841872 0" rpy="0 0 0"/>
            <geometry>
                <box size="1 1.3398928529683745 1" />
            </geometry>
            <material name="Blue">
                <color rgba="0 0 1.0 1.0"/>
            </material>
        </visual>
        <collision>
            <origin xyz="0 -0.6699464264841872 0" rpy="0 0 0"/>
            <geometry>
                <box size="1 1.3398928529683745 1" />
            </geometry>
        </collision>
    </link>
    <joint name="rootLink40_rootLink400" type="revolute">
       <parent link="rootLink40"/>
       <child  link="rootLink400"/>
       <origin rpy="0 0 0" xyz="0 -0.6699464264841872 0.5" />
     <axis xyz="1 0 0"/>
       <limit effort="0.0" lower="-3.14159" upper="3.14159" velocity="0.0"/>
    </joint>
    <link name="rootLink400">
        <inertial>
            <origin xyz="0 0 0.7365371328946542" rpy="0 0 0"/>
            <mass value="1" />
            <inertia ixx="100" ixy="0" ixz="0" iyy="100" iyz="0" izz="100" />
        </inertial>
        <visual>
            <origin xyz="0 0 0.7365371328946542" rpy="0 0 0"/>
            <geometry>
                <box size="1 1 1.4730742657893083" />
            </geometry>
            <material name="Blue">
                <color rgba="0 0 1.0 1.0"/>
            </material>
        </visual>
        <collision>
            <origin xyz="0 0 0.7365371328946542" rpy="0 0 0"/>
            <geometry>
                <box size="1 1 1.4730742657893083" />
            </geometry>
        </collision>
    </link>
</robot>