<robot name = "robot">
    <link name="rootLink">
        <inertial>
            <origin xyz="0 0 0.5" rpy="0 0 0"/>
            <mass value="1" />
            <inertia ixx="100" ixy="0" ixz="0" iyy="100" iyz="0" izz="100" />
        </inertial>
        <visual>
            <origin xyz="0 0 0.5" rpy="0 0 0"/>
            <geometry>
                <box size="1 1 1" />
            </geometry>
            <material name="Green">
                <color rgba="0 1.0 0 1.0"/>
            </material>
        </visual>
        <collision>
            <origin xyz="0 0 0.5" rpy="0 0 0"/>
            <geometry>
                <box size="1 1 1" />
            </geometry>
        </collision>
    </link>
    <joint name="rootLink_rootLink2" type="revolute">
       <parent link="rootLink"/>
       <child  link="rootLink2"/>
       <origin rpy="0 0 0" xyz="0 0 1.0" />
     <axis xyz="0 1 0"/>
       <limit effort="0.0" lower="-3.14159" upper="3.14159" velocity="0.0"/>
    </joint>
    <link name="rootLink2">
        <inertial>
            <origin xyz="0 0 0.5110125268969059" rpy="0 0 0"/>
            <mass value="1" />
            <inertia ixx="100" ixy="0" ixz="0" iyy="100" iyz="0" izz="100" />
        </inertial>
        <visual>
            <origin xyz="0 0 0.5110125268969059" rpy="0 0 0"/>
            <geometry>
                <box size="1 1 1.0220250537938118" />
            </geometry>
            <material name="Blue">
                <color rgba="0 0 1.0 1.0"/>
            </material>
        </visual>
        <collision>
            <origin xyz="0 0 0.5110125268969059" rpy="0 0 0"/>
            <geometry>
                <box size="1 1 1.0220250537938118" />
            </geometry>
        </collision>
    </link>
    <joint name="rootLink2_rootLink20" type="revolute">
       <parent link="rootLink2"/>
       <child  link="rootLink20"/>
       <origin rpy="0 0 0" xyz="0 0 1.0220250537938118" />
     <axis xyz="1 0 0"/>
       <limit effort="0.0" lower="-3.14159" upper="3.14159" velocity="0.0"/>
    </joint>
    <link name="rootLink20">
        <inertial>
            <origin xyz="0 0 0.5436536186720347" rpy="0 0 0"/>
            <mass value="1" />
            <inertia ixx="100" ixy="0" ixz="0" iyy="100" iyz="0" izz="100" />
        </inertial>
        <visual>
            <origin xyz="0 0 0.5436536186720347" rpy="0 0 0"/>
            <geometry>
                <box size="1 1 1.0873072373440693" />
            </geometry>
            <material name="Blue">
                <color rgba="0 0 1.0 1.0"/>
            </material>
        </visual>
        <collision>
            <origin xyz="0 0 0.5436536186720347" rpy="0 0 0"/>
            <geometry>
                <box size="1 1 1.0873072373440693" />
            </geometry>
        </collision>
    </link>
    <joint name="rootLink20_rootLink200" type="revolute">
       <parent link="rootLink20"/>
       <child  link="rootLink200"/>
       <origin rpy="0 0 0" xyz="0 -0.5 0.5436536186720347" />
     <axis xyz="0 0 1"/>
       <limit effort="0.0" lower="-3.14159" upper="3.14159" velocity="0.0"/>
    </joint>
    <link name="rootLink200">
        <inertial>
            <origin xyz="0 -0.8425226136609065 0" rpy="0 0 0"/>
            <mass value="1" />
            <inertia ixx="100" ixy="0" ixz="0" iyy="100" iyz="0" izz="100" />
        </inertial>
        <visual>
            <origin xyz="0 -0.8425226136609065 0" rpy="0 0 0"/>
            <geometry>
                <box size="1 1.685045227321813 1" />
            </geometry>
            <material name="Blue">
                <color rgba="0 0 1.0 1.0"/>
            </material>
        </visual>
        <collision>
            <origin xyz="0 -0.8425226136609065 0" rpy="0 0 0"/>
            <geometry>
                <box size="1 1.685045227321813 1" />
            </geometry>
        </collision>
    </link>
    <joint name="rootLink200_rootLink2000" type="revolute">
       <parent link="rootLink200"/>
       <child  link="rootLink2000"/>
       <origin rpy="0 0 0" xyz="-0.5 -0.8425226136609065 0" />
     <axis xyz="1 0 0"/>
       <limit effort="0.0" lower="-3.14159" upper="3.14159" velocity="0.0"/>
    </joint>
    <link name="rootLink2000">
        <inertial>
            <origin xyz="-0.9687435105520267 0 0" rpy="0 0 0"/>
            <mass value="1" />
            <inertia ixx="100" ixy="0" ixz="0" iyy="100" iyz="0" izz="100" />
        </inertial>
        <visual>
            <origin xyz="-0.9687435105520267 0 0" rpy="0 0 0"/>
            <geometry>
                <box size="1.9374870211040534 1 1" />
            </geometry>
            <material name="Blue">
                <color rgba="0 0 1.0 1.0"/>
            </material>
        </visual>
        <collision>
            <origin xyz="-0.9687435105520267 0 0" rpy="0 0 0"/>
            <geometry>
                <box size="1.9374870211040534 1 1" />
            </geometry>
        </collision>
    </link>
    <joint name="rootLink200_rootLink2001" type="revolute">
       <parent link="rootLink200"/>
       <child  link="rootLink2001"/>
       <origin rpy="0 0 0" xyz="0 0.0 0" />
     <axis xyz="0 0 1"/>
       <limit effort="0.0" lower="-3.14159" upper="3.14159" velocity="0.0"/>
    </joint>
    <link name="rootLink2001">
        <inertial>
            <origin xyz="0 0.829123419604711 0" rpy="0 0 0"/>
            <mass value="1" />
            <inertia ixx="100" ixy="0" ixz="0" iyy="100" iyz="0" izz="100" />
        </inertial>
        <visual>
            <origin xyz="0 0.829123419604711 0" rpy="0 0 0"/>
            <geometry>
                <box size="1 1.658246839209422 1" />
            </geometry>
            <material name="Green">
                <color rgba="0 1.0 0 1.0"/>
            </material>
        </visual>
        <collision>
            <origin xyz="0 0.829123419604711 0" rpy="0 0 0"/>
            <geometry>
                <box size="1 1.658246839209422 1" />
            </geometry>
        </collision>
    </link>
</robot>